Workbook

Sheet flw11-12
A1: STATES/Uts | B1: ANTHURIUM | F1: CARNATION | J1: CHRYSANTHEMUM | N1: GERBERA | R1: GLADIOUS | V1: JASMINE | Z1: MARIGOLD | AD1: ORCHIDS | AH1: ROSE | AL1: TUBE ROSE | AP1: TULIP | AT1: OTHERS | AX1: TOTAL FLOWERS
B2: A | C2: P | D2: P | E2: Prod. | F2: A | G2: P | H2: P | J2: A | K2: P | L2: P | N2: A | O2: P | P2: P | R2: A | S2: P | T2: P | V2: A | W2: P | X2: P | Z2: A | AA2: P | AB2: P | AD2: A | AE2: P | AF2: P | AH2: A | AI2: P | AJ2: P | AL2: A | AM2: P | AN2: P | AP2: A | AQ2: P | AR2: P | AT2: A | AU2: P | AV2: P | AX2: A | AY2: P
C3: LOOSE | D3: CUT | G3: LOOSE | H3: CUT | K3: LOOSE | L3: CUT | O3: LOOSE | P3: CUT | S3: LOOSE | T3: CUT | W3: LOOSE | X3: CUT | AA3: LOOSE | AB3: CUT | AE3: LOOSE | AF3: CUT | AI3: LOOSE | AJ3: CUT | AM3: LOOSE | AN3: CUT | AQ3: LOOSE | AR3: CUT | AU3: LOOSE | AV3: CUT | AY3: LOOSE | AZ3: CUT
A4: ANDAMAN NICOBAR | V4: 0.00185 | W4: 0.01115 | Z4: 0.00675 | AA4: 0.09692 | AH4: 0.0038 | AI4: 0.03724 | AT4: 0.0226 | AU4: 0.196 | AX4: =B4+F4+J4+N4+R4+V4+Z4+AD4+AH4+AL4+AP4+AT4 -> 0.035 | AY4: =C4+G4+K4+O4+S4+W4+AA4+AE4+AI4+AM4+AQ4+AU4 -> 0.34131 | AZ4: =D4+H4+L4+P4+T4+X4+AB4+AF4+AJ4+AN4+AR4+AV4 -> 0 | BA4: =(AZ4+AY4)/AX4 -> 9.7517143
A5: ANDHRA PRADESH | J5: 10.609 | K5: 121.998 | R5: 0.014 | T5: 7.07 | V5: 33.354 | W5: 166.768 | Z5: 4.539 | AA5: 34.042 | AH5: 2.364 | AJ5: 7092.32 | AL5: 2.45 | AM5: 14.702 | AT5: =1.453+9.37 -> 10.823 | AU5: =4.649+46.849 -> 51.498 | AX5: =B5+F5+J5+N5+R5+V5+Z5+AD5+AH5+AL5+AP5+AT5 -> 64.153 | AY5: =C5+G5+K5+O5+S5+W5+AA5+AE5+AI5+AM5+AQ5+AU5 -> 389.008 | AZ5: =D5+H5+L5+P5+T5+X5+AB5+AF5+AJ5+AN5+AR5+AV5 -> 7099.39 | BA5: =(AZ5+AY5)/AX5 -> 116.72717
A6: ARUNACHAL PRADESH | AT6: 1.22 | AV6: 2860 | AX6: =B6+F6+J6+N6+R6+V6+Z6+AD6+AH6+AL6+AP6+AT6 -> 1.22 | AY6: =C6+G6+K6+O6+S6+W6+AA6+AE6+AI6+AM6+AQ6+AU6 -> 0 | AZ6: =D6+H6+L6+P6+T6+X6+AB6+AF6+AJ6+AN6+AR6+AV6 -> 2860 | BA6: =(AZ6+AY6)/AX6 -> 2344.2623
A7: ASSAM | AX7: =B7+F7+J7+N7+R7+V7+Z7+AD7+AH7+AL7+AP7+AT7 -> 0 | AY7: =C7+G7+K7+O7+S7+W7+AA7+AE7+AI7+AM7+AQ7+AU7 -> 0 | AZ7: =D7+H7+L7+P7+T7+X7+AB7+AF7+AJ7+AN7+AR7+AV7 -> 0 | BA7: =(AZ7+AY7)/AX7 -> #DIV/0!
A8: BIHAR | AT8: =0.172+0.729 -> 0.901 | AU8: 8.72 | AV8: 1285 | AX8: =B8+F8+J8+N8+R8+V8+Z8+AD8+AH8+AL8+AP8+AT8 -> 0.901 | AY8: =C8+G8+K8+O8+S8+W8+AA8+AE8+AI8+AM8+AQ8+AU8 -> 8.72 | AZ8: =D8+H8+L8+P8+T8+X8+AB8+AF8+AJ8+AN8+AR8+AV8 -> 1285 | BA8: =(AZ8+AY8)/AX8 -> 1435.8713
A9: CHHATISHGARH | J9: 0.16 | K9: 0.48 | R9: 2.04 | S9: 5.41 | V9: 0.02 | W9: 0.04 | Z9: 2.16 | AA9: 15.47 | AH9: 0.83 | AI9: 1.92 | AL9: 1.79 | AM9: 6.55 | AT9: 1.41 | AU9: 2.98 | AX9: =B9+F9+J9+N9+R9+V9+Z9+AD9+AH9+AL9+AP9+AT9 -> 8.41 | AY9: =C9+G9+K9+O9+S9+W9+AA9+AE9+AI9+AM9+AQ9+AU9 -> 32.85 | AZ9: =D9+H9+L9+P9+T9+X9+AB9+AF9+AJ9+AN9+AR9+AV9 -> 0 | BA9: =(AZ9+AY9)/AX9 -> 3.9060642
A10: D & N HAVELI | AX10: =B10+F10+J10+N10+R10+V10+Z10+AD10+AH10+AL10+AP10+AT10 -> 0 | AY10: =C10+G10+K10+O10+S10+W10+AA10+AE10+AI10+AM10+AQ10+AU10 -> 0 | AZ10: =D10+H10+L10+P10+T10+X10+AB10+AF10+AJ10+AN10+AR10+AV10 -> 0 | BA10: =(AZ10+AY10)/AX10 -> #DIV/0!
A11: DAMAN & DIU | AX11: =B11+F11+J11+N11+R11+V11+Z11+AD11+AH11+AL11+AP11+AT11 -> 0 | AY11: =C11+G11+K11+O11+S11+W11+AA11+AE11+AI11+AM11+AQ11+AU11 -> 0 | AZ11: =D11+H11+L11+P11+T11+X11+AB11+AF11+AJ11+AN11+AR11+AV11 -> 0 | BA11: =(AZ11+AY11)/AX11 -> #DIV/0!
A12: DELHI | AT12: 5.5 | AU12: 5.7 | AV12: 1038 | AX12: =B12+F12+J12+N12+R12+V12+Z12+AD12+AH12+AL12+AP12+AT12 -> 5.5 | AY12: =C12+G12+K12+O12+S12+W12+AA12+AE12+AI12+AM12+AQ12+AU12 -> 5.7 | AZ12: =D12+H12+L12+P12+T12+X12+AB12+AF12+AJ12+AN12+AR12+AV12 -> 1038 | BA12: =(AZ12+AY12)/AX12 -> 189.76364
A13: GOA | AX13: =B13+F13+J13+N13+R13+V13+Z13+AD13+AH13+AL13+AP13+AT13 -> 0 | AY13: =C13+G13+K13+O13+S13+W13+AA13+AE13+AI13+AM13+AQ13+AU13 -> 0 | AZ13: =D13+H13+L13+P13+T13+X13+AB13+AF13+AJ13+AN13+AR13+AV13 -> 0 | BA13: =(AZ13+AY13)/AX13 -> #DIV/0!
A14: GUJARAT | Z14: 6.33 | AA14: 59.12 | AH14: 4.11 | AI14: 32.14 | AT14: 5.52 | AU14: 44.24 | AX14: =B14+F14+J14+N14+R14+V14+Z14+AD14+AH14+AL14+AP14+AT14 -> 15.96 | AY14: =C14+G14+K14+O14+S14+W14+AA14+AE14+AI14+AM14+AQ14+AU14 -> 135.5 | AZ14: =D14+H14+L14+P14+T14+X14+AB14+AF14+AJ14+AN14+AR14+AV14 -> 0 | BA14: =(AZ14+AY14)/AX14 -> 8.4899749
A15: HARYANA | J15: 0.07 | K15: 0.75 | L15: 62.68 | R15: 0.9 | T15: 1027.98 | Z15: 5.01 | AA15: 62.97 | AH15: 0.14 | AI15: 0.2 | AJ15: 4.48 | AL15: 0.16 | AM15: 0.02 | AN15: 171.79 | AT15: 0.05 | AU15: 0.21 | AV15: 2.54 | AX15: =B15+F15+J15+N15+R15+V15+Z15+AD15+AH15+AL15+AP15+AT15 -> 6.33 | AY15: =C15+G15+K15+O15+S15+W15+AA15+AE15+AI15+AM15+AQ15+AU15 -> 64.15 | AZ15: =D15+H15+L15+P15+T15+X15+AB15+AF15+AJ15+AN15+AR15+AV15 -> 1269.47 | BA15: =(AZ15+AY15)/AX15 -> 210.68246
A16: HIMACHAL PRADESH | AT16: =0.456+0.403 -> 0.859 | AU16: 35.293 | AV16: 1948.057 | AX16: =B16+F16+J16+N16+R16+V16+Z16+AD16+AH16+AL16+AP16+AT16 -> 0.859 | AY16: =C16+G16+K16+O16+S16+W16+AA16+AE16+AI16+AM16+AQ16+AU16 -> 35.293 | AZ16: =D16+H16+L16+P16+T16+X16+AB16+AF16+AJ16+AN16+AR16+AV16 -> 1948.057 | BA16: =(AZ16+AY16)/AX16 -> 2308.9057
A17: JAMMU & KASHMIR | F17: 0.003 | H17: 18 | J17: 0.012 | L17: 10 | N17: 0.0012 | P17: 3 | R17: 0.0023 | T17: 60.92 | Z17: 0.115 | AA17: 1 | AP17: 0.012 | AR17: 40 | AT17: 0.031 | AU17: 0.06 | AV17: 24 | AX17: =B17+F17+J17+N17+R17+V17+Z17+AD17+AH17+AL17+AP17+AT17 -> 0.1765 | AY17: =C17+G17+K17+O17+S17+W17+AA17+AE17+AI17+AM17+AQ17+AU17 -> 1.06 | AZ17: =D17+H17+L17+P17+T17+X17+AB17+AF17+AJ17+AN17+AR17+AV17 -> 155.92 | BA17: =(AZ17+AY17)/AX17 -> 889.4051
A18: JHARKHAND | AT18: 1.6 | AU18: 22.026 | AV18: 1711 | AX18: =B18+F18+J18+N18+R18+V18+Z18+AD18+AH18+AL18+AP18+AT18 -> 1.6 | AY18: =C18+G18+K18+O18+S18+W18+AA18+AE18+AI18+AM18+AQ18+AU18 -> 22.026 | AZ18: =D18+H18+L18+P18+T18+X18+AB18+AF18+AJ18+AN18+AR18+AV18 -> 1711 | BA18: =(AZ18+AY18)/AX18 -> 1083.1412
A19: KARNATAKA | B19: 0.056 | D19: 23 | E19: =D19/B19 -> 410.71429 | F19: 0.032 | H19: 339 | J19: 5.309 | K19: 63.867 | N19: 0.084 | P19: 297 | R19: 0.241 | T19: 482 | V19: 5.874 | W19: 35.1 | Z19: 7.797 | AA19: 67.133 | AH19: 2.524 | AJ19: 7303 | AL19: 1.752 | AM19: 11.617 | AN19: 1884 | AT19: =2.063+2.457+0.06+0.031+0.031+0.089+0.08+0.739 -> 5.55 | AU19: =19.803+11.209+0.039+0.077+0.012+0.037+2.646 -> 33.823 | AV19: 60 | AX19: =B19+F19+J19+N19+R19+V19+Z19+AD19+AH19+AL19+AP19+AT19 -> 29.219 | AY19: =C19+G19+K19+O19+S19+W19+AA19+AE19+AI19+AM19+AQ19+AU19 -> 211.54 | AZ19: =D19+H19+L19+P19+T19+X19+AB19+AF19+AJ19+AN19+AR19+AV19 -> 10388 | BA19: =(AZ19+AY19)/AX19 -> 362.7619
A20: KERALA | AX20: =B20+F20+J20+N20+R20+V20+Z20+AD20+AH20+AL20+AP20+AT20 -> 0 | AY20: =C20+G20+K20+O20+S20+W20+AA20+AE20+AI20+AM20+AQ20+AU20 -> 0 | AZ20: =D20+H20+L20+P20+T20+X20+AB20+AF20+AJ20+AN20+AR20+AV20 -> 0 | BA20: =(AZ20+AY20)/AX20 -> #DIV/0!
A21: LAKSHDWEEP | AX21: =B21+F21+J21+N21+R21+V21+Z21+AD21+AH21+AL21+AP21+AT21 -> 0 | AY21: =C21+G21+K21+O21+S21+W21+AA21+AE21+AI21+AM21+AQ21+AU21 -> 0 | AZ21: =D21+H21+L21+P21+T21+X21+AB21+AF21+AJ21+AN21+AR21+AV21 -> 0 | BA21: =(AZ21+AY21)/AX21 -> #DIV/0!
A22: MADHYA PRADESH | AT22: 15.613 | AU22: 150.665 | AX22: =B22+F22+J22+N22+R22+V22+Z22+AD22+AH22+AL22+AP22+AT22 -> 15.613 | AY22: =C22+G22+K22+O22+S22+W22+AA22+AE22+AI22+AM22+AQ22+AU22 -> 150.665 | AZ22: =D22+H22+L22+P22+T22+X22+AB22+AF22+AJ22+AN22+AR22+AV22 -> 0 | BA22: =(AZ22+AY22)/AX22 -> 9.6499712
A23: MAHARASHTRA | J23: 2 | K23: 8 | R23: 0.75 | S23: 6 | V23: 2 | W23: 4 | Z23: 6.05 | AA23: 59 | AH23: 5.53 | AI23: 11 | AL23: 0.75 | AM23: 5 | AT23: =1.8 -> 1.8 | AU23: 11 | AV23: 7914 | AX23: =B23+F23+J23+N23+R23+V23+Z23+AD23+AH23+AL23+AP23+AT23 -> 18.88 | AY23: =C23+G23+K23+O23+S23+W23+AA23+AE23+AI23+AM23+AQ23+AU23 -> 104 | AZ23: =D23+H23+L23+P23+T23+X23+AB23+AF23+AJ23+AN23+AR23+AV23 -> 7914 | BA23: =(AZ23+AY23)/AX23 -> 424.6822
A24: MANIPUR | AX24: =B24+F24+J24+N24+R24+V24+Z24+AD24+AH24+AL24+AP24+AT24 -> 0 | AY24: =C24+G24+K24+O24+S24+W24+AA24+AE24+AI24+AM24+AQ24+AU24 -> 0 | AZ24: =D24+H24+L24+P24+T24+X24+AB24+AF24+AJ24+AN24+AR24+AV24 -> 0 | BA24: =(AZ24+AY24)/AX24 -> #DIV/0!
A25: MEGHALAYA | AX25: =B25+F25+J25+N25+R25+V25+Z25+AD25+AH25+AL25+AP25+AT25 -> 0 | AY25: =C25+G25+K25+O25+S25+W25+AA25+AE25+AI25+AM25+AQ25+AU25 -> 0 | AZ25: =D25+H25+L25+P25+T25+X25+AB25+AF25+AJ25+AN25+AR25+AV25 -> 0 | BA25: =(AZ25+AY25)/AX25 -> #DIV/0!
A26: MIZORAM | B26: 0.033 | D26: 90.75 | E26: =D26/B26 -> 2750 | AD26: 0.001 | AF26: 0.0625 | AH26: 0.009 | AJ26: 43.2 | AT26: 0.086 | AV26: 215 | AX26: =B26+F26+J26+N26+R26+V26+Z26+AD26+AH26+AL26+AP26+AT26 -> 0.129 | AY26: =C26+G26+K26+O26+S26+W26+AA26+AE26+AI26+AM26+AQ26+AU26 -> 0 | AZ26: =D26+H26+L26+P26+T26+X26+AB26+AF26+AJ26+AN26+AR26+AV26 -> 349.0125 | BA26: =(AZ26+AY26)/AX26 -> 2705.5233
A27: NAGALAND | B27: 0.002 | D27: 2.04 | E27: =D27/B27 -> 1020 | N27: 0.0018 | P27: 3.24 | AD27: 0.0018 | AF27: 0.216 | AH27: 0.003 | AJ27: 3.6 | AT27: =0.005+0.0048 -> 0.0098 | AV27: =3.38+2.88 -> 6.26 | AX27: =B27+F27+J27+N27+R27+V27+Z27+AD27+AH27+AL27+AP27+AT27 -> 0.0184 | AY27: =C27+G27+K27+O27+S27+W27+AA27+AE27+AI27+AM27+AQ27+AU27 -> 0 | AZ27: =D27+H27+L27+P27+T27+X27+AB27+AF27+AJ27+AN27+AR27+AV27 -> 15.356 | BA27: =(AZ27+AY27)/AX27 -> 834.56522
A28: ODISHA | R28: 2.38 | T28: 2360 | Z28: 2.69 | AA28: 24.66 | AH28: 1.93 | AJ28: 3660 | AL28: 0.54 | AM28: 1.419 | AX28: =B28+F28+J28+N28+R28+V28+Z28+AD28+AH28+AL28+AP28+AT28 -> 7.54 | AY28: =C28+G28+K28+O28+S28+W28+AA28+AE28+AI28+AM28+AQ28+AU28 -> 26.079 | AZ28: =D28+H28+L28+P28+T28+X28+AB28+AF28+AJ28+AN28+AR28+AV28 -> 6020 | BA28: =(AZ28+AY28)/AX28 -> 801.86724
A29: PUDUCHERRY | V29: 0.0174 | W29: 0.104 | Z29: 0.036 | AA29: 0.233 | AL29: 0.0084 | AM29: 0.0378 | AT29: 0.0082 | AU29: 0.0328 | AX29: =B29+F29+J29+N29+R29+V29+Z29+AD29+AH29+AL29+AP29+AT29 -> 0.07 | AY29: =C29+G29+K29+O29+S29+W29+AA29+AE29+AI29+AM29+AQ29+AU29 -> 0.4076 | AZ29: =D29+H29+L29+P29+T29+X29+AB29+AF29+AJ29+AN29+AR29+AV29 -> 0 | BA29: =(AZ29+AY29)/AX29 -> 5.8228571
A30: PUNJAB | AT30: =1.3+0.76 -> 2.06 | AU30: 10.054 | AV30: 0.065 | AX30: =B30+F30+J30+N30+R30+V30+Z30+AD30+AH30+AL30+AP30+AT30 -> 2.06 | AY30: =C30+G30+K30+O30+S30+W30+AA30+AE30+AI30+AM30+AQ30+AU30 -> 10.054 | AZ30: =D30+H30+L30+P30+T30+X30+AB30+AF30+AJ30+AN30+AR30+AV30 -> 0.065 | BA30: =(AZ30+AY30)/AX30 -> 4.9121359
A31: RAJASTHAN | AT31: 2.49 | AU31: 2.69 | AX31: =B31+F31+J31+N31+R31+V31+Z31+AD31+AH31+AL31+AP31+AT31 -> 2.49 | AY31: =C31+G31+K31+O31+S31+W31+AA31+AE31+AI31+AM31+AQ31+AU31 -> 2.69 | AZ31: =D31+H31+L31+P31+T31+X31+AB31+AF31+AJ31+AN31+AR31+AV31 -> 0 | BA31: =(AZ31+AY31)/AX31 -> 1.0803213
A32: SIKKIM | B32: 0.008 | D32: 4.3 | E32: =D32/B32 -> 537.5 | F32: 0.007 | H32: 8.68 | N32: 0.027 | P32: 16.58 | R32: 0.028 | T32: 60 | AH32: 0.024 | AJ32: 26.68 | AT32: =0.03+0.009+0.018+0.038+0.016 -> 0.111 | AU32: 25.95 | AV32: =29+13.76+18+32.05 -> 92.81 | AX32: =B32+F32+J32+N32+R32+V32+Z32+AD32+AH32+AL32+AP32+AT32 -> 0.205 | AY32: =C32+G32+K32+O32+S32+W32+AA32+AE32+AI32+AM32+AQ32+AU32 -> 25.95 | AZ32: =D32+H32+L32+P32+T32+X32+AB32+AF32+AJ32+AN32+AR32+AV32 -> 209.05 | BA32: =(AZ32+AY32)/AX32 -> 1146.3415
A33: TAMIL NADU | AT33: 32.32 | AU33: 332.81 | AX33: =B33+F33+J33+N33+R33+V33+Z33+AD33+AH33+AL33+AP33+AT33 -> 32.32 | AY33: =C33+G33+K33+O33+S33+W33+AA33+AE33+AI33+AM33+AQ33+AU33 -> 332.81 | AZ33: =D33+H33+L33+P33+T33+X33+AB33+AF33+AJ33+AN33+AR33+AV33 -> 0 | BA33: =(AZ33+AY33)/AX33 -> 10.297339
A34: TRIPURA | AX34: =B34+F34+J34+N34+R34+V34+Z34+AD34+AH34+AL34+AP34+AT34 -> 0 | AY34: =C34+G34+K34+O34+S34+W34+AA34+AE34+AI34+AM34+AQ34+AU34 -> 0 | AZ34: =D34+H34+L34+P34+T34+X34+AB34+AF34+AJ34+AN34+AR34+AV34 -> 0 | BA34: =(AZ34+AY34)/AX34 -> #DIV/0!
A35: UTTAR PRADESH | R35: 2.691 | T35: 2691 | Z35: 3.091 | AA35: 6.182 | AH35: 8.711 | AI35: 20.87 | AJ35: 1503 | AX35: =B35+F35+J35+N35+R35+V35+Z35+AD35+AH35+AL35+AP35+AT35 -> 14.493 | AY35: =C35+G35+K35+O35+S35+W35+AA35+AE35+AI35+AM35+AQ35+AU35 -> 27.052 | AZ35: =D35+H35+L35+P35+T35+X35+AB35+AF35+AJ35+AN35+AR35+AV35 -> 4194 | BA35: =(AZ35+AY35)/AX35 -> 291.24764
A36: UTTARAKHAND | AT36: =0.6+0.944 -> 1.544 | AU36: 1.805 | AV36: 3567.56 | AX36: =B36+F36+J36+N36+R36+V36+Z36+AD36+AH36+AL36+AP36+AT36 -> 1.544 | AY36: =C36+G36+K36+O36+S36+W36+AA36+AE36+AI36+AM36+AQ36+AU36 -> 1.805 | AZ36: =D36+H36+L36+P36+T36+X36+AB36+AF36+AJ36+AN36+AR36+AV36 -> 3567.56 | BA36: =(AZ36+AY36)/AX36 -> 2311.7649
A37: WEST BENGAL | J37: 0.52 | L37: 1404 | R37: 2.611 | T37: 3916.5 | V37: 0.468 | W37: 0.646 | Z37: 6.174 | AA37: 52.074 | AH37: 1.688 | AJ37: 7764.8 | AL37: 5 | AN37: 11956.8 | AT37: 7.46 | AU37: 11.19 | AX37: =B37+F37+J37+N37+R37+V37+Z37+AD37+AH37+AL37+AP37+AT37 -> 23.921 | AY37: =C37+G37+K37+O37+S37+W37+AA37+AE37+AI37+AM37+AQ37+AU37 -> 63.91 | AZ37: =D37+H37+L37+P37+T37+X37+AB37+AF37+AJ37+AN37+AR37+AV37 -> 25042.1 | BA37: =(AZ37+AY37)/AX37 -> 1049.5385
BA38: =(AZ38+AY38)/AX38 -> #DIV/0!
A39: TOTAL | B39: =SUM(B4:B38) -> 0.099 | C39: =SUM(C4:C38) -> 0 | D39: =SUM(D4:D38) -> 120.09 | E39: =(D39+C39)/B39 -> 1213.0303 | F39: =SUM(F4:F38) -> 0.042 | G39: =SUM(G4:G38) -> 0 | H39: =SUM(H4:H38) -> 365.68 | I39: =(H39+G39)/F39 -> 8706.6667 | J39: =SUM(J4:J38) -> 18.68 | K39: =SUM(K4:K38) -> 195.095 | L39: =SUM(L4:L38) -> 1476.68 | M39: =(L39+K39)/J39 -> 89.49545 | N39: =SUM(N4:N38) -> 0.114 | O39: =SUM(O4:O38) -> 0 | P39: =SUM(P4:P38) -> 319.82 | Q39: =(P39+O39)/N39 -> 2805.4386 | R39: =SUM(R4:R38) -> 11.6573 | S39: =SUM(S4:S38) -> 11.41 | T39: =SUM(T4:T38) -> 10605.47 | U39: =(T39+S39)/R39 -> 910.74949 | V39: =SUM(V4:V38) -> 41.73525 | W39: =SUM(W4:W38) -> 206.66915 | X39: =SUM(X4:X38) -> 0 | Y39: =(X39+W39)/V39 -> 4.9519088 | Z39: =SUM(Z4:Z38) -> 43.99875 | AA39: =SUM(AA4:AA38) -> 381.98092 | AB39: =SUM(AB4:AB38) -> 0 | AC39: =(AB39+AA39)/Z39 -> 8.6816312 | AD39: =SUM(AD4:AD38) -> 0.0028 | AE39: =SUM(AE4:AE38) -> 0 | AF39: =SUM(AF4:AF38) -> 0.2785 | AG39: =(AF39+AE39)/AD39 -> 99.464286 | AH39: =SUM(AH4:AH38) -> 27.8668 | AI39: =SUM(AI4:AI38) -> 66.16724 | AJ39: =SUM(AJ4:AJ38) -> 27401.08 | AK39: =(AJ39+AI39)/AH39 -> 985.66205 | AL39: =SUM(AL4:AL38) -> 12.4504 | AM39: =SUM(AM4:AM38) -> 39.3458 | AN39: =SUM(AN4:AN38) -> 14012.59 | AO39: =(AN39+AM39)/AL39 -> 1128.6333 | AP39: =SUM(AP4:AP38) -> 0.012 | AQ39: =SUM(AQ4:AQ38) -> 0 | AR39: =SUM(AR4:AR38) -> 40 | AS39: =(AR39+AQ39)/AP39 -> 3333.3333 | AT39: =SUM(AT4:AT38) -> 96.9886 | AU39: =SUM(AU4:AU38) -> 750.9428 | AV39: =SUM(AV4:AV38) -> 20724.292 | AW39: =(AV39+AU39)/AT39 -> 221.4202 | AX39: =SUM(AX4:AX38) -> 253.6469 | AY39: =SUM(AY4:AY38) -> 1651.6109 | AZ39: =SUM(AZ4:AZ38) -> 75065.981 | BA39: =(AZ39+AY39)/AX39 -> 302.45823
A40: A= '000 ha
...

Sheet 12-13
A1: STATES/Uts | B1: ANTHURIUM | F1: CARNATION | J1: CHRYSANTHEMUM | N1: GERBERA | R1: GLADIOUS | V1: JASMINE | Z1: MARIGOLD | AD1: ORCHIDS | AH1: ROSE | AL1: TUBE ROSE | AP1: TULIP | AT1: OTHERS | AW1: TOTAL FLOWERS
B2: A | C2: P | D2: P | F2: A | G2: P | H2: P | J2: A | K2: P | L2: P | N2: A | O2: P | P2: P | R2: A | S2: P | T2: P | V2: A | W2: P | X2: P | Z2: A | AA2: P | AB2: P | AD2: A | AE2: P | AF2: P | AH2: A | AI2: P | AJ2: P | AL2: A | AM2: P | AN2: P | AP2: A | AQ2: P | AR2: P | AT2: A | AU2: P | AV2: P | AW2: A | AX2: P
C3: LOOSE | D3: CUT | G3: LOOSE | H3: CUT | K3: LOOSE | L3: CUT | O3: LOOSE | P3: CUT | S3: LOOSE | T3: CUT | W3: LOOSE | X3: CUT | AA3: LOOSE | AB3: CUT | AE3: LOOSE | AF3: CUT | AI3: LOOSE | AJ3: CUT | AM3: LOOSE | AN3: CUT | AQ3: LOOSE | AR3: CUT | AU3: LOOSE | AV3: CUT | AX3: LOOSE | AY3: CUT
A4: ANDAMAN NICOBAR | V4: 0.01 | W4: 0.01 | Z4: 0.01 | AA4: 0.1 | AH4: 0 | AI4: 0.04 | AT4: 0.02 | AU4: 0.2 | AW4: =B4+F4+J4+N4+R4+V4+Z4+AD4+AH4+AL4+AP4+AT4 -> 0.04 | AX4: =C4+G4+K4+O4+S4+W4+AA4+AE4+AI4+AM4+AQ4+AU4 -> 0.35 | AY4: =D4+H4+L4+P4+T4+X4+AB4+AF4+AJ4+AN4+AR4+AV4 -> 0 | AZ4: =(AY4+AX4)/AW4 -> 8.75
A5: ANDHRA PRADESH | J5: 9.597 | K5: 95.97 | R5: 0.019 | T5: 10 | V5: 3.496 | W5: 17.473 | Z5: 4.802 | AA5: 38.412 | AH5: 2.3 | AJ5: 6899 | AL5: 2.386 | AM5: 14.314 | AT5: =2.01+10.24 -> 12.25 | AU5: =7.035+51.202 -> 58.237 | AW5: =B5+F5+J5+N5+R5+V5+Z5+AD5+AH5+AL5+AP5+AT5 -> 34.85 | AX5: =C5+G5+K5+O5+S5+W5+AA5+AE5+AI5+AM5+AQ5+AU5 -> 224.406 | AY5: =D5+H5+L5+P5+T5+X5+AB5+AF5+AJ5+AN5+AR5+AV5 -> 6909 | AZ5: =(AY5+AX5)/AW5 -> 204.68884
A6: ARUNACHAL PRADESH * | B6: 0.0046 | D6: 116 | N6: 0.004 | P6: 88 | Z6: 0.01 | AA6: 0.0098 | AH6: 0.0045 | AJ6: 93 | AW6: =B6+F6+J6+N6+R6+V6+Z6+AD6+AH6+AL6+AP6+AT6 -> 0.0231 | AX6: =C6+G6+K6+O6+S6+W6+AA6+AE6+AI6+AM6+AQ6+AU6 -> 0.0098 | AY6: =D6+H6+L6+P6+T6+X6+AB6+AF6+AJ6+AN6+AR6+AV6 -> 297 | AZ6: =(AY6+AX6)/AW6 -> 12857.567
A7: ASSAM | AT7: 1.8 | AU7: 11.7 | AV7: 3750 | AW7: =B7+F7+J7+N7+R7+V7+Z7+AD7+AH7+AL7+AP7+AT7 -> 1.8 | AX7: =C7+G7+K7+O7+S7+W7+AA7+AE7+AI7+AM7+AQ7+AU7 -> 11.7 | AY7: =D7+H7+L7+P7+T7+X7+AB7+AF7+AJ7+AN7+AR7+AV7 -> 3750 | AZ7: =(AY7+AX7)/AW7 -> 2089.8333
A8: BIHAR | AT8: =0.18+0.84 -> 1.02 | AU8: 10.152 | AV8: 324 | AW8: =B8+F8+J8+N8+R8+V8+Z8+AD8+AH8+AL8+AP8+AT8 -> 1.02 | AX8: =C8+G8+K8+O8+S8+W8+AA8+AE8+AI8+AM8+AQ8+AU8 -> 10.152 | AY8: =D8+H8+L8+P8+T8+X8+AB8+AF8+AJ8+AN8+AR8+AV8 -> 324 | AZ8: =(AY8+AX8)/AW8 -> 327.6
A9: CHHATTISGARH | J9: 0.25 | K9: 0.74 | R9: 1.98 | S9: 5.18 | V9: 0.03 | W9: 0.05 | Z9: 3.13 | AA9: 19.93 | AH9: 1 | AI9: 2.4 | AL9: 1.79 | AM9: 5.91 | AT9: =0.22+1.39 -> 1.61 | AU9: =0.96+2.58 -> 3.54 | AW9: =B9+F9+J9+N9+R9+V9+Z9+AD9+AH9+AL9+AP9+AT9 -> 9.79 | AX9: =C9+G9+K9+O9+S9+W9+AA9+AE9+AI9+AM9+AQ9+AU9 -> 37.75 | AY9: =D9+H9+L9+P9+T9+X9+AB9+AF9+AJ9+AN9+AR9+AV9 -> 0 | AZ9: =(AY9+AX9)/AW9 -> 3.8559755
A10: D & N HAVELI | AW10: =B10+F10+J10+N10+R10+V10+Z10+AD10+AH10+AL10+AP10+AT10 -> 0 | AX10: =C10+G10+K10+O10+S10+W10+AA10+AE10+AI10+AM10+AQ10+AU10 -> 0 | AY10: =D10+H10+L10+P10+T10+X10+AB10+AF10+AJ10+AN10+AR10+AV10 -> 0 | AZ10: =(AY10+AX10)/AW10 -> #DIV/0!
A11: DAMAN & DIU | AW11: =B11+F11+J11+N11+R11+V11+Z11+AD11+AH11+AL11+AP11+AT11 -> 0 | AX11: =C11+G11+K11+O11+S11+W11+AA11+AE11+AI11+AM11+AQ11+AU11 -> 0 | AY11: =D11+H11+L11+P11+T11+X11+AB11+AF11+AJ11+AN11+AR11+AV11 -> 0 | AZ11: =(AY11+AX11)/AW11 -> #DIV/0!
A12: DELHI | AT12: 5.5 | AU12: 5.7 | AV12: 1038 | AW12: =B12+F12+J12+N12+R12+V12+Z12+AD12+AH12+AL12+AP12+AT12 -> 5.5 | AX12: =C12+G12+K12+O12+S12+W12+AA12+AE12+AI12+AM12+AQ12+AU12 -> 5.7 | AY12: =D12+H12+L12+P12+T12+X12+AB12+AF12+AJ12+AN12+AR12+AV12 -> 1038 | AZ12: =(AY12+AX12)/AW12 -> 189.76364
A13: GOA | AW13: =B13+F13+J13+N13+R13+V13+Z13+AD13+AH13+AL13+AP13+AT13 -> 0 | AX13: =C13+G13+K13+O13+S13+W13+AA13+AE13+AI13+AM13+AQ13+AU13 -> 0 | AY13: =D13+H13+L13+P13+T13+X13+AB13+AF13+AJ13+AN13+AR13+AV13 -> 0 | AZ13: =(AY13+AX13)/AW13 -> #DIV/0!
A14: GUJARAT | Z14: 7.01 | AA14: 66.54 | AH14: 4.42 | AI14: 35.48 | AT14: 5.84 | AU14: 47.25 | AW14: =B14+F14+J14+N14+R14+V14+Z14+AD14+AH14+AL14+AP14+AT14 -> 17.27 | AX14: =C14+G14+K14+O14+S14+W14+AA14+AE14+AI14+AM14+AQ14+AU14 -> 149.27 | AY14: =D14+H14+L14+P14+T14+X14+AB14+AF14+AJ14+AN14+AR14+AV14 -> 0 | AZ14: =(AY14+AX14)/AW14 -> 8.6433121
A15: HARYANA | J15: 0.11 | K15: 0.4 | L15: 20.33 | N15: 0.004 | P15: 2.4 | R15: 0.64 | T15: 826.95 | Z15: 5.37 | AA15: 63.73 | AH15: 0.12 | AI15: 0.39 | AJ15: 154.7 | AL15: 0.12 | AN15: 130.8 | AT15: =0.002+0.1 -> 0.102 | AU15: 0.2 | AV15: =2.4+133 -> 135.4 | AW15: =B15+F15+J15+N15+R15+V15+Z15+AD15+AH15+AL15+AP15+AT15 -> 6.466 | AX15: =C15+G15+K15+O15+S15+W15+AA15+AE15+AI15+AM15+AQ15+AU15 -> 64.72 | AY15: =D15+H15+L15+P15+T15+X15+AB15+AF15+AJ15+AN15+AR15+AV15 -> 1270.58 | AZ15: =(AY15+AX15)/AW15 -> 206.51098
A16: HIMACHAL PRADESH | AT16: =0.345+0.569 -> 0.914 | AU16: 37.707 | AV16: 1760.3 | AW16: =B16+F16+J16+N16+R16+V16+Z16+AD16+AH16+AL16+AP16+AT16 -> 0.914 | AX16: =C16+G16+K16+O16+S16+W16+AA16+AE16+AI16+AM16+AQ16+AU16 -> 37.707 | AY16: =D16+H16+L16+P16+T16+X16+AB16+AF16+AJ16+AN16+AR16+AV16 -> 1760.3 | AZ16: =(AY16+AX16)/AW16 -> 1967.1849
A17: JAMMU & KASHMIR | B17: 0.00035 | C17: 0.0002 | F17: 0.004 | H17: 25 | J17: 0.0005 | L17: 10.25 | N17: 0.002 | P17: 5 | R17: =0.03+0.0075 -> 0.0375 | T17: =62+7.6 -> 69.6 | V17: 0.0005 | W17: 1e-05 | Z17: =0.015+0.716 -> 0.731 | AA17: =0.31+0.017 -> 0.327 | AH17: 0.019 | AJ17: 33.15 | AL17: =0.0002+0.0003 -> 0.0005 | AM17: =0.00003 -> 3e-05 | AN17: 0.8 | AP17: 0.018 | AR17: 45.1 | AT17: =0.001+0.02+0.0015+0.011+0.002+0.005+0.00005 -> 0.04055 | AU17: =0.06+0.015 -> 0.075 | AV17: =3+3+22+5.15+0.045 -> 33.195 | AW17: =B17+F17+J17+N17+R17+V17+Z17+AD17+AH17+AL17+AP17+AT17 -> 0.8539 | AX17: =C17+G17+K17+O17+S17+W17+AA17+AE17+AI17+AM17+AQ17+AU17 -> 0.40224 | AY17: =D17+H17+L17+P17+T17+X17+AB17+AF17+AJ17+AN17+AR17+AV17 -> 222.095 | AZ17: =(AY17+AX17)/AW17 -> 260.56592
A18: JHARKHAND | AT18: 1.6 | AU18: 22.026 | AV18: 1711 | AW18: =B18+F18+J18+N18+R18+V18+Z18+AD18+AH18+AL18+AP18+AT18 -> 1.6 | AX18: =C18+G18+K18+O18+S18+W18+AA18+AE18+AI18+AM18+AQ18+AU18 -> 22.026 | AY18: =D18+H18+L18+P18+T18+X18+AB18+AF18+AJ18+AN18+AR18+AV18 -> 1711 | AZ18: =(AY18+AX18)/AW18 -> 1083.1412
A19: KARNATAKA | D19: 7.3 | H19: 114.7 | J19: 5.4 | K19: 66.5 | P19: 104.2 | R19: 0.2 | T19: 654.4 | V19: 4.8 | W19: 29.3 | Z19: 8.5 | AA19: 74 | AF19: 0.1 | AH19: 2.8 | AJ19: 7132 | AL19: =1.8+0.3 -> 2.1 | AN19: =16.1+1413 -> 1429.1 | AT19: 5.9 | AU19: 37.7 | AW19: =B19+F19+J19+N19+R19+V19+Z19+AD19+AH19+AL19+AP19+AT19 -> 29.7 | AX19: =C19+G19+K19+O19+S19+W19+AA19+AE19+AI19+AM19+AQ19+AU19 -> 207.5 | AY19: =D19+H19+L19+P19+T19+X19+AB19+AF19+AJ19+AN19+AR19+AV19 -> 9441.8 | AZ19: =(AY19+AX19)/AW19 -> 324.89226
A20: KERALA | AW20: =B20+F20+J20+N20+R20+V20+Z20+AD20+AH20+AL20+AP20+AT20 -> 0 | AX20: =C20+G20+K20+O20+S20+W20+AA20+AE20+AI20+AM20+AQ20+AU20 -> 0 | AY20: =D20+H20+L20+P20+T20+X20+AB20+AF20+AJ20+AN20+AR20+AV20 -> 0 | AZ20: =(AY20+AX20)/AW20 -> #DIV/0!
A21: LAKSHADWEEP | AW21: =B21+F21+J21+N21+R21+V21+Z21+AD21+AH21+AL21+AP21+AT21 -> 0 | AX21: =C21+G21+K21+O21+S21+W21+AA21+AE21+AI21+AM21+AQ21+AU21 -> 0 | AY21: =D21+H21+L21+P21+T21+X21+AB21+AF21+AJ21+AN21+AR21+AV21 -> 0 | AZ21: =(AY21+AX21)/AW21 -> #DIV/0!
A22: MADHYA PRADESH | AT22: 16.515 | AU22: 193 | AW22: =B22+F22+J22+N22+R22+V22+Z22+AD22+AH22+AL22+AP22+AT22 -> 16.515 | AX22: =C22+G22+K22+O22+S22+W22+AA22+AE22+AI22+AM22+AQ22+AU22 -> 193 | AY22: =D22+H22+L22+P22+T22+X22+AB22+AF22+AJ22+AN22+AR22+AV22 -> 0 | AZ22: =(AY22+AX22)/AW22 -> 11.686346
A23: MAHARASHTRA | J23: 3 | K23: 12 | R23: 1 | S23: 7 | V23: 2 | W23: 4 | Z23: 7 | AA23: 65 | AH23: 6 | AI23: 13 | AL23: 1 | AM23: 6 | AT23: 2 | AU23: 12 | AV23: 7914 | AW23: =B23+F23+J23+N23+R23+V23+Z23+AD23+AH23+AL23+AP23+AT23 -> 22 | AX23: =C23+G23+K23+O23+S23+W23+AA23+AE23+AI23+AM23+AQ23+AU23 -> 119 | AY23: =D23+H23+L23+P23+T23+X23+AB23+AF23+AJ23+AN23+AR23+AV23 -> 7914 | AZ23: =(AY23+AX23)/AW23 -> 365.13636
A24: MANIPUR | AW24: =B24+F24+J24+N24+R24+V24+Z24+AD24+AH24+AL24+AP24+AT24 -> 0 | AX24: =C24+G24+K24+O24+S24+W24+AA24+AE24+AI24+AM24+AQ24+AU24 -> 0 | AY24: =D24+H24+L24+P24+T24+X24+AB24+AF24+AJ24+AN24+AR24+AV24 -> 0 | AZ24: =(AY24+AX24)/AW24 -> #DIV/0!
A25: MEGHALAYA | AW25: =B25+F25+J25+N25+R25+V25+Z25+AD25+AH25+AL25+AP25+AT25 -> 0 | AX25: =C25+G25+K25+O25+S25+W25+AA25+AE25+AI25+AM25+AQ25+AU25 -> 0 | AY25: =D25+H25+L25+P25+T25+X25+AB25+AF25+AJ25+AN25+AR25+AV25 -> 0 | AZ25: =(AY25+AX25)/AW25 -> #DIV/0!
A26: MIZORAM | B26: 0.051 | D26: 141.27 | N26: 0.023 | P26: 32.2 | AD26: 0.012 | AF26: 0.077 | AH26: 0.01 | AJ26: 45.8 | AT26: 0.067 | AU26: 166.83 | AV26: 385.87 | AW26: =B26+F26+J26+N26+R26+V26+Z26+AD26+AH26+AL26+AP26+AT26 -> 0.163 | AX26: =C26+G26+K26+O26+S26+W26+AA26+AE26+AI26+AM26+AQ26+AU26 -> 166.83 | AY26: =D26+H26+L26+P26+T26+X26+AB26+AF26+AJ26+AN26+AR26+AV26 -> 605.217 | AZ26: =(AY26+AX26)/AW26 -> 4736.4847
A27: NAGALAND | B27: 0.00292 | D27: 51.2 | N27: 0.0004 | P27: 0.396 | AH27: 0.00182 | AJ27: 16.113 | AT27: =0.00188+0.00112 -> 0.003 | AV27: =11.28+17.67 -> 28.95 | AW27: =B27+F27+J27+N27+R27+V27+Z27+AD27+AH27+AL27+AP27+AT27 -> 0.00814 | AX27: =C27+G27+K27+O27+S27+W27+AA27+AE27+AI27+AM27+AQ27+AU27 -> 0 | AY27: =D27+H27+L27+P27+T27+X27+AB27+AF27+AJ27+AN27+AR27+AV27 -> 96.659 | AZ27: =(AY27+AX27)/AW27 -> 11874.57
A28: ODISHA | R28: 2.37 | T28: 2350 | Z28: 2.69 | AA28: 24.707 | AH28: 1.91 | AJ28: 3690 | AL28: 0.55 | AM28: 1.455 | AW28: =B28+F28+J28+N28+R28+V28+Z28+AD28+AH28+AL28+AP28+AT28 -> 7.52 | AX28: =C28+G28+K28+O28+S28+W28+AA28+AE28+AI28+AM28+AQ28+AU28 -> 26.162 | AY28: =D28+H28+L28+P28+T28+X28+AB28+AF28+AJ28+AN28+AR28+AV28 -> 6040 | AZ28: =(AY28+AX28)/AW28 -> 806.67048
A29: PUDUCHERRY | V29: 0.013 | W29: 0.061 | Z29: 0.046 | AA29: 0.298 | AH29: 0.002 | AI29: 0.005 | AL29: 0.006 | AM29: 0.026 | AT29: 0.009 | AU29: 0.037 | AW29: =B29+F29+J29+N29+R29+V29+Z29+AD29+AH29+AL29+AP29+AT29 -> 0.076 | AX29: =C29+G29+K29+O29+S29+W29+AA29+AE29+AI29+AM29+AQ29+AU29 -> 0.427 | AY29: =D29+H29+L29+P29+T29+X29+AB29+AF29+AJ29+AN29+AR29+AV29 -> 0 | AZ29: =(AY29+AX29)/AW29 -> 5.6184211
A30: PUNJAB | AT30: =1.34+0.77 -> 2.11 | AU30: =10.38+0.07 -> 10.45 | AW30: =B30+F30+J30+N30+R30+V30+Z30+AD30+AH30+AL30+AP30+AT30 -> 2.11 | AX30: =C30+G30+K30+O30+S30+W30+AA30+AE30+AI30+AM30+AQ30+AU30 -> 10.45 | AY30: =D30+H30+L30+P30+T30+X30+AB30+AF30+AJ30+AN30+AR30+AV30 -> 0 | AZ30: =(AY30+AX30)/AW30 -> 4.9526066
A31: RAJASTHAN | AT31: 3.434 | AU31: 3.719 | AW31: =B31+F31+J31+N31+R31+V31+Z31+AD31+AH31+AL31+AP31+AT31 -> 3.434 | AX31: =C31+G31+K31+O31+S31+W31+AA31+AE31+AI31+AM31+AQ31+AU31 -> 3.719 | AY31: =D31+H31+L31+P31+T31+X31+AB31+AF31+AJ31+AN31+AR31+AV31 -> 0 | AZ31: =(AY31+AX31)/AW31 -> 1.0829936
A32: SIKKIM | B32: 0.009 | D32: 4.5 | F32: 0.007 | H32: 9 | N32: 0.03 | P32: 17 | R32: 0.029 | T32: 65 | AH32: 0.023 | AJ32: 23 | AT32: =0.035+0.015+0.018+0.039+0.017 -> 0.124 | AU32: 26.5 | AV32: =30+14.5+18.5+32.6 -> 95.6 | AW32: =B32+F32+J32+N32+R32+V32+Z32+AD32+AH32+AL32+AP32+AT32 -> 0.222 | AX32: =C32+G32+K32+O32+S32+W32+AA32+AE32+AI32+AM32+AQ32+AU32 -> 26.5 | AY32: =D32+H32+L32+P32+T32+X32+AB32+AF32+AJ32+AN32+AR32+AV32 -> 214.1 | AZ32: =(AY32+AX32)/AW32 -> 1083.7838
A33: TAMIL NADU | AT33: 28.71 | AU33: 312.97 | AV33: 1168 | AW33: =B33+F33+J33+N33+R33+V33+Z33+AD33+AH33+AL33+AP33+AT33 -> 28.71 | AX33: =C33+G33+K33+O33+S33+W33+AA33+AE33+AI33+AM33+AQ33+AU33 -> 312.97 | AY33: =D33+H33+L33+P33+T33+X33+AB33+AF33+AJ33+AN33+AR33+AV33 -> 1168 | AZ33: =(AY33+AX33)/AW33 -> 51.583769
A34: TRIPURA | AW34: =B34+F34+J34+N34+R34+V34+Z34+AD34+AH34+AL34+AP34+AT34 -> 0 | AX34: =C34+G34+K34+O34+S34+W34+AA34+AE34+AI34+AM34+AQ34+AU34 -> 0 | AY34: =D34+H34+L34+P34+T34+X34+AB34+AF34+AJ34+AN34+AR34+AV34 -> 0 | AZ34: =(AY34+AX34)/AW34 -> #DIV/0!
A35: UTTAR PRADESH | R35: 3.092 | T35: 3092 | Z35: 3.576 | AA35: 7.152 | AH35: =7.704+1.816 -> 9.52 | AI35: 24.342 | AJ35: 1816 | AW35: =B35+F35+J35+N35+R35+V35+Z35+AD35+AH35+AL35+AP35+AT35 -> 16.188 | AX35: =C35+G35+K35+O35+S35+W35+AA35+AE35+AI35+AM35+AQ35+AU35 -> 31.494 | AY35: =D35+H35+L35+P35+T35+X35+AB35+AF35+AJ35+AN35+AR35+AV35 -> 4908 | AZ35: =(AY35+AX35)/AW35 -> 305.13306
A36: UTTARAKHAND | AT36: =0.607+0.954 -> 1.561 | AU36: 1.824 | AV36: 3633 | AW36: =B36+F36+J36+N36+R36+V36+Z36+AD36+AH36+AL36+AP36+AT36 -> 1.561 | AX36: =C36+G36+K36+O36+S36+W36+AA36+AE36+AI36+AM36+AQ36+AU36 -> 1.824 | AY36: =D36+H36+L36+P36+T36+X36+AB36+AF36+AJ36+AN36+AR36+AV36 -> 3633 | AZ36: =(AY36+AX36)/AW36 -> 2328.5227
A37: WEST BENGAL | AT37: =10.045+14.365 -> 24.41 | AU37: 65.143 | AV37: 25429.1 | AW37: =B37+F37+J37+N37+R37+V37+Z37+AD37+AH37+AL37+AP37+AT37 -> 24.41 | AX37: =C37+G37+K37+O37+S37+W37+AA37+AE37+AI37+AM37+AQ37+AU37 -> 65.143 | AY37: =D37+H37+L37+P37+T37+X37+AB37+AF37+AJ37+AN37+AR37+AV37 -> 25429.1 | AZ37: =(AY37+AX37)/AW37 -> 1044.418
AZ38: =(AY38+AX38)/AW38 -> #DIV/0!
A39: TOTAL | B39: =SUM(B4:B38) -> 0.06787 | C39: =SUM(C4:C38) -> 0.0002 | D39: =SUM(D4:D38) -> 320.27 | E39: =(D39+C39)/B39 -> 4718.8773 | F39: =SUM(F4:F38) -> 0.011 | G39: =SUM(G4:G38) -> 0 | H39: =SUM(H4:H38) -> 148.7 | I39: =(H39+G39)/F39 -> 13518.182 | J39: =SUM(J4:J38) -> 18.3575 | K39: =SUM(K4:K38) -> 175.61 | L39: =SUM(L4:L38) -> 30.58 | M39: =(L39+K39)/J39 -> 11.231922 | N39: =SUM(N4:N38) -> 0.0634 | O39: =SUM(O4:O38) -> 0 | P39: =SUM(P4:P38) -> 249.196 | Q39: =(P39+O39)/N39 -> 3930.5363 | R39: =SUM(R4:R38) -> 9.3675 | S39: =SUM(S4:S38) -> 12.18 | T39: =SUM(T4:T38) -> 7067.95 | U39: =(T39+S39)/R39 -> 755.81852 | V39: =SUM(V4:V38) -> 10.3495 | W39: =SUM(W4:W38) -> 50.89401 | X39: =SUM(X4:X38) -> 0 | Y39: =(X39+W39)/V39 -> 4.9175332 | Z39: =SUM(Z4:Z38) -> 42.875 | AA39: =SUM(AA4:AA38) -> 360.2058 | AB39: =SUM(AB4:AB38) -> 0 | AC39: =(AB39+AA39)/Z39 -> 8.4013015 | AD39: =SUM(AD4:AD38) -> 0.012 | AE39: =SUM(AE4:AE38) -> 0 | AF39: =SUM(AF4:AF38) -> 0.177 | AG39: =(AF39+AE39)/AD39 -> 14.75 | AH39: =SUM(AH4:AH38) -> 28.13032 | AI39: =SUM(AI4:AI38) -> 75.657 | AJ39: =SUM(AJ4:AJ38) -> 19902.763 | AK39: =(AJ39+AI39)/AH39 -> 710.20948 | AL39: =SUM(AL4:AL38) -> 7.9525 | AM39: =SUM(AM4:AM38) -> 27.70503 | AN39: =SUM(AN4:AN38) -> 1560.7 | AO39: =(AN39+AM39)/AL39 -> 199.73656 | AP39: =SUM(AP4:AP38) -> 0.018 | AQ39: =SUM(AQ4:AQ38) -> 0 | AR39: =SUM(AR4:AR38) -> 45.1 | AS39: =(AR39+AQ39)/AP39 -> 2505.5556 | AT39: =SUM(AT4:AT38) -> 115.53955 | AU39: =SUM(AU4:AU38) -> 1026.96 | AV39: =SUM(AV4:AV38) -> 47406.415 | AW39: =SUM(AW4:AW38) -> 232.74414 | AX39: =SUM(AX4:AX38) -> 1729.212 | AY39: =SUM(AY4:AY38) -> 76731.851 | AZ39: =(AY39+AX39)/AW39 -> 337.11295
A40: Note : Area in '000 Ha | E40: =(D39+C39)/B39 -> 4718.8773 | L40: =L39+K39 -> 206.19 | T40: =T39+S39 -> 7080.13 | AJ40: =AJ39+AI39 -> 19978.42 | AN40: =AN39+AM39 -> 1588.405 | AY40: =AY39+AX39 -> 78461.063
...

Sheet 13-14
A1: STATES/UTs | B1: ANTHURIUM | F1: CARNATION | J1: CHRYSANTHEMUM | N1: GERBERA | R1: GLADIOLUS | V1: JASMINE | Z1: MARIGOLD | AD1: ORCHIDS | AH1: ROSE | AL1: TUBE ROSE | AP1: TULIP | AT1: OTHERS | AX1: TOTAL FLOWERS
B2: A | C2: P | D2: P | F2: A | G2: P | H2: P | J2: A | K2: P | L2: P | N2: A | O2: P | P2: P | R2: A | S2: P | T2: P | V2: A | W2: P | X2: P | Z2: A | AA2: P | AB2: P | AD2: A | AE2: P | AF2: P | AH2: A | AI2: P | AJ2: P | AL2: A | AM2: P | AN2: P | AP2: A | AQ2: P | AR2: P | AT2: A | AU2: P | AV2: P | AX2: A | AY2: P
C3: LOOSE | D3: CUT | G3: LOOSE | H3: CUT | K3: LOOSE | L3: CUT | O3: LOOSE | P3: CUT | S3: LOOSE | T3: CUT | W3: LOOSE | X3: CUT | AA3: LOOSE | AB3: CUT | AE3: LOOSE | AF3: CUT | AI3: LOOSE | AJ3: CUT | AM3: LOOSE | AN3: CUT | AQ3: LOOSE | AR3: CUT | AU3: LOOSE | AV3: CUT | AY3: LOOSE | AZ3: CUT
A4: ANDAMAN NICOBAR | V4: 0.01 | W4: 0.02 | Z4: 0.03 | AA4: 0.09 | AH4: 0.01 | AI4: 0.02 | AT4: 0.08 | AU4: 0.16 | AX4: =B4+F4+J4+N4+R4+V4+Z4+AD4+AH4+AL4+AP4+AT4 -> 0.13 | AY4: =C4+G4+K4+O4+S4+W4+AA4+AE4+AI4+AM4+AQ4+AU4 -> 0.29 | AZ4: =D4+H4+L4+P4+T4+X4+AB4+AF4+AJ4+AN4+AR4+AV4 -> 0 | BA4: =(AZ4+AY4)/AX4 -> 2.2307692
A5: ANDHRA PRADESH | J5: 6.135 | K5: 70.553 | V5: 2.435 | W5: 12.175 | Z5: 3.285 | AA5: 24.638 | AH5: 1.3 | AJ5: 30 | AL5: 2.313 | AM5: 13.878 | AT5: 4.905 | AU5: 15.023 | AX5: =B5+F5+J5+N5+R5+V5+Z5+AD5+AH5+AL5+AP5+AT5 -> 20.373 | AY5: =C5+G5+K5+O5+S5+W5+AA5+AE5+AI5+AM5+AQ5+AU5 -> 136.267 | AZ5: =D5+H5+L5+P5+T5+X5+AB5+AF5+AJ5+AN5+AR5+AV5 -> 30 | BA5: =(AZ5+AY5)/AX5 -> 8.1611447
A6: ARUNACHAL PRADESH | B6: 0.0046 | D6: 0.64444444 | N6: 0.004 | P6: 0.50285714 | Z6: 0.01 | AA6: 0.0098 | AH6: 0.0045 | AJ6: 0.71538462 | AX6: =B6+F6+J6+N6+R6+V6+Z6+AD6+AH6+AL6+AP6+AT6 -> 0.0231 | AY6: =C6+G6+K6+O6+S6+W6+AA6+AE6+AI6+AM6+AQ6+AU6 -> 0.0098 | AZ6: =D6+H6+L6+P6+T6+X6+AB6+AF6+AJ6+AN6+AR6+AV6 -> 1.8626862 | BA6: =(AZ6+AY6)/AX6 -> 81.060009
A7: ASSAM | B7: 0.06 | C7: 0.396 | D7: 0.56666667 | F7: 0.09 | G7: 0.594 | H7: 0.72857143 | J7: 0.12 | K7: 0.792 | L7: 1.1333333 | N7: 0.6 | O7: 3.96 | P7: 5.8285714 | R7: 0.21 | S7: 1.386 | T7: 4.4625 | V7: 0.18 | W7: 1.188 | X7: 1.7 | Z7: 0.45 | AA7: 2.97 | AB7: 4.25 | AD7: 0.36 | AE7: 2.476 | AF7: 4.7076923 | AH7: 0.3 | AI7: 1.98 | AJ7: 3.9230769 | AT7: 0.63 | AU7: 4.258 | AV7: 5.3944444 | AX7: =B7+F7+J7+N7+R7+V7+Z7+AD7+AH7+AL7+AP7+AT7 -> 3 | AY7: =C7+G7+K7+O7+S7+W7+AA7+AE7+AI7+AM7+AQ7+AU7 -> 20 | AZ7: =D7+H7+L7+P7+T7+X7+AB7+AF7+AJ7+AN7+AR7+AV7 -> 32.694857 | BA7: =(AZ7+AY7)/AX7 -> 17.564952
A8: BIHAR | R8: 0.08 | T8: 2.05375 | V8: 0.113 | W8: 0.317 | Z8: 0.314 | AA8: 5.603 | AH8: 0.073 | AI8: 0.098 | AJ8: 0.68976923 | AL8: 0.11 | AM8: 0.535 | AT8: 0.132 | AU8: 1.08 | AX8: =B8+F8+J8+N8+R8+V8+Z8+AD8+AH8+AL8+AP8+AT8 -> 0.822 | AY8: =C8+G8+K8+O8+S8+W8+AA8+AE8+AI8+AM8+AQ8+AU8 -> 7.633 | AZ8: =D8+H8+L8+P8+T8+X8+AB8+AF8+AJ8+AN8+AR8+AV8 -> 2.7435192 | BA8: =(AZ8+AY8)/AX8 -> 12.623503
A9: CHHATTISGARH | J9: 0.28 | K9: 1 | L9: 0 | R9: 1.67 | S9: 5.77 | V9: 0.04 | W9: 0.09 | Z9: 3.66 | AA9: 26.16 | AH9: 0.96 | AI9: 2.57 | AL9: 1.41 | AM9: 5.54 | AT9: =0.16+1.95 -> 2.11 | AU9: =0.87+3.73 -> 4.6 | AX9: =B9+F9+J9+N9+R9+V9+Z9+AD9+AH9+AL9+AP9+AT9 -> 10.13 | AY9: =C9+G9+K9+O9+S9+W9+AA9+AE9+AI9+AM9+AQ9+AU9 -> 45.73 | AZ9: =D9+H9+L9+P9+T9+X9+AB9+AF9+AJ9+AN9+AR9+AV9 -> 0 | BA9: =(AZ9+AY9)/AX9 -> 4.5143139
A10: D & N HAVELI | AX10: =B10+F10+J10+N10+R10+V10+Z10+AD10+AH10+AL10+AP10+AT10 -> 0 | AY10: =C10+G10+K10+O10+S10+W10+AA10+AE10+AI10+AM10+AQ10+AU10 -> 0 | AZ10: =D10+H10+L10+P10+T10+X10+AB10+AF10+AJ10+AN10+AR10+AV10 -> 0 | BA10: =(AZ10+AY10)/AX10 -> #DIV/0!
A11: DAMAN & DIU | AX11: =B11+F11+J11+N11+R11+V11+Z11+AD11+AH11+AL11+AP11+AT11 -> 0 | AY11: =C11+G11+K11+O11+S11+W11+AA11+AE11+AI11+AM11+AQ11+AU11 -> 0 | AZ11: =D11+H11+L11+P11+T11+X11+AB11+AF11+AJ11+AN11+AR11+AV11 -> 0 | BA11: =(AZ11+AY11)/AX11 -> #DIV/0!
A12: DELHI | AT12: 5.5 | AU12: 5.7 | AV12: 5.7666667 | AX12: =B12+F12+J12+N12+R12+V12+Z12+AD12+AH12+AL12+AP12+AT12 -> 5.5 | AY12: =C12+G12+K12+O12+S12+W12+AA12+AE12+AI12+AM12+AQ12+AU12 -> 5.7 | AZ12: =D12+H12+L12+P12+T12+X12+AB12+AF12+AJ12+AN12+AR12+AV12 -> 5.7666667 | BA12: =(AZ12+AY12)/AX12 -> 2.0848485
A13: GOA | B13: 0.0002 | D13: 0.0033333333 | J13: 0.0002 | L13: 0.0027777778 | N13: 0.0008 | P13: 0.092 | V13: 0.0001 | W13: 0.003 | Z13: 0.003 | AA13: 0.017 | AD13: 0.0001 | AF13: 0.0023076923 | AL13: 0.0001 | AM13: 0.001 | AT13: 0.002 | AU13: 0.002 | AX13: =B13+F13+J13+N13+R13+V13+Z13+AD13+AH13+AL13+AP13+AT13 -> 0.0065 | AY13: =C13+G13+K13+O13+S13+W13+AA13+AE13+AI13+AM13+AQ13+AU13 -> 0.023 | AZ13: =D13+H13+L13+P13+T13+X13+AB13+AF13+AJ13+AN13+AR13+AV13 -> 0.1004188 | BA13: =(AZ13+AY13)/AX13 -> 18.987508
A14: GUJARAT | Z14: 7.22 | AA14: 68.93 | AH14: 4.12 | AI14: 37.36 | AT14: 5.96 | AU14: 57.31 | AX14: =B14+F14+J14+N14+R14+V14+Z14+AD14+AH14+AL14+AP14+AT14 -> 17.3 | AY14: =C14+G14+K14+O14+S14+W14+AA14+AE14+AI14+AM14+AQ14+AU14 -> 163.6 | AZ14: =D14+H14+L14+P14+T14+X14+AB14+AF14+AJ14+AN14+AR14+AV14 -> 0 | BA14: =(AZ14+AY14)/AX14 -> 9.4566474
A15: HARYANA | J15: 0.06 | K15: 0.06 | L15: 0.65333333 | N15: 0.01 | P15: 0.028857143 | R15: 0.37 | T15: 6.25625 | Z15: 5.69 | AA15: 64.62 | AH15: 0.17 | AI15: 0.64 | AJ15: 2.583 | AL15: 0.1 | AN15: 0.76944444 | AT15: =0.01+0.07 -> 0.08 | AU15: 0.13 | AV15: 0.96433333 | AX15: =B15+F15+J15+N15+R15+V15+Z15+AD15+AH15+AL15+AP15+AT15 -> 6.48 | AY15: =C15+G15+K15+O15+S15+W15+AA15+AE15+AI15+AM15+AQ15+AU15 -> 65.45 | AZ15: =D15+H15+L15+P15+T15+X15+AB15+AF15+AJ15+AN15+AR15+AV15 -> 11.255218 | BA15: =(AZ15+AY15)/AX15 -> 11.837225
A16: HIMACHAL PRADESH | F16: 0.059 | H16: 2.7460238 | J16: =0.086+0.205 -> 0.291 | K16: 8.218 | L16: 3.8017778 | N16: 0.006 | P16: 0.39085714 | R16: 0.122 | T16: 2.8953625 | Z16: 0.226 | AA16: 19.921 | AH16: 0.035 | AJ16: 1.9828462 | AT16: 0.084 | AU16: 0.0003 | AV16: 0.54125 | AX16: =B16+F16+J16+N16+R16+V16+Z16+AD16+AH16+AL16+AP16+AT16 -> 0.823 | AY16: =C16+G16+K16+O16+S16+W16+AA16+AE16+AI16+AM16+AQ16+AU16 -> 28.1393 | AZ16: =D16+H16+L16+P16+T16+X16+AB16+AF16+AJ16+AN16+AR16+AV16 -> 12.358117 | BA16: =(AZ16+AY16)/AX16 -> 49.207069
A17: JAMMU & KASHMIR | F17: 0.004 | H17: 0.13945238 | J17: 0.005 | K17: 0.000467 | L17: 0.055555556 | N17: =0.00264+0.00005 -> 0.00269 | P17: 0.10158857 | R17: =0.00465+0.031 -> 0.03565 | T17: 0.808125 | Z17: =0.60778+0.016 -> 0.62378 | AA17: =0.31+0.01458 -> 0.32458 | AH17: 0.01925 | AI17: 0.0167 | AJ17: 0.25692308 | AL17: =0.0013+0.00005 -> 0.00135 | AN17: 0.02295 | AP17: 0.018 | AR17: 0.25055556 | AT17: =0.006+0.002+0.011+0.003+0.022+0.001+0.00015 -> 0.04515 | AU17: =0.018+0.0605+0.00015 -> 0.07865 | AV17: 0.1837 | AX17: =B17+F17+J17+N17+R17+V17+Z17+AD17+AH17+AL17+AP17+AT17 -> 0.75487 | AY17: =C17+G17+K17+O17+S17+W17+AA17+AE17+AI17+AM17+AQ17+AU17 -> 0.420397 | AZ17: =D17+H17+L17+P17+T17+X17+AB17+AF17+AJ17+AN17+AR17+AV17 -> 1.8188501 | BA17: =(AZ17+AY17)/AX17 -> 2.966401
A18: JHARKHAND | AT18: 1.6 | AU18: 22.026 | AV18: 9.5055556 | AX18: =B18+F18+J18+N18+R18+V18+Z18+AD18+AH18+AL18+AP18+AT18 -> 1.6 | AY18: =C18+G18+K18+O18+S18+W18+AA18+AE18+AI18+AM18+AQ18+AU18 -> 22.026 | AZ18: =D18+H18+L18+P18+T18+X18+AB18+AF18+AJ18+AN18+AR18+AV18 -> 9.5055556 | BA18: =(AZ18+AY18)/AX18 -> 19.707222
A19: KARNATAKA | D19: 0.15555556 | H19: 0.69142857 | J19: 4.7 | K19: 61 | L19: 0 | P19: 0.58171429 | R19: 0.2 | T19: 6.38875 | V19: 6.6 | W19: 43.6 | Z19: 9.1 | AA19: 74.9 | AF19: 0.040769231 | AH19: 2.7 | AJ19: 50.56 | AL19: 2 | AN19: 13.109444 | AT19: 5.3 | AU19: 32 | AX19: =B19+F19+J19+N19+R19+V19+Z19+AD19+AH19+AL19+AP19+AT19 -> 30.6 | AY19: =C19+G19+K19+O19+S19+W19+AA19+AE19+AI19+AM19+AQ19+AU19 -> 211.5 | AZ19: =D19+H19+L19+P19+T19+X19+AB19+AF19+AJ19+AN19+AR19+AV19 -> 71.527662 | BA19: =(AZ19+AY19)/AX19 -> 9.24927
A20: KERALA | AX20: =B20+F20+J20+N20+R20+V20+Z20+AD20+AH20+AL20+AP20+AT20 -> 0 | AY20: =C20+G20+K20+O20+S20+W20+AA20+AE20+AI20+AM20+AQ20+AU20 -> 0 | AZ20: =D20+H20+L20+P20+T20+X20+AB20+AF20+AJ20+AN20+AR20+AV20 -> 0 | BA20: =(AZ20+AY20)/AX20 -> #DIV/0!
A21: LAKSHADWEEP | AX21: =B21+F21+J21+N21+R21+V21+Z21+AD21+AH21+AL21+AP21+AT21 -> 0 | AY21: =C21+G21+K21+O21+S21+W21+AA21+AE21+AI21+AM21+AQ21+AU21 -> 0 | AZ21: =D21+H21+L21+P21+T21+X21+AB21+AF21+AJ21+AN21+AR21+AV21 -> 0 | BA21: =(AZ21+AY21)/AX21 -> #DIV/0!
A22: MADHYA PRADESH | J22: 0.8 | K22: 10.496 | L22: 0 | R22: 1.96 | S22: 38.004 | Z22: 7.755 | AA22: 85.072 | AH22: 2.381 | AI22: 13.262 | AL22: 0.263 | AM22: 0.999 | AT22: 3.905 | AU22: 52.561 | AX22: =B22+F22+J22+N22+R22+V22+Z22+AD22+AH22+AL22+AP22+AT22 -> 17.064 | AY22: =C22+G22+K22+O22+S22+W22+AA22+AE22+AI22+AM22+AQ22+AU22 -> 200.394 | AZ22: =D22+H22+L22+P22+T22+X22+AB22+AF22+AJ22+AN22+AR22+AV22 -> 0 | BA22: =(AZ22+AY22)/AX22 -> 11.743671
A23: MAHARASHTRA | J23: 3 | K23: 13.05 | R23: 1 | S23: 5 | V23: 2 | W23: 3.5 | Z23: 8 | AA23: 70 | AH23: 6 | AI23: 15 | AL23: 1 | AM23: 6.1 | AT23: 2 | AU23: 10 | AV23: 43.966667 | AX23: =B23+F23+J23+N23+R23+V23+Z23+AD23+AH23+AL23+AP23+AT23 -> 23 | AY23: =C23+G23+K23+O23+S23+W23+AA23+AE23+AI23+AM23+AQ23+AU23 -> 122.65 | AZ23: =D23+H23+L23+P23+T23+X23+AB23+AF23+AJ23+AN23+AR23+AV23 -> 43.966667 | BA23: =(AZ23+AY23)/AX23 -> 7.2442029
A24: MANIPUR | AT24: 0.76 | AU24: 0.282 | AV24: 0.0097777778 | AX24: =B24+F24+J24+N24+R24+V24+Z24+AD24+AH24+AL24+AP24+AT24 -> 0.76 | AY24: =C24+G24+K24+O24+S24+W24+AA24+AE24+AI24+AM24+AQ24+AU24 -> 0.282 | AZ24: =D24+H24+L24+P24+T24+X24+AB24+AF24+AJ24+AN24+AR24+AV24 -> 0.0097777778 | BA24: =(AZ24+AY24)/AX24 -> 0.38391813
A25: MEGHALAYA | B25: 0.021 | D25: 0.70277778 | F25: 0.003 | H25: 0.29619048 | J25: 0.003 | L25: 0.070833333 | N25: 0.013 | P25: 0.83285714 | AD25: 0.012 | AF25: 0.46884615 | AX25: =B25+F25+J25+N25+R25+V25+Z25+AD25+AH25+AL25+AP25+AT25 -> 0.052 | AY25: =C25+G25+K25+O25+S25+W25+AA25+AE25+AI25+AM25+AQ25+AU25 -> 0 | AZ25: =D25+H25+L25+P25+T25+X25+AB25+AF25+AJ25+AN25+AR25+AV25 -> 2.3715049 | BA25: =(AZ25+AY25)/AX25 -> 45.605863
A26: MIZORAM | B26: 0.036 | D26: 0.46344444 | F26: 0.025 | H26: 0.11 | N26: 0.023 | P26: 0.18514286 | AD26: 0.02 | AF26: 0.0060769231 | AH26: 0.02 | AJ26: 0.46230769 | AT26: =0.071+0.003 -> 0.074 | AU26: =0.1+171.47 -> 171.57 | AX26: =B26+F26+J26+N26+R26+V26+Z26+AD26+AH26+AL26+AP26+AT26 -> 0.198 | AY26: =C26+G26+K26+O26+S26+W26+AA26+AE26+AI26+AM26+AQ26+AU26 -> 171.57 | AZ26: =D26+H26+L26+P26+T26+X26+AB26+AF26+AJ26+AN26+AR26+AV26 -> 1.2269719 | BA26: =(AZ26+AY26)/AX26 -> 872.71198
A27: NAGALAND | B27: 0.00248 | D27: 0.013777778 | N27: 0.00098 | P27: 0.0504 | AD27: 0.00054 | AF27: 0.0099692308 | AH27: 0.00202 | AJ27: 0.15538462 | AT27: =0.00216+0.0015 -> 0.00366 | AV27: 0.13033333 | AX27: =B27+F27+J27+N27+R27+V27+Z27+AD27+AH27+AL27+AP27+AT27 -> 0.00968 | AY27: =C27+G27+K27+O27+S27+W27+AA27+AE27+AI27+AM27+AQ27+AU27 -> 0 | AZ27: =D27+H27+L27+P27+T27+X27+AB27+AF27+AJ27+AN27+AR27+AV27 -> 0.35986496 | BA27: =(AZ27+AY27)/AX27 -> 37.176132
A28: ODISHA | D28: 0 | R28: 2.37 | T28: 29.375 | Z28: 2.68 | AA28: 24.58 | AH28: 1.87 | AJ28: 27.538462 | AL28: 0.51 | AM28: 12.82 | AT28: 0.01 | AV28: 0.48611111 | AX28: =B28+F28+J28+N28+R28+V28+Z28+AD28+AH28+AL28+AP28+AT28 -> 7.44 | AY28: =C28+G28+K28+O28+S28+W28+AA28+AE28+AI28+AM28+AQ28+AU28 -> 37.4 | AZ28: =D28+H28+L28+P28+T28+X28+AB28+AF28+AJ28+AN28+AR28+AV28 -> 57.399573 | BA28: =(AZ28+AY28)/AX28 -> 12.741878
A29: PUDUCHERRY | V29: 0.03 | W29: 0.122 | Z29: 0.085 | AA29: 0.72 | AH29: 0.0005 | AI29: 0.266 | AL29: 0.006 | AM29: 0.004 | AT29: 0.019 | AU29: 0.085 | AX29: =B29+F29+J29+N29+R29+V29+Z29+AD29+AH29+AL29+AP29+AT29 -> 0.1405 | AY29: =C29+G29+K29+O29+S29+W29+AA29+AE29+AI29+AM29+AQ29+AU29 -> 1.197 | AZ29: =D29+H29+L29+P29+T29+X29+AB29+AF29+AJ29+AN29+AR29+AV29 -> 0 | BA29: =(AZ29+AY29)/AX29 -> 8.519573
A30: PUNJAB | AT30: 1.351 | AU30: 10.463 | AX30: =B30+F30+J30+N30+R30+V30+Z30+AD30+AH30+AL30+AP30+AT30 -> 1.351 | AY30: =C30+G30+K30+O30+S30+W30+AA30+AE30+AI30+AM30+AQ30+AU30 -> 10.463 | AZ30: =D30+H30+L30+P30+T30+X30+AB30+AF30+AJ30+AN30+AR30+AV30 -> 0 | BA30: =(AZ30+AY30)/AX30 -> 7.7446336
A31: RAJASTHAN | AT31: 2.53 | AU31: 2.73 | AX31: =B31+F31+J31+N31+R31+V31+Z31+AD31+AH31+AL31+AP31+AT31 -> 2.53 | AY31: =C31+G31+K31+O31+S31+W31+AA31+AE31+AI31+AM31+AQ31+AU31 -> 2.73 | AZ31: =D31+H31+L31+P31+T31+X31+AB31+AF31+AJ31+AN31+AR31+AV31 -> 0 | BA31: =(AZ31+AY31)/AX31 -> 1.0790514
A32: SIKKIM | B32: 0.01 | D32: 0.027222222 | F32: 0.008 | H32: 0.043809524 | N32: 0.032 | P32: 0.10571429 | R32: 0.032 | T32: 0.8375 | Z32: 0.015 | AA32: 16 | AD32: 0.037 | AF32: 0.24615385 | AH32: 0.025 | AJ32: 0.18461538 | AT32: =0.016+0.04+0.018+0.003 -> 0.077 | AV32: 0.435 | AX32: =B32+F32+J32+N32+R32+V32+Z32+AD32+AH32+AL32+AP32+AT32 -> 0.236 | AY32: =C32+G32+K32+O32+S32+W32+AA32+AE32+AI32+AM32+AQ32+AU32 -> 16 | AZ32: =D32+H32+L32+P32+T32+X32+AB32+AF32+AJ32+AN32+AR32+AV32 -> 1.8800153 | BA32: =(AZ32+AY32)/AX32 -> 75.762777
A33: TAMIL NADU | AT33: 55.03 | AU33: 343.65 | AV33: =2317.304/180 -> 12.873911 | AX33: =B33+F33+J33+N33+R33+V33+Z33+AD33+AH33+AL33+AP33+AT33 -> 55.03 | AY33: =C33+G33+K33+O33+S33+W33+AA33+AE33+AI33+AM33+AQ33+AU33 -> 343.65 | AZ33: =D33+H33+L33+P33+T33+X33+AB33+AF33+AJ33+AN33+AR33+AV33 -> 12.873911 | BA33: =(AZ33+AY33)/AX33 -> 6.4787191
A34: TELANGANA | J34: 1.235 | K34: 14.203 | N34: 0.057 | P34: 1.9428571 | V34: 0.843 | W34: 4.215 | Z34: 2.458 | AA34: 18.435 | AH34: 1.078 | AJ34: 33.169231 | AL34: 0.027 | AM34: 0.02 | AT34: 1.191 | AU34: 3.811 | AX34: =B34+F34+J34+N34+R34+V34+Z34+AD34+AH34+AL34+AP34+AT34 -> 6.889 | AY34: =C34+G34+K34+O34+S34+W34+AA34+AE34+AI34+AM34+AQ34+AU34 -> 40.684 | AZ34: =D34+H34+L34+P34+T34+X34+AB34+AF34+AJ34+AN34+AR34+AV34 -> 35.112088 | BA34: =(AZ34+AY34)/AX34 -> 11.00248
A35: TRIPURA | AX35: =B35+F35+J35+N35+R35+V35+Z35+AD35+AH35+AL35+AP35+AT35 -> 0 | AY35: =C35+G35+K35+O35+S35+W35+AA35+AE35+AI35+AM35+AQ35+AU35 -> 0 | AZ35: =D35+H35+L35+P35+T35+X35+AB35+AF35+AJ35+AN35+AR35+AV35 -> 0 | BA35: =(AZ35+AY35)/AX35 -> #DIV/0!
A36: UTTAR PRADESH | R36: 3.185 | T36: 39.8125 | Z36: 3.683 | AA36: 7.366 | AH36: 9.71 | AI36: 24.793 | AJ36: 14.246154 | AX36: =B36+F36+J36+N36+R36+V36+Z36+AD36+AH36+AL36+AP36+AT36 -> 16.578 | AY36: =C36+G36+K36+O36+S36+W36+AA36+AE36+AI36+AM36+AQ36+AU36 -> 32.159 | AZ36: =D36+H36+L36+P36+T36+X36+AB36+AF36+AJ36+AN36+AR36+AV36 -> 54.058654 | BA36: =(AZ36+AY36)/AX36 -> 5.2007271
A37: UTTARAKHAND | F37: 0.02338 | H37: =261.89/210 -> 1.2470952 | N37: 0.072 | P37: 7.2004 | R37: 0.434 | S37: 0.538 | Z37: 0.603 | AA37: 0.955 | AH37: 0.096 | AI37: 0.087 | AL37: 0.027 | AM37: 0.32 | AT37: =0.088+0.008 -> 0.096 | AU37: =0.112+0.012 -> 0.124 | AX37: =B37+F37+J37+N37+R37+V37+Z37+AD37+AH37+AL37+AP37+AT37 -> 1.35138 | AY37: =C37+G37+K37+O37+S37+W37+AA37+AE37+AI37+AM37+AQ37+AU37 -> 2.024 | AZ37: =D37+H37+L37+P37+T37+X37+AB37+AF37+AJ37+AN37+AR37+AV37 -> 8.4474952 | BA37: =(AZ37+AY37)/AX37 -> 7.7487422
A38: WEST BENGAL | AT38: 24.85 | AU38: 66.5 | AV38: 145.19444 | AX38: =B38+F38+J38+N38+R38+V38+Z38+AD38+AH38+AL38+AP38+AT38 -> 24.85 | AY38: =C38+G38+K38+O38+S38+W38+AA38+AE38+AI38+AM38+AQ38+AU38 -> 66.5 | AZ38: =D38+H38+L38+P38+T38+X38+AB38+AF38+AJ38+AN38+AR38+AV38 -> 145.19444 | BA38: =(AZ38+AY38)/AX38 -> 8.5188911
BA39: =(AZ39+AY39)/AX39 -> #DIV/0!
A40: TOTAL | B40: =SUM(B4:B39) -> 0.13428 | C40: =SUM(C4:C39) -> 0.396 | D40: =SUM(D4:D39) -> 2.5772222 | E40: =(D40+C40)/B40 -> 22.141959 | F40: =SUM(F4:F39) -> 0.21238 | G40: =SUM(G4:G39) -> 0.594 | H40: =SUM(H4:H39) -> 6.0025714 | I40: =(H40+G40)/F40 -> 31.060229 | J40: =SUM(J4:J39) -> 16.6292 | K40: =SUM(K4:K39) -> 179.37247 | L40: =SUM(L4:L39) -> 5.7176111 | M40: =(L40+K40)/J40 -> 11.130426 | N40: =SUM(N4:N39) -> 0.82147 | O40: =SUM(O4:O39) -> 3.96 | P40: =SUM(P4:P39) -> 17.843817 | R40: =SUM(R4:R39) -> 11.66865 | S40: =SUM(S4:S39) -> 50.698 | T40: =SUM(T4:T39) -> 92.889737 | V40: =SUM(V4:V39) -> 12.2511 | W40: =SUM(W4:W39) -> 65.23 | X40: =SUM(X4:X39) -> 1.7 | Z40: =SUM(Z4:Z39) -> 55.89078 | AA40: =SUM(AA4:AA39) -> 511.31138 | AB40: =SUM(AB4:AB39) -> 4.25 | AD40: =SUM(AD4:AD39) -> 0.42964 | AE40: =SUM(AE4:AE39) -> 2.476 | AF40: =SUM(AF4:AF39) -> 5.4818154 | AH40: =SUM(AH4:AH39) -> 30.87427 | AI40: =SUM(AI4:AI39) -> 96.0927 | AJ40: =SUM(AJ4:AJ39) -> 166.46715 | AL40: =SUM(AL4:AL39) -> 7.76745 | AM40: =SUM(AM4:AM39) -> 40.217 | AN40: =SUM(AN4:AN39) -> 13.901839 | AP40: =SUM(AP4:AP39) -> 0.018 | AQ40: =SUM(AQ4:AQ39) -> 0 | AR40: =SUM(AR4:AR39) -> 0.25055556 | AT40: =SUM(AT4:AT39) -> 118.32481 | AU40: =SUM(AU4:AU39) -> 804.14395 | AV40: =SUM(AV4:AV39) -> 225.45219 | AX40: =SUM(AX4:AX39) -> 255.02203 | AY40: =SUM(AY4:AY39) -> 1754.4915 | AZ40: =SUM(AZ4:AZ39) -> 542.53452 | BA40: =(AZ40+AY40)/AX40 -> 9.007167
...

Sheet 14-15
B1: Area | C1: Production | F1: Area | G1: Production | J1: Area | K1: Production | N1: Area | O1: Production | R1: Area | S1: Production | V1: Area | W1: Production | Z1: Area | AA1: Production | AD1: Area | AE1: Production | AH1: Area | AI1: Production | AL1: Area | AM1: Production | AP1: Area | AQ1: Production | AT1: Area | AU1: Production | AX1: Area | AY1: Production
C2: Loose | D2: Cut | G2: Loose | H2: Cut | K2: Loose | L2: Cut | O2: Loose | S2: Loose | T2: Cut | W2: Loose | X2: Cut | AA2: Loose | AB2: Cut | AE2: Loose | AF2: Cut | AI2: Loose | AJ2: Cut | AM2: Loose | AN2: Cut | AQ2: Loose | AR2: Cut | AU2: Loose | AV2: Cut | AY2: Loose | AZ2: Cut
A3: ANDAMAN NICOBAR | V3: 0.011 | W3: 0.014 | Z3: 0.036 | AA3: 0.053 | AH3: 0.012 | AI3: 0.01 | AT3: 0.125 | AU3: 0.112 | AX3: =B3+F3+J3+N3+R3+V3+Z3+AD3+AH3+AL3+AP3+AT3 -> 0.184 | AY3: =C3+G3+K3+O3+S3+W3+AA3+AE3+AI3+AM3+AQ3+AU3 -> 0.189 | AZ3: =D3+H3+L3+P3+T3+X3+AB3+AF3+AJ3+AN3+AR3+AV3 -> 0 | BA3: =(AZ3+AY3)/AX3 -> 1.0271739
A4: ANDHRA PRADESH | J4: 2.224 | K4: 20.263 | V4: 2.459 | W4: 13.219 | Z4: 5.05 | AA4: 39.474 | AH4: 0.516 | AJ4: =21.2076923076923/130 -> 0.16313609 | AL4: 1.034 | AM4: 11.18 | AT4: 3.104 | AU4: 19.183 | AX4: =B4+F4+J4+N4+R4+V4+Z4+AD4+AH4+AL4+AP4+AT4 -> 14.387 | AY4: =C4+G4+K4+O4+S4+W4+AA4+AE4+AI4+AM4+AQ4+AU4 -> 103.319 | AZ4: =D4+H4+L4+P4+T4+X4+AB4+AF4+AJ4+AN4+AR4+AV4 -> 0.16313609 | BA4: =(AZ4+AY4)/AX4 -> 7.1927529
A5: ARUNACHAL PRADESH | B5: 0.0046 | D5: =0.644444444444444/180 -> 0.0035802469 | N5: 0.004 | P5: =0.502857142857143/175 -> 0.0028734694 | Z5: 0.01 | AA5: 0.0098 | AH5: 0.0045 | AJ5: =0.715384615384615/130 -> 0.0055029586 | AX5: =B5+F5+J5+N5+R5+V5+Z5+AD5+AH5+AL5+AP5+AT5 -> 0.0231 | AY5: =C5+G5+K5+O5+S5+W5+AA5+AE5+AI5+AM5+AQ5+AU5 -> 0.0098 | AZ5: =D5+H5+L5+P5+T5+X5+AB5+AF5+AJ5+AN5+AR5+AV5 -> 0.011956675 | BA5: =(AZ5+AY5)/AX5 -> 0.9418474
A6: ASSAM | B6: 0.063 | C6: 0.416 | D6: =0.622222222222222/180 -> 0.0034567901 | F6: 0.093 | G6: 0.614 | H6: =0.728571428571429/210 -> 0.0034693878 | J6: 0.123 | K6: 0.812 | L6: =1.16111111111111/180 -> 0.0064506173 | N6: 0.606 | O6: 4 | P6: =5.85714285714286/175 -> 0.033469388 | R6: 0.21 | S6: 1.386 | T6: =4.525/80 -> 0.0565625 | V6: 0.183 | W6: 1.208 | X6: =1.72777777777778/180 -> 0.0095987654 | Z6: 0.453 | AA6: 2.99 | AB6: =4.27777777777778/180 -> 0.023765432 | AD6: 0.363 | AE6: 2.496 | AF6: =4.74615384615385/130 -> 0.036508876 | AH6: 0.306 | AI6: 2.02 | AJ6: =3.96153846153846/130 -> 0.030473373 | AL6: 0.5 | AM6: 2.6 | AN6: =0.0069/180 -> 3.8333333e-05 | AT6: 0.63 | AU6: 4.258 | AV6: =5.42222222222222/180 -> 0.030123457 | AX6: =B6+F6+J6+N6+R6+V6+Z6+AD6+AH6+AL6+AP6+AT6 -> 3.53 | AY6: =C6+G6+K6+O6+S6+W6+AA6+AE6+AI6+AM6+AQ6+AU6 -> 22.8 | AZ6: =D6+H6+L6+P6+T6+X6+AB6+AF6+AJ6+AN6+AR6+AV6 -> 0.23391692 | BA6: =(AZ6+AY6)/AX6 -> 6.5251889
A7: BIHAR | R7: 0.085 | T7: =2.0665/80 -> 0.02583125 | V7: 0.113 | W7: 0.317 | Z7: 0.865 | AA7: 11.576 | AH7: 0.1 | AI7: 0.112 | AJ7: =0.697038461538461/130 -> 0.0053618343 | AL7: 0.132 | AM7: 0.596 | AT7: 0.132 | AU7: 1.08 | AX7: =B7+F7+J7+N7+R7+V7+Z7+AD7+AH7+AL7+AP7+AT7 -> 1.427 | AY7: =C7+G7+K7+O7+S7+W7+AA7+AE7+AI7+AM7+AQ7+AU7 -> 13.681 | AZ7: =D7+H7+L7+P7+T7+X7+AB7+AF7+AJ7+AN7+AR7+AV7 -> 0.031193084 | BA7: =(AZ7+AY7)/AX7 -> 9.6091052
A8: CHHATTISGARH | J8: 0.284 | K8: 1.038 | R8: 1.791 | S8: 5.994 | V8: 0.044 | W8: 0.088 | Z8: 4.007 | AA8: 29.27 | AH8: 1.05 | AI8: 2.904 | AL8: 1.498 | AM8: 5.901 | AT8: 2.287 | AU8: 4.834 | AX8: =B8+F8+J8+N8+R8+V8+Z8+AD8+AH8+AL8+AP8+AT8 -> 10.961 | AY8: =C8+G8+K8+O8+S8+W8+AA8+AE8+AI8+AM8+AQ8+AU8 -> 50.029 | AZ8: =D8+H8+L8+P8+T8+X8+AB8+AF8+AJ8+AN8+AR8+AV8 -> 0 | BA8: =(AZ8+AY8)/AX8 -> 4.5642733
A9: D & N HAVELI | AX9: =B9+F9+J9+N9+R9+V9+Z9+AD9+AH9+AL9+AP9+AT9 -> 0 | AY9: =C9+G9+K9+O9+S9+W9+AA9+AE9+AI9+AM9+AQ9+AU9 -> 0 | AZ9: =D9+H9+L9+P9+T9+X9+AB9+AF9+AJ9+AN9+AR9+AV9 -> 0 | BA9: =(AZ9+AY9)/AX9 -> #DIV/0!
A10: DAMAN & DIU | Z10: 0.002 | AA10: 0.016 | AH10: 0.002 | AI10: 0.014 | AX10: =B10+F10+J10+N10+R10+V10+Z10+AD10+AH10+AL10+AP10+AT10 -> 0.004 | AY10: =C10+G10+K10+O10+S10+W10+AA10+AE10+AI10+AM10+AQ10+AU10 -> 0.03 | AZ10: =D10+H10+L10+P10+T10+X10+AB10+AF10+AJ10+AN10+AR10+AV10 -> 0 | BA10: =(AZ10+AY10)/AX10 -> 7.5
A11: DELHI | AX11: =B11+F11+J11+N11+R11+V11+Z11+AD11+AH11+AL11+AP11+AT11 -> 0 | AY11: =C11+G11+K11+O11+S11+W11+AA11+AE11+AI11+AM11+AQ11+AU11 -> 0 | AZ11: =D11+H11+L11+P11+T11+X11+AB11+AF11+AJ11+AN11+AR11+AV11 -> 0 | BA11: =(AZ11+AY11)/AX11 -> #DIV/0!
A12: GOA | B12: 0.003 | D12: =0.00555555555555556/180 -> 3.0864198e-05 | N12: 0.001 | P12: =0.114285714285714/175 -> 0.00065306122 | W12: 0.006 | Z12: 0.004 | AA12: 0.022 | AD12: 0.001 | AM12: 0.002 | AT12: 0.003 | AU12: 0.003 | AX12: =B12+F12+J12+N12+R12+V12+Z12+AD12+AH12+AL12+AP12+AT12 -> 0.012 | AY12: =C12+G12+K12+O12+S12+W12+AA12+AE12+AI12+AM12+AQ12+AU12 -> 0.033 | AZ12: =D12+H12+L12+P12+T12+X12+AB12+AF12+AJ12+AN12+AR12+AV12 -> 0.00068392542 | BA12: =(AZ12+AY12)/AX12 -> 2.8069938
A13: GUJARAT | Z13: 7.22 | AA13: 68.93 | AH13: 4.12 | AI13: 37.36 | AT13: 5.96 | AU13: 57.31 | AX13: =B13+F13+J13+N13+R13+V13+Z13+AD13+AH13+AL13+AP13+AT13 -> 17.3 | AY13: =C13+G13+K13+O13+S13+W13+AA13+AE13+AI13+AM13+AQ13+AU13 -> 163.6 | AZ13: =D13+H13+L13+P13+T13+X13+AB13+AF13+AJ13+AN13+AR13+AV13 -> 0 | BA13: =(AZ13+AY13)/AX13 -> 9.4566474
A14: HARYANA | J14: 0.03 | K14: 0.04 | L14: =0.133333333333333/180 -> 0.00074074074 | N14: 0.02 | P14: =0.137142857142857/175 -> 0.00078367347 | R14: 0.21 | T14: =2.4/80 -> 0.03 | Z14: 5.38 | AA14: 62.34 | AH14: 0.24 | AI14: 0.46 | AJ14: =1.67692307692308/130 -> 0.012899408 | AL14: 0.09 | AT14: 0.1 | AU14: 0.01 | AV14: =0.572222222222222/180 -> 0.0031790123 | AX14: =B14+F14+J14+N14+R14+V14+Z14+AD14+AH14+AL14+AP14+AT14 -> 6.07 | AY14: =C14+G14+K14+O14+S14+W14+AA14+AE14+AI14+AM14+AQ14+AU14 -> 62.85 | AZ14: =D14+H14+L14+P14+T14+X14+AB14+AF14+AJ14+AN14+AR14+AV14 -> 0.047602835 | BA14: =(AZ14+AY14)/AX14 -> 10.362043
A15: HIMACHAL PRADESH | F15: 0.052 | H15: =2.39047619047619/210 -> 0.01138322 | J15: 0.295 | K15: 7.6 | L15: =4.65/180 -> 0.025833333 | N15: 0.006 | P15: =0.434285714285714/175 -> 0.0024816327 | R15: 0.083 | T15: =1.9625/80 -> 0.02453125 | Z15: 0.223 | AA15: 19.605 | AH15: 0.036 | AT15: 0.107 | AV15: =2.11666666666667/180 -> 0.011759259 | AX15: =B15+F15+J15+N15+R15+V15+Z15+AD15+AH15+AL15+AP15+AT15 -> 0.802 | AY15: =C15+G15+K15+O15+S15+W15+AA15+AE15+AI15+AM15+AQ15+AU15 -> 27.205 | AZ15: =D15+H15+L15+P15+T15+X15+AB15+AF15+AJ15+AN15+AR15+AV15 -> 0.075988695 | BA15: =(AZ15+AY15)/AX15 -> 34.016195
A16: JAMMU & KASHMIR | F16: 0.004 | J16: 0.004 | K16: 0.001 | N16: 0.003 | R16: 0.034 | Z16: 0.331 | AA16: 0.263 | AH16: 0.019 | AI16: 0.015 | AL16: 0.001 | AP16: 0.018 | AT16: 0.045 | AU16: 0.067 | AX16: =B16+F16+J16+N16+R16+V16+Z16+AD16+AH16+AL16+AP16+AT16 -> 0.459 | AY16: =C16+G16+K16+O16+S16+W16+AA16+AE16+AI16+AM16+AQ16+AU16 -> 0.346 | AZ16: =D16+H16+L16+P16+T16+X16+AB16+AF16+AJ16+AN16+AR16+AV16 -> 0 | BA16: =(AZ16+AY16)/AX16 -> 0.75381264
A17: JHARKHAND | D17: 0 | P17: 0 | AT17: 1.6 | AU17: 22.026 | AV17: =52.8111111111111/180 -> 0.29339506 | AX17: =B17+F17+J17+N17+R17+V17+Z17+AD17+AH17+AL17+AP17+AT17 -> 1.6 | AY17: =C17+G17+K17+O17+S17+W17+AA17+AE17+AI17+AM17+AQ17+AU17 -> 22.026 | AZ17: =D17+H17+L17+P17+T17+X17+AB17+AF17+AJ17+AN17+AR17+AV17 -> 0.29339506 | BA17: =(AZ17+AY17)/AX17 -> 13.949622
A18: KARNATAKA | D18: =0.0555555555555556/180 -> 0.00030864198 | H18: =0.380952380952381/210 -> 0.001814059 | J18: 5.1 | K18: 61.2 | P18: =2.02285714285714/175 -> 0.011559184 | R18: 0.2 | T18: =5.3625/80 -> 0.06703125 | V18: 6.3 | W18: 38.6 | Z18: 9.4 | AA18: 77.2 | AH18: 3 | AJ18: =57.0230769230769/130 -> 0.43863905 | AL18: 2.1 | AM18: 14.7 | AN18: =5.92777777777778/180 -> 0.032932099 | AT18: 4.8 | AU18: 28.3 | AX18: =B18+F18+J18+N18+R18+V18+Z18+AD18+AH18+AL18+AP18+AT18 -> 30.9 | AY18: =C18+G18+K18+O18+S18+W18+AA18+AE18+AI18+AM18+AQ18+AU18 -> 220 | AZ18: =D18+H18+L18+P18+T18+X18+AB18+AF18+AJ18+AN18+AR18+AV18 -> 0.55228429 | BA18: =(AZ18+AY18)/AX18 -> 7.1376144
A19: KERALA | AT19: =0.1363+13.2385 -> 13.3748 | AU19: 0.05246 | AV19: =5915.51824/180 -> 32.86399 | AX19: =B19+F19+J19+N19+R19+V19+Z19+AD19+AH19+AL19+AP19+AT19 -> 13.3748 | AY19: =C19+G19+K19+O19+S19+W19+AA19+AE19+AI19+AM19+AQ19+AU19 -> 0.05246 | AZ19: =D19+H19+L19+P19+T19+X19+AB19+AF19+AJ19+AN19+AR19+AV19 -> 32.86399 | BA19: =(AZ19+AY19)/AX19 -> 2.4610798
A20: LAKSHADWEEP | AX20: =B20+F20+J20+N20+R20+V20+Z20+AD20+AH20+AL20+AP20+AT20 -> 0 | AY20: =C20+G20+K20+O20+S20+W20+AA20+AE20+AI20+AM20+AQ20+AU20 -> 0 | AZ20: =D20+H20+L20+P20+T20+X20+AB20+AF20+AJ20+AN20+AR20+AV20 -> 0 | BA20: =(AZ20+AY20)/AX20 -> #DIV/0!
A21: MADHYA PRADESH | J21: 0.84 | K21: 11 | R21: 1.999 | S21: 38 | Z21: 8.143 | AA21: 89 | AH21: 2.428 | AI21: 14 | AL21: 0.274 | AM21: 1 | AT21: 4.066 | AU21: 53 | AX21: =B21+F21+J21+N21+R21+V21+Z21+AD21+AH21+AL21+AP21+AT21 -> 17.75 | AY21: =C21+G21+K21+O21+S21+W21+AA21+AE21+AI21+AM21+AQ21+AU21 -> 206 | AZ21: =D21+H21+L21+P21+T21+X21+AB21+AF21+AJ21+AN21+AR21+AV21 -> 0 | BA21: =(AZ21+AY21)/AX21 -> 11.605634
A22: MAHARASHTRA | J22: 0.47 | K22: 1.54 | N22: 0.01 | R22: 0.43 | S22: 1.94 | V22: 0.12 | W22: 0.53 | Z22: 3.76 | AA22: 23.82 | AH22: 1.21 | AI22: 6.99 | AL22: 0.45 | AM22: 2.18 | AT22: 0.8 | AU22: 1.53 | AX22: =B22+F22+J22+N22+R22+V22+Z22+AD22+AH22+AL22+AP22+AT22 -> 7.25 | AY22: =C22+G22+K22+O22+S22+W22+AA22+AE22+AI22+AM22+AQ22+AU22 -> 38.53 | AZ22: =D22+H22+L22+P22+T22+X22+AB22+AF22+AJ22+AN22+AR22+AV22 -> 0 | BA22: =(AZ22+AY22)/AX22 -> 5.3144828
A23: MANIPUR | F23: 0.016 | N23: 0.03 | R23: 0.008 | Z23: 0.24 | AA23: 0.128 | AD23: 0.029 | AH23: 0.049 | AI23: 0.015 | AL23: 0.018 | AT23: 0.42 | AU23: 0.158 | AX23: =B23+F23+J23+N23+R23+V23+Z23+AD23+AH23+AL23+AP23+AT23 -> 0.81 | AY23: =C23+G23+K23+O23+S23+W23+AA23+AE23+AI23+AM23+AQ23+AU23 -> 0.301 | AZ23: =D23+H23+L23+P23+T23+X23+AB23+AF23+AJ23+AN23+AR23+AV23 -> 0 | BA23: =(AZ23+AY23)/AX23 -> 0.37160494
A24: MEGHALAYA | B24: 0.022 | D24: =0.722222222222222/180 -> 0.0040123457 | F24: 0.004 | H24: =0.380952380952381/210 -> 0.001814059 | J24: 0.004 | L24: =0.0888888888888889/180 -> 0.00049382716 | N24: 0.014 | P24: =0.914285714285714/175 -> 0.0052244898 | AD24: 0.013 | AF24: =0.5/130 -> 0.0038461538 | AX24: =B24+F24+J24+N24+R24+V24+Z24+AD24+AH24+AL24+AP24+AT24 -> 0.057 | AY24: =C24+G24+K24+O24+S24+W24+AA24+AE24+AI24+AM24+AQ24+AU24 -> 0 | AZ24: =D24+H24+L24+P24+T24+X24+AB24+AF24+AJ24+AN24+AR24+AV24 -> 0.015390875 | BA24: =(AZ24+AY24)/AX24 -> 0.27001536
A25: MIZORAM | B25: 0.01 | D25: =0.836111111111111/180 -> 0.0046450617 | F25: 0.025 | H25: =0.11/210 -> 0.00052380952 | N25: 0.027 | P25: =0.172571428571429/175 -> 0.00098612245 | R25: 0.013 | T25: =0.005625/80 -> 7.03125e-05 | AD25: 0.02 | AF25: =0.00807692307692308/130 -> 6.2130178e-05 | AH25: 0.024 | AJ25: =0.693307692307692/130 -> 0.0053331361 | AT25: 0.079 | AU25: 180 | AX25: =B25+F25+J25+N25+R25+V25+Z25+AD25+AH25+AL25+AP25+AT25 -> 0.198 | AY25: =D25+G25+K25+O25+T25+W25+AA25+AF25+AJ25+AM25+AQ25+AU25 -> 180.01011 | AZ25: =D25+H25+L25+P25+T25+X25+AB25+AF25+AJ25+AN25+AR25+AV25 -> 0.011620572 | BA25: =(AZ25+AY25)/AX25 -> 909.20066
A26: NAGALAND | B26: 0.003 | N26: 0.001 | AD26: 0.001 | AH26: 0.002 | AT26: 0.004 | AX26: =B26+F26+J26+N26+R26+V26+Z26+AD26+AH26+AL26+AP26+AT26 -> 0.011 | AY26: =C26+G26+K26+O26+S26+W26+AA26+AE26+AI26+AM26+AQ26+AU26 -> 0 | AZ26: =D26+H26+L26+P26+T26+X26+AB26+AF26+AJ26+AN26+AR26+AV26 -> 0 | BA26: =(AZ26+AY26)/AX26 -> 0
A27: ODISHA | N27: 0.008 | P27: =0.001/175 -> 5.7142857e-06 | R27: 2.37 | T27: =2358.78/80 -> 29.48475 | Z27: 2.74 | AA27: 24.58 | AH27: 1.87 | AJ27: =3597.64/130 -> 27.674154 | AL27: 0.51 | AM27: 1.28 | AX27: =B27+F27+J27+N27+R27+V27+Z27+AD27+AH27+AL27+AP27+AT27 -> 7.498 | AY27: =C27+G27+K27+O27+S27+W27+AA27+AE27+AI27+AM27+AQ27+AU27 -> 25.86 | AZ27: =D27+H27+L27+P27+T27+X27+AB27+AF27+AJ27+AN27+AR27+AV27 -> 57.15891 | BA27: =(AZ27+AY27)/AX27 -> 11.072141
A28: PUDUCHERRY | V28: 0.03 | W28: 0.305 | Z28: 0.118 | AA28: 1.062 | AH28: 0.006 | AI28: 0.003 | AL28: 0.004 | AM28: 0.024 | AT28: 0.017 | AU28: 0.094 | AX28: =B28+F28+J28+N28+R28+V28+Z28+AD28+AH28+AL28+AP28+AT28 -> 0.175 | AY28: =C28+G28+K28+O28+S28+W28+AA28+AE28+AI28+AM28+AQ28+AU28 -> 1.488 | AZ28: =D28+H28+L28+P28+T28+X28+AB28+AF28+AJ28+AN28+AR28+AV28 -> 0 | BA28: =(AZ28+AY28)/AX28 -> 8.5028571
A29: PUNJAB | AT29: 1.374 | AU29: 10.654 | AX29: =B29+F29+J29+N29+R29+V29+Z29+AD29+AH29+AL29+AP29+AT29 -> 1.374 | AY29: =C29+G29+K29+O29+S29+W29+AA29+AE29+AI29+AM29+AQ29+AU29 -> 10.654 | AZ29: =D29+H29+L29+P29+T29+X29+AB29+AF29+AJ29+AN29+AR29+AV29 -> 0 | BA29: =(AZ29+AY29)/AX29 -> 7.7540029
A30: RAJASTHAN | AT30: 2.71 | AU30: 2.91 | AX30: =B30+F30+J30+N30+R30+V30+Z30+AD30+AH30+AL30+AP30+AT30 -> 2.71 | AY30: =C30+G30+K30+O30+S30+W30+AA30+AE30+AI30+AM30+AQ30+AU30 -> 2.91 | AZ30: =D30+H30+L30+P30+T30+X30+AB30+AF30+AJ30+AN30+AR30+AV30 -> 0 | BA30: =(AZ30+AY30)/AX30 -> 1.0738007
A31: SIKKIM | B31: 0.011 | D31: =0.0277777777777778/180 -> 0.00015432099 | F31: 0.007 | H31: =0.0428571428571429/210 -> 0.00020408163 | N31: 0.031 | P31: =0.108571428571429/175 -> 0.00062040816 | R31: 0.034 | T31: =0.875/80 -> 0.0109375 | Z31: 0.017 | AA31: 16.5 | AD31: 0.038 | AF31: =0.246153846153846/130 -> 0.0018934911 | AH31: 0.025 | AJ31: =0.184615384615385/130 -> 0.0014201183 | AT31: 0.079 | AV31: =0.438888888888889/180 -> 0.0024382716 | AX31: =B31+F31+J31+N31+R31+V31+Z31+AD31+AH31+AL31+AP31+AT31 -> 0.242 | AY31: =C31+G31+K31+O31+S31+W31+AA31+AE31+AI31+AM31+AQ31+AU31 -> 16.5 | AZ31: =D31+H31+L31+P31+T31+X31+AB31+AF31+AJ31+AN31+AR31+AV31 -> 0.017668192 | BA31: =(AZ31+AY31)/AX31 -> 68.254827
A32: TAMIL NADU | AT32: 55.03 | AU32: 343.65 | AV32: =2317.304/180 -> 12.873911 | AX32: =B32+F32+J32+N32+R32+V32+Z32+AD32+AH32+AL32+AP32+AT32 -> 55.03 | AY32: =C32+G32+K32+O32+S32+W32+AA32+AE32+AI32+AM32+AQ32+AU32 -> 343.65 | AZ32: =D32+H32+L32+P32+T32+X32+AB32+AF32+AJ32+AN32+AR32+AV32 -> 12.873911 | BA32: =(AZ32+AY32)/AX32 -> 6.4787191
A33: TELANGANA | J33: 1.328 | K33: 2.718 | N33: 0.049 | P33: =6.00571428571429/175 -> 0.034318367 | V33: 0.646 | W33: 1.844 | Z33: 2.61 | AA33: 9.627 | AH33: 0.802 | AI33: 1.002 | AL33: 0.015 | AM33: 0.072 | AT33: 2.391 | AU33: 7.131 | AX33: =B33+F33+J33+N33+R33+V33+Z33+AD33+AH33+AL33+AP33+AT33 -> 7.841 | AY33: =C33+G33+K33+O33+S33+W33+AA33+AE33+AI33+AM33+AQ33+AU33 -> 22.394 | AZ33: =D33+H33+L33+P33+T33+X33+AB33+AF33+AJ33+AN33+AR33+AV33 -> 0.034318367 | BA33: =(AZ33+AY33)/AX33 -> 2.86039
