Workbook

Sheet spi11-12
A1: STATES/Uts | B1: Pepper | E1: Ginger | H1: Chillies | K1: Turmeric | N1: Garlic | Q1: Cardamom | T1: Coriander | W1: Cumin | Z1: Fennel | AC1: F. Greek | AF1: Ajwan | AI1: Dill / Poppy /Celery | AL1: Cinnamon /Tejpat | AO1: Nutmeg | AR1: Clove | AU1: Tamarind | AX1: Saffron / Vanilla | BA1: Total
B2: A | C2: P | D2: Prod. | E2: A | F2: P | G2: Prod. | H2: A | I2: P | J2: Prod. | K2: A | L2: P | M2: Prod. | N2: A | O2: P | P2: Prod. | Q2: A | R2: P | S2: Prod. | T2: A | U2: P | V2: Prod. | W2: A | X2: P | Y2: Prod. | Z2: A | AA2: P | AB2: Prod. | AC2: A | AD2: P | AE2: Prod. | AF2: A | AG2: P | AH2: Prod. | AI2: A | AJ2: P | AK2: Prod. | AL2: A | AM2: P | AN2: Prod. | AO2: A | AP2: P | AQ2: Prod. | AR2: A | AS2: P | AT2: Prod. | AU2: A | AV2: P | AW2: Prod. | AX2: A | AY2: P | AZ2: Prod. | BA2: A | BB2: P | BC2: Prod.
A3: ANDAMAN NICOBAR | B3: 0.6 | C3: 0.03171 | D3: =C3/B3 -> 0.05285 | E3: 0.21 | F3: 1.855 | G3: =F3/E3 -> 8.8333333 | H3: 0.385 | I3: 0.58 | J3: =I3/H3 -> 1.5064935 | K3: 0.08 | L3: 0.485 | M3: =L3/K3 -> 6.0625 | AL3: 0.15 | AM3: 0.028 | AN3: =AM3/AL3 -> 0.18666667 | AO3: 0.07 | AP3: 0.00351 | AR3: 0.156 | AS3: 0.0011 | BA3: =B3+E3+H3+K3+N3+Q3+T3+W3+Z3+AC3+AF3+AI3+AL3+AO3+AR3+AU3+AX3 -> 1.651 | BB3: =C3+F3+I3+L3+O3+R3+U3+X3+AA3+AD3+AG3+AJ3+AM3+AP3+AS3+AV3+AY3 -> 2.98432 | BC3: =BB3/BA3 -> 1.8075833
A4: ANDHRA PRADESH | B4: 0.01 | C4: 0.002 | D4: =C4/B4 -> 0.2 | E4: 2.32 | F4: 20 | G4: =F4/E4 -> 8.6206897 | H4: 183 | I4: 565 | J4: =I4/H4 -> 3.0874317 | K4: 75 | L4: 485 | M4: =L4/K4 -> 6.4666667 | N4: 0.4 | O4: 0 | P4: =O4/N4 -> 0 | T4: 20.8 | U4: 26 | V4: =U4/T4 -> 1.25 | AF4: 5.08 | AG4: 2.398 | AH4: =AG4/AF4 -> 0.47204724 | AU4: 6.2 | AV4: 30.9 | AW4: =AV4/AU4 -> 4.983871 | AX4: 0.009 | AY4: 0.014 | AZ4: =AY4/AX4 -> 1.5555556 | BA4: =B4+E4+H4+K4+N4+Q4+T4+W4+Z4+AC4+AF4+AI4+AL4+AO4+AR4+AU4+AX4 -> 292.819 | BB4: =C4+F4+I4+L4+O4+R4+U4+X4+AA4+AD4+AG4+AJ4+AM4+AP4+AS4+AV4+AY4 -> 1129.314 | BC4: =BB4/BA4 -> 3.8566965
A5: ARUNACHAL PRADESH | E5: 6.8 | F5: 53 | G5: =F5/E5 -> 7.7941176 | H5: 2.6 | I5: 5.5 | J5: =I5/H5 -> 2.1153846 | K5: 0.65 | L5: 3.1 | M5: =L5/K5 -> 4.7692308 | BA5: =B5+E5+H5+K5+N5+Q5+T5+W5+Z5+AC5+AF5+AI5+AL5+AO5+AR5+AU5+AX5 -> 10.05 | BB5: =C5+F5+I5+L5+O5+R5+U5+X5+AA5+AD5+AG5+AJ5+AM5+AP5+AS5+AV5+AY5 -> 61.6 | BC5: =BB5/BA5 -> 6.1293532
A6: ASSAM | B6: 3.442 | C6: 1.74537 | D6: =C6/B6 -> 0.50708019 | E6: 16.99 | F6: 125.421 | G6: =F6/E6 -> 7.3820483 | H6: 19.995 | I6: 13.356 | J6: =I6/H6 -> 0.66796699 | K6: 15.468 | L6: 13.302 | M6: =L6/K6 -> 0.85996897 | N6: 9.687 | O6: 62.529 | P6: =O6/N6 -> 6.4549396 | T6: 27.463 | U6: 45.204 | V6: =U6/T6 -> 1.6459964 | BA6: =B6+E6+H6+K6+N6+Q6+T6+W6+Z6+AC6+AF6+AI6+AL6+AO6+AR6+AU6+AX6 -> 93.045 | BB6: =C6+F6+I6+L6+O6+R6+U6+X6+AA6+AD6+AG6+AJ6+AM6+AP6+AS6+AV6+AY6 -> 261.55737 | BC6: =BB6/BA6 -> 2.8110846
A7: BIHAR | E7: 0.56 | F7: 0.84 | G7: =F7/E7 -> 1.5 | H7: 2.9 | I7: 3 | J7: =I7/H7 -> 1.0344828 | K7: 3 | L7: 3 | M7: =L7/K7 -> 1 | N7: 4.25 | O7: 4 | P7: =O7/N7 -> 0.94117647 | T7: 2.3 | U7: 1.7 | V7: =U7/T7 -> 0.73913043 | BA7: =B7+E7+H7+K7+N7+Q7+T7+W7+Z7+AC7+AF7+AI7+AL7+AO7+AR7+AU7+AX7 -> 13.01 | BB7: =C7+F7+I7+L7+O7+R7+U7+X7+AA7+AD7+AG7+AJ7+AM7+AP7+AS7+AV7+AY7 -> 12.54 | BC7: =BB7/BA7 -> 0.96387394
A8: CHHATISHGARH | E8: 1.07 | F8: 1.415 | G8: =F8/E8 -> 1.3224299 | H8: 5.555 | I8: 2.755 | J8: =I8/H8 -> 0.49594959 | K8: 0.91 | L8: 0.77 | M8: =L8/K8 -> 0.84615385 | N8: 0.99 | O8: 2.519 | P8: =O8/N8 -> 2.5444444 | T8: 3.146 | U8: 0.858 | V8: =U8/T8 -> 0.27272727 | BA8: =B8+E8+H8+K8+N8+Q8+T8+W8+Z8+AC8+AF8+AI8+AL8+AO8+AR8+AU8+AX8 -> 11.671 | BB8: =C8+F8+I8+L8+O8+R8+U8+X8+AA8+AD8+AG8+AJ8+AM8+AP8+AS8+AV8+AY8 -> 8.317 | BC8: =BB8/BA8 -> 0.71262103
A9: GOA | B9: 0.731 | C9: 0.234 | D9: =C9/B9 -> 0.32010944 | BA9: =B9+E9+H9+K9+N9+Q9+T9+W9+Z9+AC9+AF9+AI9+AL9+AO9+AR9+AU9+AX9 -> 0.731 | BB9: =C9+F9+I9+L9+O9+R9+U9+X9+AA9+AD9+AG9+AJ9+AM9+AP9+AS9+AV9+AY9 -> 0.234 | BC9: =BB9/BA9 -> 0.32010944
A10: GUJARAT | E10: 4.395 | F10: 70.646 | G10: =F10/E10 -> 16.074175 | H10: 43.395 | I10: 68.534 | J10: =I10/H10 -> 1.5793064 | K10: 2.975 | L10: 50.493 | M10: =L10/K10 -> 16.972437 | N10: 39.2 | O10: 277.455 | P10: =O10/N10 -> 7.0779337 | T10: 20.574 | U10: 32.31 | V10: =U10/T10 -> 1.5704287 | W10: 373.9 | X10: 283.302 | Y10: =X10/W10 -> 0.75769457 | Z10: 39.5 | AA10: 57.941 | AB10: =AA10/Z10 -> 1.4668608 | AC10: 5.26 | AD10: 13.959 | AE10: =AD10/AC10 -> 2.6538023 | AF10: 5.866 | AG10: 6.369 | AH10: =AG10/AF10 -> 1.0857484 | AI10: 16.6 | AJ10: 21.132 | AK10: =AJ10/AI10 -> 1.273012 | BA10: =B10+E10+H10+K10+N10+Q10+T10+W10+Z10+AC10+AF10+AI10+AL10+AO10+AR10+AU10+AX10 -> 551.665 | BB10: =C10+F10+I10+L10+O10+R10+U10+X10+AA10+AD10+AG10+AJ10+AM10+AP10+AS10+AV10+AY10 -> 882.141 | BC10: =BB10/BA10 -> 1.599052
A11: HARYANA | E11: 0.57 | F11: 7.785 | G11: =F11/E11 -> 13.657895 | H11: 1.045 | I11: 8.928 | J11: =I11/H11 -> 8.5435407 | K11: 1.996 | L11: 18.3 | M11: =L11/K11 -> 9.1683367 | N11: 1.364 | O11: 11.611 | P11: =O11/N11 -> 8.5124633 | T11: 2.433 | U11: 3.156 | V11: =U11/T11 -> 1.297164 | Z11: 0.1 | AA11: 0.119 | AB11: =AA11/Z11 -> 1.19 | AC11: 5.29 | AD11: 11.786 | AE11: =AD11/AC11 -> 2.2279773 | BA11: =B11+E11+H11+K11+N11+Q11+T11+W11+Z11+AC11+AF11+AI11+AL11+AO11+AR11+AU11+AX11 -> 12.798 | BB11: =C11+F11+I11+L11+O11+R11+U11+X11+AA11+AD11+AG11+AJ11+AM11+AP11+AS11+AV11+AY11 -> 61.685 | BC11: =BB11/BA11 -> 4.8198937
A12: HIMACHAL PRADESH | E12: 2.18 | F12: 16.76 | G12: =F12/E12 -> 7.6880734 | H12: 0.709 | I12: 0.277 | J12: =I12/H12 -> 0.39069111 | K12: 0.185 | L12: 0.102 | M12: =L12/K12 -> 0.55135135 | N12: 1.473 | O12: 2.051 | P12: =O12/N12 -> 1.3923965 | T12: 0.141 | U12: 0.048 | V12: =U12/T12 -> 0.34042553 | W12: 0.078 | X12: 0.021 | Y12: =X12/W12 -> 0.26923077 | BA12: =B12+E12+H12+K12+N12+Q12+T12+W12+Z12+AC12+AF12+AI12+AL12+AO12+AR12+AU12+AX12 -> 4.766 | BB12: =C12+F12+I12+L12+O12+R12+U12+X12+AA12+AD12+AG12+AJ12+AM12+AP12+AS12+AV12+AY12 -> 19.259 | BC12: =BB12/BA12 -> 4.0409148
A13: JAMMU & KASHMIR | E13: 0.034 | F13: 0.0448 | G13: =F13/E13 -> 1.3176471 | H13: 0.564 | I13: 0.5428 | J13: =I13/H13 -> 0.96241135 | K13: 0.017 | L13: 0.0172 | M13: =L13/K13 -> 1.0117647 | N13: 0.543 | O13: 0.4637 | P13: =O13/N13 -> 0.85395948 | AX13: 2.989 | AY13: 0.00885 | AZ13: =AY13/AX13 -> 0.0029608565 | BA13: =B13+E13+H13+K13+N13+Q13+T13+W13+Z13+AC13+AF13+AI13+AL13+AO13+AR13+AU13+AX13 -> 4.147 | BB13: =C13+F13+I13+L13+O13+R13+U13+X13+AA13+AD13+AG13+AJ13+AM13+AP13+AS13+AV13+AY13 -> 1.07735 | BC13: =BB13/BA13 -> 0.25979021
A14: JHARKHAND | BA14: =B14+E14+H14+K14+N14+Q14+T14+W14+Z14+AC14+AF14+AI14+AL14+AO14+AR14+AU14+AX14 -> 0 | BB14: =C14+F14+I14+L14+O14+R14+U14+X14+AA14+AD14+AG14+AJ14+AM14+AP14+AS14+AV14+AY14 -> 0
A15: KARNATAKA | B15: 20 | C15: 5.5 | D15: =C15/B15 -> 0.275 | E15: 40 | F15: 139.6 | G15: =F15/E15 -> 3.49 | H15: 133.4 | I15: 153.14 | J15: =I15/H15 -> 1.147976 | K15: 15.9 | L15: 100 | M15: =L15/K15 -> 6.2893082 | N15: 5.693 | O15: 6 | P15: =O15/N15 -> 1.0539259 | Q15: 21.9 | R15: 1.9 | S15: =R15/Q15 -> 0.086757991 | T15: 8.6 | U15: 8 | V15: =U15/T15 -> 0.93023256 | AL15: 0.037 | AM15: 0.007 | AN15: =AM15/AL15 -> 0.18918919 | AO15: 0.147 | AP15: 0.15 | AQ15: =AP15/AO15 -> 1.0204082 | AR15: 0.122 | AS15: 0.17 | AT15: =AS15/AR15 -> 1.3934426 | AU15: 16.8 | AV15: 87 | AW15: =AV15/AU15 -> 5.1785714 | AX15: 2.518 | AY15: 0.994 | AZ15: =AY15/AX15 -> 0.39475774 | BA15: =B15+E15+H15+K15+N15+Q15+T15+W15+Z15+AC15+AF15+AI15+AL15+AO15+AR15+AU15+AX15 -> 265.117 | BB15: =C15+F15+I15+L15+O15+R15+U15+X15+AA15+AD15+AG15+AJ15+AM15+AP15+AS15+AV15+AY15 -> 502.461 | BC15: =BB15/BA15 -> 1.8952425
A16: KERALA | B16: 170.25 | C16: 31.69 | D16: =C16/B16 -> 0.18613803 | E16: 5.828 | F16: 31.596 | G16: =F16/E16 -> 5.4214139 | H16: 1.913 | I16: 3.101 | J16: =I16/H16 -> 1.6210141 | K16: 2.404 | L16: 6.305 | M16: =L16/K16 -> 2.6227121 | N16: 0.075 | O16: 0.65 | P16: =O16/N16 -> 8.6666667 | Q16: 41.593 | R16: 7.8 | S16: =R16/Q16 -> 0.18753156 | AL16: 0.321 | AN16: =AM16/AL16 -> 0 | AO16: 17.22 | AP16: 12.42 | AQ16: =AP16/AO16 -> 0.72125436 | AR16: 1.226 | AS16: 0.1 | AT16: =AS16/AR16 -> 0.081566069 | AU16: 12.711 | AV16: 19.1 | AW16: =AV16/AU16 -> 1.5026355 | AX16: 1.009 | AY16: 0.04036 | AZ16: =AY16/AX16 -> 0.04 | BA16: =B16+E16+H16+K16+N16+Q16+T16+W16+Z16+AC16+AF16+AI16+AL16+AO16+AR16+AU16+AX16 -> 254.55 | BB16: =C16+F16+I16+L16+O16+R16+U16+X16+AA16+AD16+AG16+AJ16+AM16+AP16+AS16+AV16+AY16 -> 112.80236 | BC16: =BB16/BA16 -> 0.44314422
A17: MADHYA PRADESH | E17: 9 | F17: 15 | G17: =F17/E17 -> 1.6666667 | H17: 54.41 | I17: 93.57 | J17: =I17/H17 -> 1.7197206 | K17: 1.5 | L17: 0.6 | M17: =L17/K17 -> 0.4 | N17: 60 | O17: 270 | P17: =O17/N17 -> 4.5 | T17: 175 | U17: 82 | V17: =U17/T17 -> 0.46857143 | BA17: =B17+E17+H17+K17+N17+Q17+T17+W17+Z17+AC17+AF17+AI17+AL17+AO17+AR17+AU17+AX17 -> 299.91 | BB17: =C17+F17+I17+L17+O17+R17+U17+X17+AA17+AD17+AG17+AJ17+AM17+AP17+AS17+AV17+AY17 -> 461.17 | BC17: =BB17/BA17 -> 1.5376946
A18: MAHARASHTRA | E18: 1.06 | F18: 1.04 | G18: =F18/E18 -> 0.98113208 | H18: 99.5 | I18: 45.6 | J18: =I18/H18 -> 0.45829146 | K18: 6.76 | L18: 8.43 | M18: =L18/K18 -> 1.2470414 | N18: 3.5 | O18: 40 | P18: =O18/N18 -> 11.428571 | AU18: 5.7 | AV18: 11.4 | AW18: =AV18/AU18 -> 2 | BA18: =B18+E18+H18+K18+N18+Q18+T18+W18+Z18+AC18+AF18+AI18+AL18+AO18+AR18+AU18+AX18 -> 116.52 | BB18: =C18+F18+I18+L18+O18+R18+U18+X18+AA18+AD18+AG18+AJ18+AM18+AP18+AS18+AV18+AY18 -> 106.47 | BC18: =BB18/BA18 -> 0.91374871
A19: MANIPUR | E19: 2.4 | F19: 3.84 | G19: =F19/E19 -> 1.6 | H19: 6.5 | I19: 3.9 | J19: =I19/H19 -> 0.6 | K19: 1.4 | L19: 16.4 | M19: =L19/K19 -> 11.714286 | N19: 0.17 | O19: 0 | P19: =O19/N19 -> 0 | BA19: =B19+E19+H19+K19+N19+Q19+T19+W19+Z19+AC19+AF19+AI19+AL19+AO19+AR19+AU19+AX19 -> 10.47 | BB19: =C19+F19+I19+L19+O19+R19+U19+X19+AA19+AD19+AG19+AJ19+AM19+AP19+AS19+AV19+AY19 -> 24.14 | BC19: =BB19/BA19 -> 2.3056351
A20: MEGHALAYA | B20: 0.885 | C20: 0.464 | D20: =C20/B20 -> 0.52429379 | E20: 9.442 | F20: 56.801 | G20: =F20/E20 -> 6.0157806 | H20: 1.846 | I20: 1.41 | J20: =I20/H20 -> 0.76381365 | K20: 1.941 | L20: 9.976 | M20: =L20/K20 -> 5.1396188 | N20: 0.28 | O20: 1.114 | P20: =O20/N20 -> 3.9785714 | T20: 0.012 | U20: 0.051 | V20: =U20/T20 -> 4.25 | AL20: 2.436 | AM20: 5 | AN20: =AM20/AL20 -> 2.0525452 | BA20: =B20+E20+H20+K20+N20+Q20+T20+W20+Z20+AC20+AF20+AI20+AL20+AO20+AR20+AU20+AX20 -> 16.842 | BB20: =C20+F20+I20+L20+O20+R20+U20+X20+AA20+AD20+AG20+AJ20+AM20+AP20+AS20+AV20+AY20 -> 74.816 | BC20: =BB20/BA20 -> 4.4422278
A21: MIZORAM | B21: 0.05 | C21: 0.0086 | D21: =C21/B21 -> 0.172 | E21: 6.5 | F21: 37 | G21: =F21/E21 -> 5.6923077 | H21: 8.019 | I21: 48.473 | J21: =I21/H21 -> 6.0447687 | K21: 4.78 | L21: 23.9 | M21: =L21/K21 -> 5 | N21: 1.3 | O21: 5.6 | P21: =O21/N21 -> 4.3076923 | BA21: =B21+E21+H21+K21+N21+Q21+T21+W21+Z21+AC21+AF21+AI21+AL21+AO21+AR21+AU21+AX21 -> 20.649 | BB21: =C21+F21+I21+L21+O21+R21+U21+X21+AA21+AD21+AG21+AJ21+AM21+AP21+AS21+AV21+AY21 -> 114.9816 | BC21: =BB21/BA21 -> 5.5683859
A22: NAGALAND | B22: 0.225 | C22: 0.012 | D22: =C22/B22 -> 0.053333333 | E22: 5.32 | F22: 36 | G22: =F22/E22 -> 6.7669173 | H22: 0.8 | I22: 1 | J22: =I22/H22 -> 1.25 | K22: 0.12 | L22: 0.5 | M22: =L22/K22 -> 4.1666667 | N22: 0.1 | O22: 0.154 | P22: =O22/N22 -> 1.54 | Q22: 3.2 | R22: 1.5 | S22: =R22/Q22 -> 0.46875 | BA22: =B22+E22+H22+K22+N22+Q22+T22+W22+Z22+AC22+AF22+AI22+AL22+AO22+AR22+AU22+AX22 -> 9.765 | BB22: =C22+F22+I22+L22+O22+R22+U22+X22+AA22+AD22+AG22+AJ22+AM22+AP22+AS22+AV22+AY22 -> 39.166 | BC22: =BB22/BA22 -> 4.0108551
A23: ODISHA | E23: 15.844 | F23: 35 | G23: =F23/E23 -> 2.2090381 | H23: 75.6 | I23: 70 | J23: =I23/H23 -> 0.92592593 | K23: 2.48 | L23: 36 | M23: =L23/K23 -> 14.516129 | N23: 10.9 | O23: 35.5 | P23: =O23/N23 -> 3.2568807 | T23: 19.1 | U23: 11 | V23: =U23/T23 -> 0.57591623 | BA23: =B23+E23+H23+K23+N23+Q23+T23+W23+Z23+AC23+AF23+AI23+AL23+AO23+AR23+AU23+AX23 -> 123.924 | BB23: =C23+F23+I23+L23+O23+R23+U23+X23+AA23+AD23+AG23+AJ23+AM23+AP23+AS23+AV23+AY23 -> 187.5 | BC23: =BB23/BA23 -> 1.5130241
A24: PUDUCHERRY | B24: 0.011 | C24: 0.008 | D24: =C24/B24 -> 0.72727273 | H24: 0.005 | I24: 0.005 | J24: =I24/H24 -> 1 | K24: 0.006 | L24: 0.008 | M24: =L24/K24 -> 1.3333333 | AU24: 0.064 | AV24: 0.094 | AW24: =AV24/AU24 -> 1.46875 | BA24: =B24+E24+H24+K24+N24+Q24+T24+W24+Z24+AC24+AF24+AI24+AL24+AO24+AR24+AU24+AX24 -> 0.086 | BB24: =C24+F24+I24+L24+O24+R24+U24+X24+AA24+AD24+AG24+AJ24+AM24+AP24+AS24+AV24+AY24 -> 0.115 | BC24: =BB24/BA24 -> 1.3372093
A25: PUNJAB | H25: 10.6 | I25: 17.7 | J25: =I25/H25 -> 1.6698113 | N25: 3.7 | O25: 45 | P25: =O25/N25 -> 12.162162 | AI25: 4.07 | AJ25: 5.51 | AK25: =AJ25/AI25 -> 1.3538084 | BA25: =B25+E25+H25+K25+N25+Q25+T25+W25+Z25+AC25+AF25+AI25+AL25+AO25+AR25+AU25+AX25 -> 18.37 | BB25: =C25+F25+I25+L25+O25+R25+U25+X25+AA25+AD25+AG25+AJ25+AM25+AP25+AS25+AV25+AY25 -> 68.21 | BC25: =BB25/BA25 -> 3.7131192
A26: RAJASTHAN | E26: 0.021 | F26: 0.062 | G26: =F26/E26 -> 2.952381 | H26: 12.214 | I26: 17.705 | J26: =I26/H26 -> 1.4495661 | K26: 0.201 | L26: 0.43 | M26: =L26/K26 -> 2.1393035 | N26: 59.446 | O26: 235.979 | P26: =O26/N26 -> 3.9696363 | T26: 260 | U26: 311 | V26: =U26/T26 -> 1.1961538 | W26: 220 | X26: 111 | Y26: =X26/W26 -> 0.50454545 | Z26: 59.044 | AA26: 84.07 | AB26: =AA26/Z26 -> 1.4238534 | AC26: 82.35 | AD26: 87.382 | AE26: =AD26/AC26 -> 1.061105 | AF26: 24.43 | AG26: 18.011 | AH26: =AG26/AF26 -> 0.73724928 | AI26: 12.8 | AJ26: 6 | AK26: =AJ26/AI26 -> 0.46875 | BA26: =B26+E26+H26+K26+N26+Q26+T26+W26+Z26+AC26+AF26+AI26+AL26+AO26+AR26+AU26+AX26 -> 730.506 | BB26: =C26+F26+I26+L26+O26+R26+U26+X26+AA26+AD26+AG26+AJ26+AM26+AP26+AS26+AV26+AY26 -> 871.639 | BC26: =BB26/BA26 -> 1.193199
A27: SIKKIM | E27: 8.51 | F27: 48 | G27: =F27/E27 -> 5.640423 | K27: 0.85 | L27: 2.9 | M27: =L27/K27 -> 3.4117647 | Q27: 15.02 | R27: 3.51 | S27: =R27/Q27 -> 0.23368842 | BA27: =B27+E27+H27+K27+N27+Q27+T27+W27+Z27+AC27+AF27+AI27+AL27+AO27+AR27+AU27+AX27 -> 24.38 | BB27: =C27+F27+I27+L27+O27+R27+U27+X27+AA27+AD27+AG27+AJ27+AM27+AP27+AS27+AV27+AY27 -> 54.41 | BC27: =BB27/BA27 -> 2.2317473
A28: TAMIL NADU | B28: 3.836 | C28: 0.775 | D28: =C28/B28 -> 0.20203337 | E28: 0.462 | F28: 7.068 | G28: =F28/E28 -> 15.298701 | H28: 58.603 | I28: 30.298 | J28: =I28/H28 -> 0.51700425 | K28: 60.228 | L28: 326.135 | M28: =L28/K28 -> 5.4150063 | N28: 0.443 | O28: 2.559 | P28: =O28/N28 -> 5.7765237 | Q28: 4.419 | R28: 0.402 | S28: =R28/Q28 -> 0.090970808 | T28: 10.886 | U28: 4.213 | V28: =U28/T28 -> 0.38701084 | AO28: 0.048 | AQ28: =AP28/AO28 -> 0 | AR28: 0.883 | AS28: 0.834 | AT28: =AS28/AR28 -> 0.94450736 | AU28: 16.953 | AV28: 54.08 | AW28: =AV28/AU28 -> 3.1899959 | AX28: 0.57 | AY28: 0.017 | AZ28: =AY28/AX28 -> 0.029824561 | BA28: =B28+E28+H28+K28+N28+Q28+T28+W28+Z28+AC28+AF28+AI28+AL28+AO28+AR28+AU28+AX28 -> 157.331 | BB28: =C28+F28+I28+L28+O28+R28+U28+X28+AA28+AD28+AG28+AJ28+AM28+AP28+AS28+AV28+AY28 -> 426.381 | BC28: =BB28/BA28 -> 2.7100889
A29: TRIPURA | B29: 0.239 | C29: 0.151 | D29: =C29/B29 -> 0.63179916 | E29: 1.8 | F29: 7.599 | G29: =F29/E29 -> 4.2216667 | H29: 2.35 | I29: 3.7 | J29: =I29/H29 -> 1.5744681 | K29: 1.295 | L29: 6.59 | M29: =L29/K29 -> 5.0888031 | BA29: =B29+E29+H29+K29+N29+Q29+T29+W29+Z29+AC29+AF29+AI29+AL29+AO29+AR29+AU29+AX29 -> 5.684 | BB29: =C29+F29+I29+L29+O29+R29+U29+X29+AA29+AD29+AG29+AJ29+AM29+AP29+AS29+AV29+AY29 -> 18.04 | BC29: =BB29/BA29 -> 3.1738213
A30: UTTAR PRADESH | E30: 0.847 | F30: 2.405 | G30: =F30/E30 -> 2.8394333 | H30: 13.284 | I30: 11.026 | J30: =I30/H30 -> 0.83002108 | K30: 2 | L30: 6 | M30: =L30/K30 -> 3 | N30: 34.427 | O30: 177.919 | P30: =O30/N30 -> 5.1680077 | T30: 6.511 | U30: 3.607 | V30: =U30/T30 -> 0.55398556 | W30: 0.002 | X30: 0.005 | Y30: =X30/W30 -> 2.5 | Z30: 0.91 | AA30: 0.819 | AB30: =AA30/Z30 -> 0.9 | AC30: 0.305 | AD30: 0.192 | AE30: =AD30/AC30 -> 0.6295082 | BA30: =B30+E30+H30+K30+N30+Q30+T30+W30+Z30+AC30+AF30+AI30+AL30+AO30+AR30+AU30+AX30 -> 58.286 | BB30: =C30+F30+I30+L30+O30+R30+U30+X30+AA30+AD30+AG30+AJ30+AM30+AP30+AS30+AV30+AY30 -> 201.973 | BC30: =BB30/BA30 -> 3.4652061
A31: UTTARAKHAND | E31: 1.4 | F31: 11.84 | G31: =F31/E31 -> 8.4571429 | H31: 2 | I31: 7.2 | J31: =I31/H31 -> 3.6 | K31: 0.7 | L31: 6.1 | M31: =L31/K31 -> 8.7142857 | N31: 1.2 | O31: 7.22 | P31: =O31/N31 -> 6.0166667 | T31: 0.904 | U31: 3.8 | V31: =U31/T31 -> 4.2035398 | AC31: 0.4 | AD31: 2.61 | AE31: =AD31/AC31 -> 6.525 | BA31: =B31+E31+H31+K31+N31+Q31+T31+W31+Z31+AC31+AF31+AI31+AL31+AO31+AR31+AU31+AX31 -> 6.604 | BB31: =C31+F31+I31+L31+O31+R31+U31+X31+AA31+AD31+AG31+AJ31+AM31+AP31+AS31+AV31+AY31 -> 38.77 | BC31: =BB31/BA31 -> 5.8706844
A32: WEST BENGAL | E32: 11.5 | F32: 25 | G32: =F32/E32 -> 2.173913 | H32: 63.6 | I32: 100 | J32: =I32/H32 -> 1.572327 | K32: 15.8 | L32: 42 | M32: =L32/K32 -> 2.6582278 | N32: 3.35 | O32: 40 | P32: =O32/N32 -> 11.940299 | Q32: 2.874 | R32: 0.704 | S32: =R32/Q32 -> 0.24495477 | BA32: =B32+E32+H32+K32+N32+Q32+T32+W32+Z32+AC32+AF32+AI32+AL32+AO32+AR32+AU32+AX32 -> 97.124 | BB32: =C32+F32+I32+L32+O32+R32+U32+X32+AA32+AD32+AG32+AJ32+AM32+AP32+AS32+AV32+AY32 -> 207.704 | BC32: =BB32/BA32 -> 2.1385445
A34: TOTAL | B34: =SUM(B3:B33) -> 200.279 | C34: =SUM(C3:C33) -> 40.62168 | D34: =C34/B34 -> 0.20282546 | E34: =SUM(E3:E33) -> 155.063 | F34: =SUM(F3:F33) -> 755.6178 | G34: =F34/E34 -> 4.8729729 | H34: =SUM(H3:H33) -> 804.792 | I34: =SUM(I3:I33) -> 1276.3008 | J34: =I34/H34 -> 1.5858766 | K34: =SUM(K3:K33) -> 218.646 | L34: =SUM(L3:L33) -> 1166.8432 | M34: =L34/K34 -> 5.3366776 | N34: =SUM(N3:N33) -> 242.491 | O34: =SUM(O3:O33) -> 1228.3237 | P34: =O34/N34 -> 5.0654404 | Q34: =SUM(Q3:Q33) -> 89.006 | R34: =SUM(R3:R33) -> 15.816 | S34: =R34/Q34 -> 0.17769589 | T34: =SUM(T3:T33) -> 557.87 | U34: =SUM(U3:U33) -> 532.947 | V34: =U34/T34 -> 0.95532472 | W34: =SUM(W3:W33) -> 593.98 | X34: =SUM(X3:X33) -> 394.328 | Y34: =X34/W34 -> 0.6638742 | Z34: =SUM(Z3:Z33) -> 99.554 | AA34: =SUM(AA3:AA33) -> 142.949 | AB34: =AA34/Z34 -> 1.4358941 | AC34: =SUM(AC3:AC33) -> 93.605 | AD34: =SUM(AD3:AD33) -> 115.929 | AE34: =AD34/AC34 -> 1.2384915 | AF34: =SUM(AF3:AF33) -> 35.376 | AG34: =SUM(AG3:AG33) -> 26.778 | AH34: =AG34/AF34 -> 0.75695387 | AI34: =SUM(AI3:AI33) -> 33.47 | AJ34: =SUM(AJ3:AJ33) -> 32.642 | AK34: =AJ34/AI34 -> 0.97526143 | AL34: =SUM(AL3:AL33) -> 2.944 | AM34: =SUM(AM3:AM33) -> 5.035 | AN34: =AM34/AL34 -> 1.7102582 | AO34: =SUM(AO3:AO33) -> 17.485 | AP34: =SUM(AP3:AP33) -> 12.57351 | AQ34: =AP34/AO34 -> 0.71910266 | AR34: =SUM(AR3:AR33) -> 2.387 | AS34: =SUM(AS3:AS33) -> 1.1051 | AT34: =AS34/AR34 -> 0.46296607 | AU34: =SUM(AU3:AU33) -> 58.428 | AV34: =SUM(AV3:AV33) -> 202.574 | AW34: =AV34/AU34 -> 3.4670706 | AX34: =SUM(AX3:AX33) -> 7.095 | AY34: =SUM(AY3:AY33) -> 1.07421 | AZ34: =AY34/AX34 -> 0.15140381 | BA34: =SUM(BA3:BA33) -> 3212.471 | BB34: =SUM(BB3:BB33) -> 5951.458 | BC34: =BB34/BA34 -> 1.8526107

Sheet Sheet1
A1: Sl. No. | B1: STATES/UTs | C1: BLACK PEPPER | F1: GINGER | I1: RED CHILLIES | L1: TURMERIC | O1: GARLIC | R1: CARDAMOM | U1: CORIANDER | X1: CUMIN | AB1: FENNEL | AE1: FENUGREEK | AH1: AJWAN | AK1: DILL/POPPY/ CELERY | AN1: CINNAMON /TEJPATA | AQ1: NUTMEG | AT1: CLOVE | AW1: TAMARIND | AZ1: SAFFRON/ | BC1: VANILLA | BF1: MINT (MENTHA)* | BI1: TOTAL
C2: A | D2: P | E2: Prod. | F2: A | G2: P | H2: Prod. | I2: A | J2: P | K2: Prod. | L2: A | M2: P | N2: Prod. | O2: A | P2: P | Q2: Prod. | R2: A | S2: P | T2: Prod. | U2: A | V2: P | W2: Prod. | X2: A | Y2: Prod. | Z2: P | AA2: Prod. | AB2: A | AC2: P | AD2: Prod. | AE2: A | AF2: P | AG2: Prod. | AH2: A | AI2: P | AJ2: Prod. | AK2: A | AL2: P | AM2: Prod. | AN2: A | AO2: P | AP2: Prod. | AQ2: A | AR2: P | AS2: Prod. | AT2: A | AU2: P | AV2: Prod. | AW2: A | AX2: P | AY2: Prod. | AZ2: A | BA2: P | BB2: Prod. | BC2: A | BD2: P | BE2: Prod. | BF2: A | BG2: P | BH2: Prod. | BI2: A | BJ2: P | BK2: Prod.
A3: 1 | B3: ANDHRA PRADESH | C3: 0.89 | D3: 0.531 | E3: =D3/C3 -> 0.59662921 | F3: 0.459 | G3: 3.999 | H3: =G3/F3 -> 8.7124183 | I3: 177.456 | J3: 796.653 | K3: =J3/I3 -> 4.4892988 | L3: 30.518 | M3: 73.244 | N3: =M3/L3 -> 2.4000262 | S3: 0 | U3: 0.747 | V3: 0.707 | W3: =V3/U3 -> 0.94645248 | AH3: 3.356 | AI3: 0.917 | AJ3: =AI3/AH3 -> 0.27324195 | AW3: 3.635 | AX3: 9.628 | AY3: =AX3/AW3 -> 2.6486933 | BI3: 217.061 | BJ3: 885.679 | BK3: =BJ3/BI3 -> 4.080323
A4: 2 | B4: ARUNACHAL PRADESH | C4: 0.10211 | D4: 0.15149 | E4: =D4/C4 -> 1.4835961 | F4: 3.27788 | G4: 13.3839 | H4: =G4/F4 -> 4.0830964 | I4: 1.0623 | J4: 2.3772925 | K4: =J4/I4 -> 2.237873 | L4: 0.3529 | M4: 1.95235 | N4: =M4/L4 -> 5.5323038 | R4: 9.06668 | S4: 3.6225 | T4: =S4/R4 -> 0.39953985 | BI4: 13.86187 | BJ4: 21.487533 | BK4: =BJ4/BI4 -> 1.5501179
A5: 3 | B5: ASSAM | C5: 4.087 | D5: 3.05481 | E5: =D5/C5 -> 0.74744556 | F5: 19.451 | G5: 185.951 | H5: =G5/F5 -> 9.5599712 | I5: 20.459 | J5: 20.189 | K5: =J5/I5 -> 0.98680287 | L5: 17.757 | M5: 24.665 | N5: =M5/L5 -> 1.3890297 | O5: 10.765 | P5: 68.916 | Q5: =P5/O5 -> 6.4018579 | U5: 30.698 | V5: 35.763 | W5: =V5/U5 -> 1.1649945 | BI5: 103.217 | BJ5: 338.53881 | BK5: =BJ5/BI5 -> 3.2798745
A6: 4 | B6: BIHAR | F6: 0.34 | G6: 2.962 | H6: =G6/F6 -> 8.7117647 | I6: 1.622 | J6: 3.652 | K6: =J6/I6 -> 2.2515413 | L6: 2.788 | M6: 2.874 | N6: =M6/L6 -> 1.0308465 | O6: 1.579 | P6: 2.623 | Q6: =P6/O6 -> 1.661178 | U6: 2.269 | V6: 2.051 | W6: =V6/U6 -> 0.90392243 | BI6: 8.598 | BJ6: 14.162 | BK6: =BJ6/BI6 -> 1.6471272
A7: 5 | B7: CHHATTISGARH | F7: 2.064 | G7: 8.442 | H7: =G7/F7 -> 4.0901163 | I7: 5.415 | J7: 3.249 | K7: =J7/I7 -> 0.6 | L7: 1.443 | M7: 1.157 | N7: =M7/L7 -> 0.8018018 | O7: 1.573 | P7: 1.681 | Q7: =P7/O7 -> 1.0686586 | U7: 3.019 | V7: 0.905 | W7: =V7/U7 -> 0.29976814 | BI7: 13.514 | BJ7: 15.434 | BK7: =BJ7/BI7 -> 1.1420749
A8: 6 | B8: GUJARAT | F8: 5.069 | G8: 110.896 | H8: =G8/F8 -> 21.877293 | I8: 11.93 | J8: 23.345 | K8: =J8/I8 -> 1.9568315 | L8: 4.692 | M8: 18.191 | N8: =M8/L8 -> 3.8770247 | O8: 15.063 | P8: 118.218 | Q8: =P8/O8 -> 7.8482374 | U8: 141.221 | V8: 218.093 | W8: =V8/U8 -> 1.5443383 | X8: 475.198 | Y8: =X8/W8 -> 307.7033 | Z8: 474.523 | AA8: =Z8/Y8 -> 1.5421446 | AB8: 48.44 | AC8: 98.578 | AD8: =AC8/AB8 -> 2.0350537 | AE8: 7.577 | AF8: 14.189 | AG8: =AF8/AE8 -> 1.8726409 | AH8: 18.109 | AI8: 18.772 | AJ8: =AI8/AH8 -> 1.0366116 | AK8: 14.865 | AL8: 19.038 | AM8: =AL8/AK8 -> 1.2807265 | BI8: 742.164 | BJ8: 1113.843 | BK8: =BJ8/BI8 -> 1.5008044
A9: 7 | B9: HARYANA | F9: 0.082 | G9: 0.75 | H9: =G9/F9 -> 9.1463415 | L9: 1.331 | M9: 3.009 | N9: =M9/L9 -> 2.2607062 | O9: 3.204 | P9: 31.698 | Q9: =P9/O9 -> 9.8932584 | U9: 1.052 | V9: 1.566 | W9: =V9/U9 -> 1.4885932 | Y9: =X9/W9 -> 0 | AB9: 0.051 | AC9: 0.089 | AD9: =AC9/AB9 -> 1.745098 | AE9: 0.905 | AF9: 3.775 | AG9: =AF9/AE9 -> 4.1712707 | BI9: 6.625 | BJ9: 40.887 | BK9: =BJ9/BI9 -> 6.1716226
A10: 8 | B10: HIMACHAL PRADESH | F10: 2.571 | G10: 15.291 | H10: =G10/F10 -> 5.9474912 | I10: 0.643 | J10: 0.397 | K10: =J10/I10 -> 0.61741835 | L10: 0.498 | M10: 0.81 | N10: =M10/L10 -> 1.626506 | O10: 6.506 | P10: 12.7 | Q10: =P10/O10 -> 1.9520443 | U10: 0.159 | V10: 0.189 | W10: =V10/U10 -> 1.1886792 | X10: 0.103 | Y10: =X10/W10 -> 0.086650794 | Z10: 0.055 | AA10: =Z10/Y10 -> 0.63473164 | BI10: 10.48 | BJ10: 29.442 | BK10: =BJ10/BI10 -> 2.8093511
A11: 9 | B11: JAMMU & KASHMIR | F11: 0.028 | G11: 0.0527 | H11: =G11/F11 -> 1.8821429 | I11: 0.664 | J11: 0.5509 | K11: =J11/I11 -> 0.82966867 | L11: 0.012 | M11: 0.0114 | N11: =M11/L11 -> 0.95 | O11: 0.708 | P11: 0.5719 | Q11: =P11/O11 -> 0.80776836 | AZ11: 3.657 | BA11: 0.0036 | BB11: =BA11/AZ11 -> 0.00098441345 | BI11: 5.069 | BJ11: 1.1905 | BK11: =BJ11/BI11 -> 0.23485895
A12: 10 | B12: JHARKHAND | BI12: 0 | BJ12: 0 | BK12: =BJ12/BI12 -> #DIV/0!
A13: 11 | B13: KARNATAKA | C13: 211.497 | D13: 99.6224 | E13: =D13/C13 -> 0.47103458 | F13: 45.504 | G13: 532.073 | H13: =G13/F13 -> 11.692884 | I13: 85.598 | J13: 147.049 | K13: =J13/I13 -> 1.7179023 | L13: 20.555 | M13: 131.138 | N13: =M13/L13 -> 6.3798589 | O13: 4.013 | P13: 21.221 | Q13: =P13/O13 -> 5.2880638 | R13: 3.396 | S13: 0.59 | T13: =S13/R13 -> 0.1737338 | U13: 0.908 | V13: 0.487 | W13: =V13/U13 -> 0.53634361 | X13: 0.097 | Y13: =X13/W13 -> 0.18085421 | Z13: 0.101 | AA13: =Z13/Y13 -> 0.55846087 | AB13: 0.111 | AC13: 0.452 | AD13: =AC13/AB13 -> 4.0720721 | AE13: 0.369 | AF13: 1.081 | AG13: =AF13/AE13 -> 2.9295393 | AN13: 0.03 | AO13: 0.003 | AP13: =AO13/AN13 -> 0.1 | AQ13: 0.42 | AR13: 0.541 | AS13: =AR13/AQ13 -> 1.2880952 | AT13: 0.097 | AU13: 0.092 | AV13: =AU13/AT13 -> 0.94845361 | AW13: 11.042 | AX13: 40.026 | AY13: =AX13/AW13 -> 3.6248868 | BC13: 0.075 | BD13: 0.027 | BE13: =BD13/BC13 -> 0.36 | BI13: 383.712 | BJ13: 974.5034 | BK13: =BJ13/BI13 -> 2.539674
A14: 12 | B14: KERALA | C14: 82.124 | D14: 33.591 | E14: =D14/C14 -> 0.40902781 | F14: 2.7 | G14: 56.242 | H14: =G14/F14 -> 20.83037 | I14: 0 | J14: 0 | L14: 2.217 | M14: 7.42 | N14: =M14/L14 -> 3.3468651 | O14: 0.203 | P14: 1.068 | Q14: =P14/O14 -> 5.2610837 | R14: 39.143 | S14: 20.57 | T14: =S14/R14 -> 0.52550903 | U14: 0 | V14: 0 | AN14: 0.084 | AO14: 0.011 | AP14: =AO14/AN14 -> 0.13095238 | AQ14: 23.51 | AR14: 14.911 | AS14: =AR14/AQ14 -> 0.63424075 | AT14: 0.787 | AU14: 0.058 | AV14: =AU14/AT14 -> 0.073697586 | AW14: 8.388 | AX14: 29.129 | AY14: =AX14/AW14 -> 3.4726991 | BC14: 0.03527 | BD14: 0.017 | BE14: =BD14/BC14 -> 0.48199603 | BI14: 159.19127 | BJ14: 163.017 | BK14: =BJ14/BI14 -> 1.0240323
A15: 13 | B15: MADHYA PRADESH | C15: 0 | D15: 0 | F15: 29.762 | G15: 477.563 | H15: =G15/F15 -> 16.046065 | I15: 122.198 | J15: 315.598 | K15: =J15/I15 -> 2.5826773 | L15: 17.764 | M15: 62.995 | N15: =M15/L15 -> 3.5462171 | O15: 193.066 | P15: 1982.604 | Q15: =P15/O15 -> 10.269048 | U15: 298.95 | V15: 401.34 | W15: =V15/U15 -> 1.3424987 | X15: 0.3 | Y15: =X15/W15 -> 0.2234639 | Z15: 0.339 | AA15: =Z15/Y15 -> 1.5170236 | AB15: 1.58 | AC15: 2.848 | AD15: =AC15/AB15 -> 1.8025316 | AE15: 52.202 | AF15: 100.212 | AG15: =AF15/AE15 -> 1.9196966 | AH15: 7.227 | AI15: 7.757 | AJ15: =AI15/AH15 -> 1.0733361 | AK15: 0.026 | AL15: 0.026 | AM15: =AL15/AK15 -> 1 | AW15: 0.938 | AX15: 9.847 | AY15: =AX15/AW15 -> 10.497868 | BF15: 0.764 | BG15: 11.087 | BH15: =BG15/BF15 -> 14.51178 | BI15: 724.777 | BJ15: 3372.216 | BK15: =BJ15/BI15 -> 4.6527635
A16: 14 | B16: MAHARASHTRA | C16: 1.237 | D16: 0.593 | E16: =D16/C16 -> 0.47938561 | F16: 9.644 | G16: 133.886 | H16: =G16/F16 -> 13.882829 | I16: 5.605 | J16: 24.484 | K16: =J16/I16 -> 4.3682426 | L16: 59.576 | M16: 230.7406 | N16: =M16/L16 -> 3.8730462 | O16: 3.779 | P16: 22.442 | Q16: =P16/O16 -> 5.9386081 | U16: 1.78 | V16: 5.503 | W16: =V16/U16 -> 3.091573 | Y16: =X16/W16 -> 0 | AE16: 0.835 | AF16: 5.338 | AG16: =AF16/AE16 -> 6.3928144 | AH16: 0 | AI16: 0 | AQ16: 0.086 | AR16: 0.103 | AS16: =AR16/AQ16 -> 1.1976744 | AW16: 1.039 | AX16: 9.968 | AY16: =AX16/AW16 -> 9.5938402 | BI16: 83.581 | BJ16: 433.0576 | BK16: =BJ16/BI16 -> 5.1812924
A17: 15 | B17: MANIPUR | F17: 4.801 | G17: 66.939 | H17: =G17/F17 -> 13.94272 | L17: 2.346 | M17: 5.684 | N17: =M17/L17 -> 2.4228474 | P17: 0 | R17: 0.182 | S17: 0.004 | T17: =S17/R17 -> 0.021978022 | U17: 0.051 | V17: 0.0745 | W17: =V17/U17 -> 1.4607843 | Y17: =X17/W17 -> 0 | BI17: 7.38 | BJ17: 72.7015 | BK17: =BJ17/BI17 -> 9.8511518
A18: 16 | B18: MEGHALAYA | C18: 1.056 | D18: 0.801 | E18: =D18/C18 -> 0.75852273 | F18: 9.972 | G18: 66.449 | H18: =G18/F18 -> 6.663558 | L18: 3.006 | M18: 3.3752 | N18: =M18/L18 -> 1.122821 | O18: 0.115 | P18: 0.196 | Q18: =P18/O18 -> 1.7043478 | AN18: 0.469 | AO18: 1.149 | AP18: =AO18/AN18 -> 2.4498934 | BI18: 14.618 | BJ18: 71.9702 | BK18: =BJ18/BI18 -> 4.9233958
A19: 17 | B19: MIZORAM | C19: 0.07 | D19: 0.0025 | E19: =D19/C19 -> 0.035714286 | F19: 8.553 | G19: 60.1305 | H19: =G19/F19 -> 7.0303402 | I19: 11.19575 | J19: 10.9181 | K19: =J19/I19 -> 0.97520041 | L19: 7.7384 | M19: 29.82 | N19: =M19/L19 -> 3.8535098 | O19: 0.0228 | P19: 0.012 | Q19: =P19/O19 -> 0.52631579 | U19: 0.2304775 | V19: 0.02108 | W19: =V19/U19 -> 0.09146229 | Y19: =X19/W19 -> 0 | AK19: 0.0005 | AL19: 0.0015 | AM19: =AL19/AK19 -> 3 | AN19: 0.001 | AO19: 0.00025 | AP19: =AO19/AN19 -> 0.25 | AW19: 0.01 | AX19: 0.026 | AY19: =AX19/AW19 -> 2.6 | BI19: 27.821928 | BJ19: 100.93193 | BK19: =BJ19/BI19 -> 3.6277835
A20: 18 | B20: NAGALAND | C20: 0.101 | D20: 0.024 | E20: =D20/C20 -> 0.23762376 | F20: 4.717 | G20: 35.28 | H20: =G20/F20 -> 7.4793301 | I20: 1.98 | J20: 4.328 | K20: =J20/I20 -> 2.1858586 | L20: 0.649 | M20: 1.838 | N20: =M20/L20 -> 2.8320493 | O20: 0.29 | P20: 2.382 | Q20: =P20/O20 -> 8.2137931 | R20: 3.988 | S20: 2.263 | T20: =S20/R20 -> 0.56745236 | U20: 0.047 | V20: 0.075 | W20: =V20/U20 -> 1.5957447 | Y20: =X20/W20 -> 0 | AN20: 0.006 | AO20: 0.002 | AP20: =AO20/AN20 -> 0.33333333 | AW20: 0.01 | AX20: 0.147 | AY20: =AX20/AW20 -> 14.7 | BI20: 11.788 | BJ20: 46.339 | BK20: =BJ20/BI20 -> 3.9310316
A21: 19 | B21: ODISHA | F21: 16.575 | G21: 128.02 | H21: =G21/F21 -> 7.7236802 | I21: 71.7 | J21: 69.28 | K21: =J21/I21 -> 0.96624826 | L21: 27.87 | M21: 43.615 | N21: =M21/L21 -> 1.5649444 | O21: 12.441 | P21: 45.482 | Q21: =P21/O21 -> 3.6558154 | U21: 19.6095 | V21: 10.863 | W21: =V21/U21 -> 0.55396619 | Y21: =X21/W21 -> 0 | BI21: 148.1955 | BJ21: 297.26 | BK21: =BJ21/BI21 -> 2.0058639
A22: 20 | B22: PUNJAB | I22: 8.777 | J22: 17.63 | K22: =J22/I22 -> 2.008659 | L22: 0.907 | M22: 3.3 | N22: =M22/L22 -> 3.6383682 | O22: 8.869 | P22: 96.767 | Q22: =P22/O22 -> 10.9107 | AK22: 4.566 | AL22: 6.511 | AM22: =AL22/AK22 -> 1.4259746 | BI22: 23.119 | BJ22: 124.208 | BK22: =BJ22/BI22 -> 5.3725507
A23: 21 | B23: RAJASTHAN | F23: 0.094 | G23: 0.319 | H23: =G23/F23 -> 3.393617 | I23: 6.603 | J23: 10.925 | K23: =J23/I23 -> 1.654551 | L23: 0.243 | M23: 0.431 | N23: =M23/L23 -> 1.7736626 | O23: 87.663 | P23: 517.088 | Q23: =P23/O23 -> 5.8985889 | U23: 124.286 | V23: 182.705 | W23: =V23/U23 -> 1.4700369 | X23: 609.719 | Y23: =X23/W23 -> 414.76443 | Z23: 318.688 | AA23: =Z23/Y23 -> 0.76835904 | AB23: 30.814 | AC23: 33.563 | AD23: =AC23/AB23 -> 1.0892127 | AE23: 90.469 | AF23: 109.28 | AG23: =AF23/AE23 -> 1.2079276 | AH23: 12.475 | AI23: 7.479 | AJ23: =AI23/AH23 -> 0.59951904 | AK23: 4.522 | AL23: 3.236 | AM23: =AL23/AK23 -> 0.71561256 | BI23: 966.888 | BJ23: 1183.714 | BK23: =BJ23/BI23 -> 1.2242514
A24: 22 | B24: SIKKIM | F24: 15.222 | G24: 81.5 | H24: =G24/F24 -> 5.3540928 | L24: 4.995 | M24: 15.464 | N24: =M24/L24 -> 3.0958959 | O24: 0 | P24: 0 | R24: 22.132 | S24: 5.614 | T24: =S24/R24 -> 0.25365986 | BI24: 42.349 | BJ24: 102.578 | BK24: =BJ24/BI24 -> 2.422206
A25: 23 | B25: TAMIL NADU | C25: 6.576 | D25: 1.44 | E25: =D25/C25 -> 0.2189781 | F25: 0.645 | G25: 11.015 | H25: =G25/F25 -> 17.077519 | I25: 55.716 | J25: 25.648 | K25: =J25/I25 -> 0.46033455 | L25: 20.894 | M25: 86.513 | N25: =M25/L25 -> 4.1405667 | O25: 1.272 | P25: 7.364 | Q25: =P25/O25 -> 5.7893082 | R25: 4.031 | S25: 0.366 | T25: =S25/R25 -> 0.090796328 | U25: 9.717 | V25: 4.184 | W25: =V25/U25 -> 0.43058557 | Y25: =X25/W25 -> 0 | AB25: 0.00575 | AC25: 0 | AD25: =AC25/AB25 -> 0 | AE25: 3.75e-05 | AF25: 0 | AG25: =AF25/AE25 -> 0 | AQ25: 0.174 | AR25: 0.02 | AS25: =AR25/AQ25 -> 0.11494253 | AT25: 1.039 | AU25: 1.008 | AV25: =AU25/AT25 -> 0.97016362 | AW25: 14.501 | AX25: 44.659 | AY25: =AX25/AW25 -> 3.0797186 | BF25: 0.511 | BG25: 0 | BH25: =BG25/BF25 -> 0 | BI25: 115.08179 | BJ25: 182.217 | BK25: =BJ25/BI25 -> 1.5833696
A26: 24 | B26: TELANGANA | F26: 2.594 | G26: 23.1 | H26: =G26/F26 -> 8.9051658 | I26: 89.156 | J26: 536.541 | K26: =J26/I26 -> 6.0180022 | L26: 41.014 | M26: 319.76 | N26: =M26/L26 -> 7.7963622 | O26: 0.023 | P26: 0.108 | Q26: =P26/O26 -> 4.6956522 | U26: 0.812 | V26: 0.861 | W26: =V26/U26 -> 1.0603448 | Y26: =X26/W26 -> 0 | AH26: 0.841 | AI26: 0.644 | AJ26: =AI26/AH26 -> 0.76575505 | AW26: 2.01325 | AX26: 12.66075 | AY26: =AX26/AW26 -> 6.2887123 | BI26: 136.45325 | BJ26: 893.67475 | BK26: =BJ26/BI26 -> 6.5493108
A27: 25 | B27: TRIPURA | C27: 0.33 | D27: 0.342342 | E27: =D27/C27 -> 1.0374 | F27: 1.897 | G27: 16.126 | H27: =G27/F27 -> 8.5007907 | I27: 2.825 | J27: 6.698 | K27: =J27/I27 -> 2.3709735 | L27: 1.682 | M27: 2.049 | N27: =M27/L27 -> 1.2181926 | BI27: 6.734 | BJ27: 25.215342 | BK27: =BJ27/BI27 -> 3.744482
A28: 26 | B28: UTTAR PRADESH | F28: 0.911 | G28: 4.295 | H28: =G28/F28 -> 4.7145993 | I28: 13.6 | J28: 12.065 | K28: =J28/I28 -> 0.88713235 | L28: 1.683 | M28: 2.361 | N28: =M28/L28 -> 1.402852 | O28: 34.895 | P28: 207.144 | Q28: =P28/O28 -> 5.9362086 | U28: 6.762 | V28: 5.307 | W28: =V28/U28 -> 0.78482697 | X28: 0.002 | Y28: =X28/W28 -> 0.0025483324 | Z28: 0.00675 | AA28: =Z28/Y28 -> 2.648791 | AB28: 0.72 | AC28: 0.784 | AD28: =AC28/AB28 -> 1.0888889 | AE28: 0.341 | AF28: 0.293 | AG28: =AF28/AE28 -> 0.85923754 | BF28: 346.003 | BG28: 34.712 | BH28: =BG28/BF28 -> 0.10032283 | BI28: 404.917 | BJ28: 266.96775 | BK28: =BJ28/BI28 -> 0.65931475
A29: 27 | B29: UTTARAKHAND | F29: 5.09358 | G29: 50.6829 | H29: =G29/F29 -> 9.9503493 | I29: 2.86943 | J29: 9.68543 | K29: =J29/I29 -> 3.3753847 | L29: 1.786 | M29: 2.9623 | N29: =M29/L29 -> 1.6586226 | O29: 2.11844 | P29: 11.51587 | Q29: =P29/O29 -> 5.4360142 | R29: 0.06854 | S29: 0.07848 | T29: =S29/R29 -> 1.1450248 | U29: 1.46997 | V29: 4.17942 | W29: =V29/U29 -> 2.8432009 | Y29: =X29/W29 -> 0 | AE29: 0.70326 | AF29: 3.89834 | AG29: =AF29/AE29 -> 5.5432415 | AN29: 0.4885 | AO29: 1.11595 | AP29: =AO29/AN29 -> 2.2844422 | BI29: 14.59772 | BJ29: 84.11869 | BK29: =BJ29/BI29 -> 5.762454
A30: 28 | B30: WEST BENGAL | C30: 0.338 | D30: 0.091 | E30: =D30/C30 -> 0.26923077 | F30: 12.7 | G30: 138.998 | H30: =G30/F30 -> 10.944724 | I30: 4.93 | J30: 7.821 | K30: =J30/I30 -> 1.5864097 | L30: 18.482 | M30: 48.183 | N30: =M30/L30 -> 2.607023 | O30: 3.981 | P30: 37.975 | Q30: =P30/O30 -> 9.5390605 | R30: 3.003 | S30: 0.847 | T30: =S30/R30 -> 0.28205128 | U30: 12.67 | V30: 16.443 | W30: =V30/U30 -> 1.2977901 | X30: 1.591 | Y30: =X30/W30 -> 1.2259302 | Z30: 1.597 | AA30: =Z30/Y30 -> 1.3026843 | AB30: 1.045 | AC30: 1.074 | AD30: =AC30/AB30 -> 1.0277512 | AE30: 2.755 | AF30: 3.117 | AG30: =AF30/AE30 -> 1.1313975 | AK30: 1.299 | AL30: 1.697 | AM30: =AL30/AK30 -> 1.3063895 | AN30: 0.846 | AO30: 2.57 | AP30: =AO30/AN30 -> 3.0378251 | BI30: 63.64 | BJ30: 260.413 | BK30: =BJ30/BI30 -> 4.0919705
A31: 29 | B31: OTHERS | C31: 0.927 | D31: 0.391 | E31: =D31/C31 -> 0.42179072 | F31: 0.113 | G31: 0.491 | H31: =G31/F31 -> 4.3451327 | I31: 0.043 | J31: 0.129 | K31: =J31/I31 -> 3 | L31: 0.077 | M31: 0.294 | N31: =M31/L31 -> 3.8181818 | O31: 0 | P31: 0 | R31: 0 | S31: 0 | U31: 0 | V31: 0 | X31: 0 | Z31: 0 | AB31: 0 | AC31: 0 | AE31: 0 | AF31: 0 | AH31: 0 | AI31: 0 | AK31: 0 | AL31: 0 | AN31: 0.03124 | AO31: 0.02842 | AP31: =AO31/AN31 -> 0.90973111 | AQ31: 0.24054 | AR31: 0.01971 | AS31: =AR31/AQ31 -> 0.081940634 | AT31: 0.01422 | AU31: 0.02136 | AV31: =AU31/AT31 -> 1.5021097 | AW31: 0.055 | AX31: 0.198 | AY31: =AX31/AW31 -> 3.6 | AZ31: 0 | BA31: 0 | BC31: 0 | BD31: 0 | BF31: 0 | BG31: 0 | BI31: 1.501 | BJ31: 1.57249 | BK31: =BJ31/BI31 -> 1.0476282
B32: TOTAL | C32: 309.33511 | D32: 140.63554 | E32: =D32/C32 -> 0.45463815 | F32: 204.83946 | G32: 2224.837 | H32: =G32/F32 -> 10.861369 | I32: 702.04748 | J32: 2049.2127 | K32: =J32/I32 -> 2.918909 | L32: 292.8763 | M32: 1123.8569 | N32: =M32/L32 -> 3.837309 | O32: 392.14924 | P32: 3189.7768 | Q32: =P32/O32 -> 8.1340889 | R32: 85.01022 | S32: 33.95498 | T32: =S32/R32 -> 0.39942233 | U32: 656.45795 | V32: 891.317 | W32: =V32/U32 -> 1.3577671 | X32: 1087.01 | Y32: =X32/W32 -> 800.5865 | Z32: 795.30975 | AA32: =Z32/Y32 -> 0.9934089 | AB32: 82.76675 | AC32: 137.388 | AD32: =AC32/AB32 -> 1.6599419 | AE32: 156.1563 | AF32: 241.18334 | AG32: =AF32/AE32 -> 1.5444996 | AH32: 42.008 | AI32: 35.569 | AJ32: =AI32/AH32 -> 0.84671967 | AK32: 25.2785 | AL32: 30.5095 | AM32: =AL32/AK32 -> 1.2069347 | AN32: 1.95574 | AO32: 4.87962 | AP32: =AO32/AN32 -> 2.4950249 | AQ32: 24.43054 | AR32: 15.59471 | AS32: =AR32/AQ32 -> 0.6383285 | AT32: 1.93722 | AU32: 1.17936 | AV32: =AU32/AT32 -> 0.60878992 | AW32: 41.63125 | AX32: 156.28875 | AY32: =AX32/AW32 -> 3.754121 | AZ32: 3.657 | BA32: 0.0036 | BB32: =BA32/AZ32 -> 0.00098441345 | BC32: 0.11027 | BD32: 0.044 | BE32: =BD32/BC32 -> 0.39902059 | BF32: 347.278 | BG32: 45.799 | BH32: =BG32/BF32 -> 0.13187993 | BI32: 4456.9353 | BJ32: 11117.339 | BK32: =BJ32/BI32 -> 2.494391
BA34: =BC32+AZ32 -> 3.76727

Sheet spi12-13
A1: STATES/Uts | B1: Pepper | E1: Ginger | H1: Chillies | K1: Turmeric | N1: Garlic | Q1: Cardamom | T1: Coriander | W1: Cumin | Z1: Fennel | AC1: F. Greek | AF1: Ajwan | AI1: Dill / Poppy /Celery | AL1: Cinnamon /Tejpat | AO1: Nutmeg | AR1: Clove | AU1: Tamarind | AX1: Saffron / Vanilla | BA1: Total
B2: A | C2: P | D2: Prod. | E2: A | F2: P | G2: Prod. | H2: A | I2: P | J2: Prod. | K2: A | L2: P | M2: Prod. | N2: A | O2: P | P2: Prod. | Q2: A | R2: P | S2: Prod. | T2: A | U2: P | V2: Prod. | W2: A | X2: P | Y2: Prod. | Z2: A | AA2: P | AB2: Prod. | AC2: A | AD2: P | AE2: Prod. | AF2: A | AG2: P | AH2: Prod. | AI2: A | AJ2: P | AK2: Prod. | AL2: A | AM2: P | AN2: Prod. | AO2: A | AP2: P | AQ2: Prod. | AR2: A | AS2: P | AT2: Prod. | AU2: A | AV2: P | AW2: Prod. | AX2: A | AY2: P | AZ2: Prod. | BA2: A | BB2: P | BC2: Prod.
A3: ANDAMAN NICOBAR | B3: 0.6 | C3: 0.13 | D3: =C3/B3 -> 0.21666667 | E3: 0.215 | F3: 1.91 | G3: =F3/E3 -> 8.8837209 | H3: 0.4 | I3: 0.61 | J3: =I3/H3 -> 1.525 | K3: 0.08 | L3: 0.47 | M3: =L3/K3 -> 5.875 | AL3: 0.15 | AM3: 0.04 | AN3: =AM3/AL3 -> 0.26666667 | AO3: 0.07 | AP3: 0.05 | AQ3: =AP3/AO3 -> 0.71428571 | AR3: 0.16 | AS3: 0.01 | AT3: =AS3/AR3 -> 0.0625 | AU3: 0.06 | AV3: 0.35 | AW3: =AV3/AU3 -> 5.8333333 | BA3: =B3+E3+H3+K3+N3+Q3+T3+W3+Z3+AC3+AF3+AI3+AL3+AO3+AR3+AU3+AX3 -> 1.735 | BB3: =C3+F3+I3+L3+O3+R3+U3+X3+AA3+AD3+AG3+AJ3+AM3+AP3+AS3+AV3+AY3 -> 3.57 | BC3: =BB3/BA3 -> 2.0576369
A4: ANDHRA PRADESH | B4: 0.01 | C4: 0.0001 | D4: =C4/B4 -> 0.01 | E4: 2.32 | F4: 20 | G4: =F4/E4 -> 8.6206897 | H4: 210.02 | I4: 685.15 | J4: =I4/H4 -> 3.2623084 | K4: 67.78 | L4: 423.22 | M4: =L4/K4 -> 6.2440248 | N4: 0.4 | O4: 0.001 | P4: =O4/N4 -> 0.0025 | T4: 20.8 | U4: 26 | V4: =U4/T4 -> 1.25 | AF4: 5.08 | AG4: 2.4 | AH4: =AG4/AF4 -> 0.47244094 | AU4: 6.2 | AV4: 30.9 | AW4: =AV4/AU4 -> 4.983871 | AX4: 0.01 | AY4: 0.01 | AZ4: =AY4/AX4 -> 1 | BA4: =B4+E4+H4+K4+N4+Q4+T4+W4+Z4+AC4+AF4+AI4+AL4+AO4+AR4+AU4+AX4 -> 312.62 | BB4: =C4+F4+I4+L4+O4+R4+U4+X4+AA4+AD4+AG4+AJ4+AM4+AP4+AS4+AV4+AY4 -> 1187.6811 | BC4: =BB4/BA4 -> 3.7991207
A5: ARUNACHAL PRADESH | E5: 7 | F5: 57 | G5: =F5/E5 -> 8.1428571 | H5: 2.5 | I5: 4.4 | J5: =I5/H5 -> 1.76 | K5: 0.64 | L5: 2.86 | M5: =L5/K5 -> 4.46875 | N5: 0.03 | O5: 0.01 | P5: =O5/N5 -> 0.33333333 | BA5: =B5+E5+H5+K5+N5+Q5+T5+W5+Z5+AC5+AF5+AI5+AL5+AO5+AR5+AU5+AX5 -> 10.17 | BB5: =C5+F5+I5+L5+O5+R5+U5+X5+AA5+AD5+AG5+AJ5+AM5+AP5+AS5+AV5+AY5 -> 64.27 | BC5: =BB5/BA5 -> 6.3195674
A6: ASSAM | B6: 3.72 | C6: 1.99 | D6: =C6/B6 -> 0.53494624 | E6: 17.839 | F6: 136.83 | G6: =F6/E6 -> 7.670273 | H6: 20.59 | I6: 15.96 | J6: =I6/H6 -> 0.77513356 | K6: 16.24 | L6: 15.43 | M6: =L6/K6 -> 0.95012315 | N6: 9.98 | O6: 67.79 | P6: =O6/N6 -> 6.7925852 | T6: 28.29 | U6: 49.5 | V6: =U6/T6 -> 1.7497349 | BA6: =B6+E6+H6+K6+N6+Q6+T6+W6+Z6+AC6+AF6+AI6+AL6+AO6+AR6+AU6+AX6 -> 96.659 | BB6: =C6+F6+I6+L6+O6+R6+U6+X6+AA6+AD6+AG6+AJ6+AM6+AP6+AS6+AV6+AY6 -> 287.5 | BC6: =BB6/BA6 -> 2.9743738
A7: BIHAR | E7: 0.56 | F7: 0.84 | G7: =F7/E7 -> 1.5 | H7: 2.9 | I7: 3 | J7: =I7/H7 -> 1.0344828 | K7: 3 | L7: 3 | M7: =L7/K7 -> 1 | N7: 4.25 | O7: 4 | P7: =O7/N7 -> 0.94117647 | T7: 2.3 | U7: 1.7 | V7: =U7/T7 -> 0.73913043 | BA7: =B7+E7+H7+K7+N7+Q7+T7+W7+Z7+AC7+AF7+AI7+AL7+AO7+AR7+AU7+AX7 -> 13.01 | BB7: =C7+F7+I7+L7+O7+R7+U7+X7+AA7+AD7+AG7+AJ7+AM7+AP7+AS7+AV7+AY7 -> 12.54 | BC7: =BB7/BA7 -> 0.96387394
A8: CHHATTISGARH | E8: 1.907 | F8: 2.32 | G8: =F8/E8 -> 1.2165705 | H8: 5.46 | I8: 8.3 | J8: =I8/H8 -> 1.5201465 | K8: 0.93 | L8: 0.82 | M8: =L8/K8 -> 0.88172043 | N8: 1.15 | O8: 3.09 | P8: =O8/N8 -> 2.6869565 | T8: 2.86 | U8: 0.84 | V8: =U8/T8 -> 0.29370629 | BA8: =B8+E8+H8+K8+N8+Q8+T8+W8+Z8+AC8+AF8+AI8+AL8+AO8+AR8+AU8+AX8 -> 12.307 | BB8: =C8+F8+I8+L8+O8+R8+U8+X8+AA8+AD8+AG8+AJ8+AM8+AP8+AS8+AV8+AY8 -> 15.37 | BC8: =BB8/BA8 -> 1.2488827
A9: GOA | B9: 0.73 | C9: 0.23 | D9: =C9/B9 -> 0.31506849 | BA9: =B9+E9+H9+K9+N9+Q9+T9+W9+Z9+AC9+AF9+AI9+AL9+AO9+AR9+AU9+AX9 -> 0.73 | BB9: =C9+F9+I9+L9+O9+R9+U9+X9+AA9+AD9+AG9+AJ9+AM9+AP9+AS9+AV9+AY9 -> 0.23 | BC9: =BB9/BA9 -> 0.31506849
A10: GUJARAT | E10: 4.395 | F10: 70.65 | G10: =F10/E10 -> 16.075085 | H10: 43.4 | I10: 68.53 | J10: =I10/H10 -> 1.5790323 | K10: 2.98 | L10: 50.49 | M10: =L10/K10 -> 16.942953 | N10: 39.2 | O10: 277.46 | P10: =O10/N10 -> 7.0780612 | T10: 20.57 | U10: 32.31 | V10: =U10/T10 -> 1.5707341 | W10: 373.9 | X10: 283.3 | Y10: =X10/W10 -> 0.75768922 | Z10: 39.5 | AA10: 57.94 | AB10: =AA10/Z10 -> 1.4668354 | AC10: 5.26 | AD10: 13.96 | AE10: =AD10/AC10 -> 2.6539924 | AF10: 5.87 | AG10: 6.37 | AH10: =AG10/AF10 -> 1.0851789 | AI10: 16.6 | AJ10: 21.13 | AK10: =AJ10/AI10 -> 1.2728916 | BA10: =B10+E10+H10+K10+N10+Q10+T10+W10+Z10+AC10+AF10+AI10+AL10+AO10+AR10+AU10+AX10 -> 551.675 | BB10: =C10+F10+I10+L10+O10+R10+U10+X10+AA10+AD10+AG10+AJ10+AM10+AP10+AS10+AV10+AY10 -> 882.14 | BC10: =BB10/BA10 -> 1.5990212
A11: HARYANA | E11: 0.445 | F11: 5.65 | G11: =F11/E11 -> 12.696629 | H11: 2.43 | I11: 4.22 | J11: =I11/H11 -> 1.7366255 | K11: 1.33 | L11: 23.84 | M11: =L11/K11 -> 17.924812 | N11: 4.44 | O11: 35.83 | P11: =O11/N11 -> 8.0698198 | T11: 2.43 | U11: 4.41 | V11: =U11/T11 -> 1.8148148 | Z11: 0.27 | AA11: 0.17 | AB11: =AA11/Z11 -> 0.62962963 | AC11: 4.78 | AD11: 8.7 | AE11: =AD11/AC11 -> 1.8200837 | BA11: =B11+E11+H11+K11+N11+Q11+T11+W11+Z11+AC11+AF11+AI11+AL11+AO11+AR11+AU11+AX11 -> 16.125 | BB11: =C11+F11+I11+L11+O11+R11+U11+X11+AA11+AD11+AG11+AJ11+AM11+AP11+AS11+AV11+AY11 -> 82.82 | BC11: =BB11/BA11 -> 5.136124
A12: HIMACHAL PRADESH | E12: 2.098 | F12: 3.74 | G12: =F12/E12 -> 1.7826501 | H12: 0.63 | I12: 0.2 | J12: =I12/H12 -> 0.31746032 | K12: 0.2 | L12: 0.11 | M12: =L12/K12 -> 0.55 | N12: 4.15 | O12: 6.14 | P12: =O12/N12 -> 1.4795181 | T12: 0.14 | U12: 0.05 | V12: =U12/T12 -> 0.35714286 | W12: 0.08 | X12: 0.02 | Y12: =X12/W12 -> 0.25 | BA12: =B12+E12+H12+K12+N12+Q12+T12+W12+Z12+AC12+AF12+AI12+AL12+AO12+AR12+AU12+AX12 -> 7.298 | BB12: =C12+F12+I12+L12+O12+R12+U12+X12+AA12+AD12+AG12+AJ12+AM12+AP12+AS12+AV12+AY12 -> 10.26 | BC12: =BB12/BA12 -> 1.4058646
A13: JAMMU & KASHMIR | E13: 0.034 | F13: 0.04 | G13: =F13/E13 -> 1.1764706 | H13: 0.56 | I13: 0.54 | J13: =I13/H13 -> 0.96428571 | K13: 0.02 | L13: 0.02 | M13: =L13/K13 -> 1 | N13: 0.54 | O13: 0.46 | P13: =O13/N13 -> 0.85185185 | AX13: 2.99 | AY13: 0.01 | AZ13: =AY13/AX13 -> 0.0033444816 | BA13: =B13+E13+H13+K13+N13+Q13+T13+W13+Z13+AC13+AF13+AI13+AL13+AO13+AR13+AU13+AX13 -> 4.144 | BB13: =C13+F13+I13+L13+O13+R13+U13+X13+AA13+AD13+AG13+AJ13+AM13+AP13+AS13+AV13+AY13 -> 1.07 | BC13: =BB13/BA13 -> 0.25820463
A14: JHARKHAND | BA14: =B14+E14+H14+K14+N14+Q14+T14+W14+Z14+AC14+AF14+AI14+AL14+AO14+AR14+AU14+AX14 -> 0 | BB14: =C14+F14+I14+L14+O14+R14+U14+X14+AA14+AD14+AG14+AJ14+AM14+AP14+AS14+AV14+AY14 -> 0
A15: KARNATAKA | B15: 27.01 | C15: 6.15 | D15: =C15/B15 -> 0.22769345 | E15: 16.514 | F15: 57.8 | G15: =F15/E15 -> 3.5000606 | H15: 100.73 | I15: 107 | J15: =I15/H15 -> 1.0622456 | K15: 16.1 | L15: 100 | M15: =L15/K15 -> 6.2111801 | N15: 4.22 | O15: 4.5 | P15: =O15/N15 -> 1.0663507 | Q15: 25.05 | R15: 1.58 | S15: =R15/Q15 -> 0.063073852 | T15: 4.5 | U15: 4.5 | V15: =U15/T15 -> 1 | AL15: 0.04 | AM15: 0.01 | AN15: =AM15/AL15 -> 0.25 | AO15: 0.15 | AP15: 0.15 | AQ15: =AP15/AO15 -> 1 | AR15: 0.12 | AS15: 0.17 | AT15: =AS15/AR15 -> 1.4166667 | AU15: 16.8 | AV15: 87 | AW15: =AV15/AU15 -> 5.1785714 | AX15: 2.52 | AY15: 0.99 | AZ15: =AY15/AX15 -> 0.39285714 | BA15: =B15+E15+H15+K15+N15+Q15+T15+W15+Z15+AC15+AF15+AI15+AL15+AO15+AR15+AU15+AX15 -> 213.754 | BB15: =C15+F15+I15+L15+O15+R15+U15+X15+AA15+AD15+AG15+AJ15+AM15+AP15+AS15+AV15+AY15 -> 369.85 | BC15: =BB15/BA15 -> 1.73026
A16: KERALA | B16: 86.79 | C16: 42.49 | D16: =C16/B16 -> 0.48957253 | E16: 6.358 | F16: 33.75 | G16: =F16/E16 -> 5.308273 | H16: 1.91 | I16: 3.1 | J16: =I16/H16 -> 1.6230366 | K16: 2.73 | L16: 7.06 | M16: =L16/K16 -> 2.5860806 | N16: 0.07 | O16: 0.72 | P16: =O16/N16 -> 10.285714 | Q16: 39.66 | R16: 10.08 | S16: =R16/Q16 -> 0.25416036 | AL16: 0.32 | AM16: 0.001 | AN16: =AM16/AL16 -> 0.003125 | AO16: 17.22 | AP16: 12.42 | AQ16: =AP16/AO16 -> 0.72125436 | AR16: 1.23 | AS16: 0.1 | AT16: =AS16/AR16 -> 0.081300813 | AU16: 12.71 | AV16: 19.1 | AW16: =AV16/AU16 -> 1.5027537 | AX16: 1.01 | AY16: 0.04 | AZ16: =AY16/AX16 -> 0.03960396 | BA16: =B16+E16+H16+K16+N16+Q16+T16+W16+Z16+AC16+AF16+AI16+AL16+AO16+AR16+AU16+AX16 -> 170.008 | BB16: =C16+F16+I16+L16+O16+R16+U16+X16+AA16+AD16+AG16+AJ16+AM16+AP16+AS16+AV16+AY16 -> 128.861 | BC16: =BB16/BA16 -> 0.75797021
A17: MADHYA PRADESH | E17: 9 | F17: 15 | G17: =F17/E17 -> 1.6666667 | H17: 54.41 | I17: 93.57 | J17: =I17/H17 -> 1.7197206 | K17: 1.5 | L17: 0.6 | M17: =L17/K17 -> 0.4 | N17: 60 | O17: 270 | P17: =O17/N17 -> 4.5 | T17: 175 | U17: 82 | V17: =U17/T17 -> 0.46857143 | BA17: =B17+E17+H17+K17+N17+Q17+T17+W17+Z17+AC17+AF17+AI17+AL17+AO17+AR17+AU17+AX17 -> 299.91 | BB17: =C17+F17+I17+L17+O17+R17+U17+X17+AA17+AD17+AG17+AJ17+AM17+AP17+AS17+AV17+AY17 -> 461.17 | BC17: =BB17/BA17 -> 1.5376946
A18: MAHARASHTRA | E18: 1.06 | F18: 1.04 | G18: =F18/E18 -> 0.98113208 | H18: 99.5 | I18: 45.6 | J18: =I18/H18 -> 0.45829146 | K18: 11 | L18: 11 | M18: =L18/K18 -> 1 | N18: 3.5 | O18: 40 | P18: =O18/N18 -> 11.428571 | AU18: 5.7 | AV18: 11.4 | AW18: =AV18/AU18 -> 2 | BA18: =B18+E18+H18+K18+N18+Q18+T18+W18+Z18+AC18+AF18+AI18+AL18+AO18+AR18+AU18+AX18 -> 120.76 | BB18: =C18+F18+I18+L18+O18+R18+U18+X18+AA18+AD18+AG18+AJ18+AM18+AP18+AS18+AV18+AY18 -> 109.04 | BC18: =BB18/BA18 -> 0.902948
A19: MANIPUR | E19: 2.4 | F19: 3.84 | G19: =F19/E19 -> 1.6 | H19: 6.5 | I19: 3.9 | J19: =I19/H19 -> 0.6 | K19: 1.4 | L19: 16.4 | M19: =L19/K19 -> 11.714286 | N19: 0.17 | O19: 0.001 | P19: =O19/N19 -> 0.0058823529 | BA19: =B19+E19+H19+K19+N19+Q19+T19+W19+Z19+AC19+AF19+AI19+AL19+AO19+AR19+AU19+AX19 -> 10.47 | BB19: =C19+F19+I19+L19+O19+R19+U19+X19+AA19+AD19+AG19+AJ19+AM19+AP19+AS19+AV19+AY19 -> 24.141 | BC19: =BB19/BA19 -> 2.3057307
A20: MEGHALAYA | B20: 0.89 | C20: 0.46 | D20: =C20/B20 -> 0.51685393 | E20: 9.442 | F20: 56.8 | G20: =F20/E20 -> 6.0156746 | H20: 1.85 | I20: 1.41 | J20: =I20/H20 -> 0.76216216 | K20: 1.94 | L20: 9.98 | M20: =L20/K20 -> 5.1443299 | N20: 0.28 | O20: 1.11 | P20: =O20/N20 -> 3.9642857 | T20: 0.01 | U20: 0.05 | V20: =U20/T20 -> 5 | AL20: 2.44 | AM20: 5 | AN20: =AM20/AL20 -> 2.0491803 | BA20: =B20+E20+H20+K20+N20+Q20+T20+W20+Z20+AC20+AF20+AI20+AL20+AO20+AR20+AU20+AX20 -> 16.852 | BB20: =C20+F20+I20+L20+O20+R20+U20+X20+AA20+AD20+AG20+AJ20+AM20+AP20+AS20+AV20+AY20 -> 74.81 | BC20: =BB20/BA20 -> 4.4392357
A21: MIZORAM | B21: 0.07 | C21: 0.01 | D21: =C21/B21 -> 0.14285714 | E21: 7.28 | F21: 28.39 | G21: =F21/E21 -> 3.8997253 | H21: 9.02 | I21: 8.21 | J21: =I21/H21 -> 0.91019956 | K21: 6.05 | L21: 22.99 | M21: =L21/K21 -> 3.8 | N21: 0.02 | O21: 0.01 | P21: =O21/N21 -> 0.5 | T21: 0.03 | U21: 0.01 | V21: =U21/T21 -> 0.33333333 | BA21: =B21+E21+H21+K21+N21+Q21+T21+W21+Z21+AC21+AF21+AI21+AL21+AO21+AR21+AU21+AX21 -> 22.47 | BB21: =C21+F21+I21+L21+O21+R21+U21+X21+AA21+AD21+AG21+AJ21+AM21+AP21+AS21+AV21+AY21 -> 59.62 | BC21: =BB21/BA21 -> 2.6533155
A22: NAGALAND | B22: 0.23 | C22: 0.01 | D22: =C22/B22 -> 0.043478261 | E22: 5.32 | F22: 36 | G22: =F22/E22 -> 6.7669173 | H22: 0.8 | I22: 1 | J22: =I22/H22 -> 1.25 | K22: 0.12 | L22: 0.5 | M22: =L22/K22 -> 4.1666667 | N22: 0.1 | O22: 0.15 | P22: =O22/N22 -> 1.5 | Q22: 3.2 | R22: 1.5 | S22: =R22/Q22 -> 0.46875 | BA22: =B22+E22+H22+K22+N22+Q22+T22+W22+Z22+AC22+AF22+AI22+AL22+AO22+AR22+AU22+AX22 -> 9.77 | BB22: =C22+F22+I22+L22+O22+R22+U22+X22+AA22+AD22+AG22+AJ22+AM22+AP22+AS22+AV22+AY22 -> 39.16 | BC22: =BB22/BA22 -> 4.0081883
A23: ODISHA | E23: 15.844 | F23: 35 | G23: =F23/E23 -> 2.2090381 | H23: 75.6 | I23: 70 | J23: =I23/H23 -> 0.92592593 | K23: 2.48 | L23: 30 | M23: =L23/K23 -> 12.096774 | N23: 10.9 | O23: 35.5 | P23: =O23/N23 -> 3.2568807 | T23: 19.1 | U23: 11 | V23: =U23/T23 -> 0.57591623 | BA23: =B23+E23+H23+K23+N23+Q23+T23+W23+Z23+AC23+AF23+AI23+AL23+AO23+AR23+AU23+AX23 -> 123.924 | BB23: =C23+F23+I23+L23+O23+R23+U23+X23+AA23+AD23+AG23+AJ23+AM23+AP23+AS23+AV23+AY23 -> 181.5 | BC23: =BB23/BA23 -> 1.4646073
A24: PUDUCHERRY | B24: 0.01 | C24: 0.01 | D24: =C24/B24 -> 1 | H24: 0.01 | I24: 0.01 | J24: =I24/H24 -> 1 | K24: 0.01 | L24: 0.01 | M24: =L24/K24 -> 1 | BA24: =B24+E24+H24+K24+N24+Q24+T24+W24+Z24+AC24+AF24+AI24+AL24+AO24+AR24+AU24+AX24 -> 0.03 | BB24: =C24+F24+I24+L24+O24+R24+U24+X24+AA24+AD24+AG24+AJ24+AM24+AP24+AS24+AV24+AY24 -> 0.03 | BC24: =BB24/BA24 -> 1
A25: PUNJAB | H25: 10.6 | I25: 17.7 | J25: =I25/H25 -> 1.6698113 | N25: 3.7 | O25: 45 | P25: =O25/N25 -> 12.162162 | AI25: 4.07 | AJ25: 5.51 | AK25: =AJ25/AI25 -> 1.3538084 | BA25: =B25+E25+H25+K25+N25+Q25+T25+W25+Z25+AC25+AF25+AI25+AL25+AO25+AR25+AU25+AX25 -> 18.37 | BB25: =C25+F25+I25+L25+O25+R25+U25+X25+AA25+AD25+AG25+AJ25+AM25+AP25+AS25+AV25+AY25 -> 68.21 | BC25: =BB25/BA25 -> 3.7131192
A26: RAJASTHAN | E26: 0.16 | F26: 0.31 | G26: =F26/E26 -> 1.9375 | H26: 12.21 | I26: 17.71 | J26: =I26/H26 -> 1.4504505 | K26: 0.2 | L26: 0.43 | M26: =L26/K26 -> 2.15 | N26: 59.45 | O26: 235.98 | P26: =O26/N26 -> 3.969386 | T26: 250 | U26: 300 | V26: =U26/T26 -> 1.2 | W26: 220 | X26: 111 | Y26: =X26/W26 -> 0.50454545 | Z26: 59.04 | AA26: 84.07 | AB26: =AA26/Z26 -> 1.4239499 | AC26: 82.35 | AD26: 87.38 | AE26: =AD26/AC26 -> 1.0610808 | AF26: 24.43 | AG26: 18.01 | AH26: =AG26/AF26 -> 0.73720835 | AI26: 12.8 | AJ26: 6 | AK26: =AJ26/AI26 -> 0.46875 | BA26: =B26+E26+H26+K26+N26+Q26+T26+W26+Z26+AC26+AF26+AI26+AL26+AO26+AR26+AU26+AX26 -> 720.64 | BB26: =C26+F26+I26+L26+O26+R26+U26+X26+AA26+AD26+AG26+AJ26+AM26+AP26+AS26+AV26+AY26 -> 860.89 | BC26: =BB26/BA26 -> 1.1946187
A27: SIKKIM | E27: 9.25 | F27: 51.56 | G27: =F27/E27 -> 5.5740541 | K27: 1.3 | L27: 4.68 | M27: =L27/K27 -> 3.6 | Q27: 16.01 | R27: 3.84 | S27: =R27/Q27 -> 0.23985009 | BA27: =B27+E27+H27+K27+N27+Q27+T27+W27+Z27+AC27+AF27+AI27+AL27+AO27+AR27+AU27+AX27 -> 26.56 | BB27: =C27+F27+I27+L27+O27+R27+U27+X27+AA27+AD27+AG27+AJ27+AM27+AP27+AS27+AV27+AY27 -> 60.08 | BC27: =BB27/BA27 -> 2.2620482
A28: TAMIL NADU | B28: 4.3 | C28: 0.98 | D28: =C28/B28 -> 0.22790698 | E28: 0.33 | F28: 4.1 | G28: =F28/E28 -> 12.424242 | H28: 50.67 | I28: 23.06 | J28: =I28/H28 -> 0.45510164 | K28: 35.76 | L28: 190.1 | M28: =L28/K28 -> 5.3159955 | N28: 0.45 | O28: 2.59 | P28: =O28/N28 -> 5.7555556 | Q28: 5.16 | R28: 0.77 | S28: =R28/Q28 -> 0.14922481 | T28: 9.59 | U28: 4.1 | V28: =U28/T28 -> 0.42752868 | AO28: 0.05 | AP28: 0.001 | AQ28: =AP28/AO28 -> 0.02 | AR28: 0.87 | AS28: 0.82 | AT28: =AS28/AR28 -> 0.94252874 | AU28: 16.64 | AV28: 53.07 | AW28: =AV28/AU28 -> 3.1893029 | AX28: 0.57 | AY28: 0.02 | AZ28: =AY28/AX28 -> 0.035087719 | BA28: =B28+E28+H28+K28+N28+Q28+T28+W28+Z28+AC28+AF28+AI28+AL28+AO28+AR28+AU28+AX28 -> 124.39 | BB28: =C28+F28+I28+L28+O28+R28+U28+X28+AA28+AD28+AG28+AJ28+AM28+AP28+AS28+AV28+AY28 -> 279.611 | BC28: =BB28/BA28 -> 2.2478575
A29: TRIPURA | B29: 0.24 | C29: 0.15 | D29: =C29/B29 -> 0.625 | E29: 1.8 | F29: 7.6 | G29: =F29/E29 -> 4.2222222 | H29: 2.35 | I29: 3.7 | J29: =I29/H29 -> 1.5744681 | K29: 1.3 | L29: 6.59 | M29: =L29/K29 -> 5.0692308 | BA29: =B29+E29+H29+K29+N29+Q29+T29+W29+Z29+AC29+AF29+AI29+AL29+AO29+AR29+AU29+AX29 -> 5.69 | BB29: =C29+F29+I29+L29+O29+R29+U29+X29+AA29+AD29+AG29+AJ29+AM29+AP29+AS29+AV29+AY29 -> 18.04 | BC29: =BB29/BA29 -> 3.1704745
A30: UTTAR PRADESH | E30: 0.822 | F30: 4.02 | G30: =F30/E30 -> 4.8905109 | H30: 13.47 | I30: 10.3 | J30: =I30/H30 -> 0.76466221 | K30: 2 | L30: 6 | M30: =L30/K30 -> 3 | N30: 36.08 | O30: 187.39 | P30: =O30/N30 -> 5.1937361 | T30: 6.68 | U30: 3.61 | V30: =U30/T30 -> 0.54041916 | W30: 0.001 | X30: 0.01 | Y30: =X30/W30 -> 10 | Z30: 0.8 | AA30: 0.77 | AB30: =AA30/Z30 -> 0.9625 | AC30: 0.33 | AD30: 0.22 | AE30: =AD30/AC30 -> 0.66666667 | BA30: =B30+E30+H30+K30+N30+Q30+T30+W30+Z30+AC30+AF30+AI30+AL30+AO30+AR30+AU30+AX30 -> 60.183 | BB30: =C30+F30+I30+L30+O30+R30+U30+X30+AA30+AD30+AG30+AJ30+AM30+AP30+AS30+AV30+AY30 -> 212.32 | BC30: =BB30/BA30 -> 3.5279066
A31: UTTARAKHAND | E31: 2.355 | F31: 23.44 | G31: =F31/E31 -> 9.9532909 | H31: 2 | I31: 7.2 | J31: =I31/H31 -> 3.6 | K31: 1.34 | L31: 2.49 | M31: =L31/K31 -> 1.858209 | N31: 1.09 | O31: 1.54 | P31: =O31/N31 -> 1.412844 | T31: 0.9 | U31: 3.8 | V31: =U31/T31 -> 4.2222222 | AC31: 0.4 | AD31: 2.61 | AE31: =AD31/AC31 -> 6.525 | BA31: =B31+E31+H31+K31+N31+Q31+T31+W31+Z31+AC31+AF31+AI31+AL31+AO31+AR31+AU31+AX31 -> 8.085 | BB31: =C31+F31+I31+L31+O31+R31+U31+X31+AA31+AD31+AG31+AJ31+AM31+AP31+AS31+AV31+AY31 -> 41.08 | BC31: =BB31/BA31 -> 5.0810142
A32: WEST BENGAL | E32: 11.5 | F32: 25 | G32: =F32/E32 -> 2.173913 | H32: 63.6 | I32: 100 | J32: =I32/H32 -> 1.572327 | K32: 15.8 | L32: 42 | M32: =L32/K32 -> 2.6582278 | N32: 3.35 | O32: 40 | P32: =O32/N32 -> 11.940299 | Q32: 3.31 | R32: 0.66 | S32: =R32/Q32 -> 0.19939577 | BA32: =B32+E32+H32+K32+N32+Q32+T32+W32+Z32+AC32+AF32+AI32+AL32+AO32+AR32+AU32+AX32 -> 97.56 | BB32: =C32+F32+I32+L32+O32+R32+U32+X32+AA32+AD32+AG32+AJ32+AM32+AP32+AS32+AV32+AY32 -> 207.66 | BC32: =BB32/BA32 -> 2.1285363
BB33: =C33+F33+I33+L33+O33+R33+U33+X33+AA33+AD33+AG33+AJ33+AM33+AP33+AS33+AV33+AY33 -> 0
A34: TOTAL | B34: =SUM(B3:B33) -> 124.6 | C34: =SUM(C3:C33) -> 52.6101 | D34: =C34/B34 -> 0.42223194 | E34: =SUM(E3:E33) -> 136.248 | F34: =SUM(F3:F33) -> 682.63 | G34: =F34/E34 -> 5.010202 | H34: =SUM(H3:H33) -> 794.12 | I34: =SUM(I3:I33) -> 1304.38 | J34: =I34/H34 -> 1.6425477 | K34: =SUM(K3:K33) -> 194.23 | L34: =SUM(L3:L33) -> 971.09 | M34: =L34/K34 -> 4.9996911 | N34: =SUM(N3:N33) -> 247.52 | O34: =SUM(O3:O33) -> 1259.272 | P34: =O34/N34 -> 5.0875566 | Q34: =SUM(Q3:Q33) -> 92.39 | R34: =SUM(R3:R33) -> 18.43 | S34: =R34/Q34 -> 0.19948046 | T34: =SUM(T3:T33) -> 543.2 | U34: =SUM(U3:U33) -> 523.88 | V34: =U34/T34 -> 0.96443299 | W34: =SUM(W3:W33) -> 593.981 | X34: =SUM(X3:X33) -> 394.33 | Y34: =X34/W34 -> 0.66387645 | Z34: =SUM(Z3:Z33) -> 99.61 | AA34: =SUM(AA3:AA33) -> 142.95 | AB34: =AA34/Z34 -> 1.4350969 | AC34: =SUM(AC3:AC33) -> 93.12 | AD34: =SUM(AD3:AD33) -> 112.87 | AE34: =AD34/AC34 -> 1.2120919 | AF34: =SUM(AF3:AF33) -> 35.38 | AG34: =SUM(AG3:AG33) -> 26.78 | AH34: =AG34/AF34 -> 0.75692482 | AI34: =SUM(AI3:AI33) -> 33.47 | AJ34: =SUM(AJ3:AJ33) -> 32.64 | AK34: =AJ34/AI34 -> 0.97520167 | AL34: =SUM(AL3:AL33) -> 2.95 | AM34: =SUM(AM3:AM33) -> 5.051 | AN34: =AM34/AL34 -> 1.7122034 | AO34: =SUM(AO3:AO33) -> 17.49 | AP34: =SUM(AP3:AP33) -> 12.621 | AQ34: =AP34/AO34 -> 0.72161235 | AR34: =SUM(AR3:AR33) -> 2.38 | AS34: =SUM(AS3:AS33) -> 1.1 | AT34: =AS34/AR34 -> 0.46218487 | AU34: =SUM(AU3:AU33) -> 58.11 | AV34: =SUM(AV3:AV33) -> 201.82 | AW34: =AV34/AU34 -> 3.4730683 | AX34: =SUM(AX3:AX33) -> 7.1 | AY34: =SUM(AY3:AY33) -> 1.07 | AZ34: =AY34/AX34 -> 0.15070423 | BA34: =SUM(BA3:BA33) -> 3075.899 | BB34: =C34+F34+I34+L34+O34+R34+U34+X34+AA34+AD34+AG34+AJ34+AM34+AP34+AS34+AV34+AY34 -> 5743.5241 | BC34: =BB34/BA34 -> 1.8672668

Sheet spi13-14
A1: STATES/UTs | B1: Pepper | E1: Ginger | H1: Chillies | K1: Turmeric | N1: Garlic | Q1: Cardamom | T1: Coriander | W1: Cumin | Z1: Fennel | AC1: Fenugreek | AF1: Ajwan | AI1: Dill / Poppy /Celery | AL1: Cinnamon /Tejpat | AO1: Nutmeg | AR1: Clove | AU1: Tamarind | AX1: Saffron / Vanilla | BA1: Total
B2: A | C2: P | D2: Prod. | E2: A | F2: P | G2: Prod. | H2: A | I2: P | J2: Prod. | K2: A | L2: P | M2: Prod. | N2: A | O2: P | P2: Prod. | Q2: A | R2: P | S2: Prod. | T2: A | U2: P | V2: Prod. | W2: A | X2: P | Y2: Prod. | Z2: A | AA2: P | AB2: Prod. | AC2: A | AD2: P | AE2: Prod. | AF2: A | AG2: P | AH2: Prod. | AI2: A | AJ2: P | AK2: Prod. | AL2: A | AM2: P | AN2: Prod. | AO2: A | AP2: P | AQ2: Prod. | AR2: A | AS2: P | AT2: Prod. | AU2: A | AV2: P | AW2: Prod. | AX2: A | AY2: P | AZ2: Prod. | BA2: A | BB2: P | BC2: Prod.
A3: ANDAMAN NICOBAR | B3: 0.6 | C3: 0.13 | D3: =C3/B3 -> 0.21666667 | E3: 0.215 | F3: 1.91 | G3: =F3/E3 -> 8.8837209 | H3: 0.4 | I3: 0.61 | J3: =I3/H3 -> 1.525 | K3: 0.08 | L3: 0.47 | M3: =L3/K3 -> 5.875 | AL3: 0.15 | AM3: 0.04 | AN3: =AM3/AL3 -> 0.26666667 | AO3: 0.07 | AP3: 0.05 | AQ3: =AP3/AO3 -> 0.71428571 | AR3: 0.16 | AS3: 0.01 | AT3: =AS3/AR3 -> 0.0625 | BA3: =B3+E3+H3+K3+N3+Q3+T3+W3+Z3+AC3+AF3+AI3+AL3+AO3+AR3+AU3+AX3 -> 1.675 | BB3: =C3+F3+I3+L3+O3+R3+U3+X3+AA3+AD3+AG3+AJ3+AM3+AP3+AS3+AV3+AY3 -> 3.22 | BC3: =BB3/BA3 -> 1.9223881
A4: ANDHRA PRADESH | E4: 0.358 | F4: 1.37 | G4: =F4/E4 -> 3.8268156 | H4: 131.32 | I4: 601.99 | J4: =I4/H4 -> 4.5841456 | K4: 17.82 | L4: 151.91 | M4: =L4/K4 -> 8.5246914 | T4: 8.45 | U4: 5.02 | V4: =U4/T4 -> 0.59408284 | AF4: 6.63 | AG4: 2.88 | AH4: =AG4/AF4 -> 0.43438914 | AU4: 4.77 | AV4: 12.64 | AW4: =AV4/AU4 -> 2.6498952 | AX4: 0.01 | AY4: 0.01 | AZ4: =AY4/AX4 -> 1 | BA4: =B4+E4+H4+K4+N4+Q4+T4+W4+Z4+AC4+AF4+AI4+AL4+AO4+AR4+AU4+AX4 -> 169.358 | BB4: =C4+F4+I4+L4+O4+R4+U4+X4+AA4+AD4+AG4+AJ4+AM4+AP4+AS4+AV4+AY4 -> 775.82 | BC4: =BB4/BA4 -> 4.5809469
A5: ARUNACHAL PRADESH | E5: 7 | F5: 57 | G5: =F5/E5 -> 8.1428571 | H5: 2.5 | I5: 4.4 | J5: =I5/H5 -> 1.76 | K5: 0.64 | L5: 2.86 | M5: =L5/K5 -> 4.46875 | N5: 0.03 | O5: 0.01 | P5: =O5/N5 -> 0.33333333 | BA5: =B5+E5+H5+K5+N5+Q5+T5+W5+Z5+AC5+AF5+AI5+AL5+AO5+AR5+AU5+AX5 -> 10.17 | BB5: =C5+F5+I5+L5+O5+R5+U5+X5+AA5+AD5+AG5+AJ5+AM5+AP5+AS5+AV5+AY5 -> 64.27 | BC5: =BB5/BA5 -> 6.3195674
A6: ASSAM | B6: 3.52 | C6: 2.01 | D6: =C6/B6 -> 0.57102273 | E6: 15.683 | F6: 122.31 | G6: =F6/E6 -> 7.7988905 | H6: 18.92 | I6: 16.48 | J6: =I6/H6 -> 0.87103594 | K6: 16.31 | L6: 15.78 | M6: =L6/K6 -> 0.9675046 | N6: 10.08 | O6: 69.42 | P6: =O6/N6 -> 6.8869048 | T6: 28.57 | U6: 53.14 | V6: =U6/T6 -> 1.859993 | BA6: =B6+E6+H6+K6+N6+Q6+T6+W6+Z6+AC6+AF6+AI6+AL6+AO6+AR6+AU6+AX6 -> 93.083 | BB6: =C6+F6+I6+L6+O6+R6+U6+X6+AA6+AD6+AG6+AJ6+AM6+AP6+AS6+AV6+AY6 -> 279.14 | BC6: =BB6/BA6 -> 2.998829
A7: BIHAR | E7: 0.56 | F7: 0.84 | G7: =F7/E7 -> 1.5 | H7: 2.9 | I7: 3 | J7: =I7/H7 -> 1.0344828 | K7: 3 | L7: 3 | M7: =L7/K7 -> 1 | N7: 4.25 | O7: 4 | P7: =O7/N7 -> 0.94117647 | T7: 2.3 | U7: 1.7 | V7: =U7/T7 -> 0.73913043 | BA7: =B7+E7+H7+K7+N7+Q7+T7+W7+Z7+AC7+AF7+AI7+AL7+AO7+AR7+AU7+AX7 -> 13.01 | BB7: =C7+F7+I7+L7+O7+R7+U7+X7+AA7+AD7+AG7+AJ7+AM7+AP7+AS7+AV7+AY7 -> 12.54 | BC7: =BB7/BA7 -> 0.96387394
A8: CHHATTISGARH | E8: 1.62 | F8: 1.78 | G8: =F8/E8 -> 1.0987654 | H8: 5.01 | I8: 1.65 | J8: =I8/H8 -> 0.32934132 | K8: 0.99 | L8: 0.84 | M8: =L8/K8 -> 0.84848485 | N8: 1.2 | O8: 3.2 | P8: =O8/N8 -> 2.6666667 | T8: 2.98 | U8: 0.83 | V8: =U8/T8 -> 0.27852349 | BA8: =B8+E8+H8+K8+N8+Q8+T8+W8+Z8+AC8+AF8+AI8+AL8+AO8+AR8+AU8+AX8 -> 11.8 | BB8: =C8+F8+I8+L8+O8+R8+U8+X8+AA8+AD8+AG8+AJ8+AM8+AP8+AS8+AV8+AY8 -> 8.3 | BC8: =BB8/BA8 -> 0.70338983
A9: GOA | B9: 0.74 | C9: 0.23 | D9: =C9/B9 -> 0.31081081 | AO9: 0.17 | AP9: 0.05 | AQ9: =AP9/AO9 -> 0.29411765 | BA9: =B9+E9+H9+K9+N9+Q9+T9+W9+Z9+AC9+AF9+AI9+AL9+AO9+AR9+AU9+AX9 -> 0.91 | BB9: =C9+F9+I9+L9+O9+R9+U9+X9+AA9+AD9+AG9+AJ9+AM9+AP9+AS9+AV9+AY9 -> 0.28 | BC9: =BB9/BA9 -> 0.30769231
A10: GUJARAT | E10: 4.395 | F10: 70.65 | G10: =F10/E10 -> 16.075085 | H10: 43.4 | I10: 68.53 | J10: =I10/H10 -> 1.5790323 | K10: 2.98 | L10: 50.49 | M10: =L10/K10 -> 16.942953 | N10: 35 | O10: 250 | P10: =O10/N10 -> 7.1428571 | T10: 20.57 | U10: 32.31 | V10: =U10/T10 -> 1.5707341 | W10: 370 | X10: 280 | Y10: =X10/W10 -> 0.75675676 | Z10: 38 | AA10: 55 | AB10: =AA10/Z10 -> 1.4473684 | AC10: 5 | AD10: 14 | AE10: =AD10/AC10 -> 2.8 | AF10: 5.87 | AG10: 6.37 | AH10: =AG10/AF10 -> 1.0851789 | AI10: 16.6 | AJ10: 21.13 | AK10: =AJ10/AI10 -> 1.2728916 | BA10: =B10+E10+H10+K10+N10+Q10+T10+W10+Z10+AC10+AF10+AI10+AL10+AO10+AR10+AU10+AX10 -> 541.815 | BB10: =C10+F10+I10+L10+O10+R10+U10+X10+AA10+AD10+AG10+AJ10+AM10+AP10+AS10+AV10+AY10 -> 848.48 | BC10: =BB10/BA10 -> 1.5659958
